2015-01-14 19:46:42,212 INFO org.apache.hadoop.yarn.server.resourcemanager.ResourceManager: STARTUP_MSG: 
/************************************************************
STARTUP_MSG: Starting ResourceManager
STARTUP_MSG:   host = barbie/127.0.1.1
STARTUP_MSG:   args = []
STARTUP_MSG:   version = 2.6.0
STARTUP_MSG:   build = https://github.com/apache/hadoop -r e3496499ecb8d220fba99dc5ed4c99c8f9e33bb1; compiled by 'doopy' on 2015-01-14T23:00Z
STARTUP_MSG:   java = 1.7.0_65
************************************************************/
2015-01-14 19:46:42,241 INFO org.apache.hadoop.yarn.server.resourcemanager.ResourceManager: registered UNIX signal handlers for [TERM, HUP, INT]
2015-01-14 19:46:43,727 INFO org.apache.hadoop.conf.Configuration: found resource core-site.xml at file:/usr/local/hadoop-2.6.0/etc/hadoop/core-site.xml
2015-01-14 19:46:44,056 INFO org.apache.hadoop.security.Groups: clearing userToGroupsMap cache
2015-01-14 19:46:44,360 INFO org.apache.hadoop.conf.Configuration: found resource yarn-site.xml at file:/usr/local/hadoop-2.6.0/etc/hadoop/yarn-site.xml
2015-01-14 19:46:45,077 INFO org.apache.hadoop.yarn.event.AsyncDispatcher: Registering class org.apache.hadoop.yarn.server.resourcemanager.RMFatalEventType for class org.apache.hadoop.yarn.server.resourcemanager.ResourceManager$RMFatalEventDispatcher
2015-01-14 19:46:45,212 INFO org.apache.hadoop.yarn.server.resourcemanager.security.NMTokenSecretManagerInRM: NMTokenKeyRollingInterval: 86400000ms and NMTokenKeyActivationDelay: 900000ms
2015-01-14 19:46:45,228 INFO org.apache.hadoop.yarn.server.resourcemanager.security.RMContainerTokenSecretManager: ContainerTokenKeyRollingInterval: 86400000ms and ContainerTokenKeyActivationDelay: 900000ms
2015-01-14 19:46:45,266 INFO org.apache.hadoop.yarn.server.resourcemanager.security.AMRMTokenSecretManager: AMRMTokenKeyRollingInterval: 86400000ms and AMRMTokenKeyActivationDelay: 900000 ms
2015-01-14 19:46:45,419 INFO org.apache.hadoop.yarn.event.AsyncDispatcher: Registering class org.apache.hadoop.yarn.server.resourcemanager.recovery.RMStateStoreEventType for class org.apache.hadoop.yarn.server.resourcemanager.recovery.RMStateStore$ForwardingEventHandler
2015-01-14 19:46:45,440 INFO org.apache.hadoop.yarn.event.AsyncDispatcher: Registering class org.apache.hadoop.yarn.server.resourcemanager.NodesListManagerEventType for class org.apache.hadoop.yarn.server.resourcemanager.NodesListManager
2015-01-14 19:46:45,440 INFO org.apache.hadoop.yarn.server.resourcemanager.ResourceManager: Using Scheduler: org.apache.hadoop.yarn.server.resourcemanager.scheduler.capacity.CapacityScheduler
2015-01-14 19:46:45,517 INFO org.apache.hadoop.yarn.event.AsyncDispatcher: Registering class org.apache.hadoop.yarn.server.resourcemanager.scheduler.event.SchedulerEventType for class org.apache.hadoop.yarn.server.resourcemanager.ResourceManager$SchedulerEventDispatcher
2015-01-14 19:46:45,526 INFO org.apache.hadoop.yarn.event.AsyncDispatcher: Registering class org.apache.hadoop.yarn.server.resourcemanager.rmapp.RMAppEventType for class org.apache.hadoop.yarn.server.resourcemanager.ResourceManager$ApplicationEventDispatcher
2015-01-14 19:46:45,536 INFO org.apache.hadoop.yarn.event.AsyncDispatcher: Registering class org.apache.hadoop.yarn.server.resourcemanager.rmapp.attempt.RMAppAttemptEventType for class org.apache.hadoop.yarn.server.resourcemanager.ResourceManager$ApplicationAttemptEventDispatcher
2015-01-14 19:46:45,547 INFO org.apache.hadoop.yarn.event.AsyncDispatcher: Registering class org.apache.hadoop.yarn.server.resourcemanager.rmnode.RMNodeEventType for class org.apache.hadoop.yarn.server.resourcemanager.ResourceManager$NodeEventDispatcher
2015-01-14 19:46:45,907 INFO org.apache.hadoop.metrics2.impl.MetricsConfig: loaded properties from hadoop-metrics2.properties
2015-01-14 19:46:46,264 INFO org.apache.hadoop.metrics2.impl.MetricsSystemImpl: Scheduled snapshot period at 10 second(s).
2015-01-14 19:46:46,264 INFO org.apache.hadoop.metrics2.impl.MetricsSystemImpl: ResourceManager metrics system started
2015-01-14 19:46:46,360 INFO org.apache.hadoop.yarn.event.AsyncDispatcher: Registering class org.apache.hadoop.yarn.server.resourcemanager.RMAppManagerEventType for class org.apache.hadoop.yarn.server.resourcemanager.RMAppManager
2015-01-14 19:46:46,391 INFO org.apache.hadoop.yarn.event.AsyncDispatcher: Registering class org.apache.hadoop.yarn.server.resourcemanager.amlauncher.AMLauncherEventType for class org.apache.hadoop.yarn.server.resourcemanager.amlauncher.ApplicationMasterLauncher
2015-01-14 19:46:46,410 INFO org.apache.hadoop.yarn.server.resourcemanager.RMNMInfo: Registered RMNMInfo MBean
2015-01-14 19:46:46,412 INFO org.apache.hadoop.yarn.server.resourcemanager.metrics.SystemMetricsPublisher: YARN system metrics publishing service is not enabled
2015-01-14 19:46:46,414 INFO org.apache.hadoop.util.HostsFileReader: Refreshing hosts (include/exclude) list
2015-01-14 19:46:46,452 INFO org.apache.hadoop.conf.Configuration: found resource capacity-scheduler.xml at file:/usr/local/hadoop-2.6.0/etc/hadoop/capacity-scheduler.xml
2015-01-14 19:46:46,801 INFO org.apache.hadoop.yarn.server.resourcemanager.scheduler.capacity.ParentQueue: root, capacity=1.0, asboluteCapacity=1.0, maxCapacity=1.0, asboluteMaxCapacity=1.0, state=RUNNING, acls=ADMINISTER_QUEUE:*SUBMIT_APPLICATIONS:*, labels=*,
, reservationsContinueLooking=true
2015-01-14 19:46:46,801 INFO org.apache.hadoop.yarn.server.resourcemanager.scheduler.capacity.ParentQueue: Initialized parent-queue root name=root, fullname=root
2015-01-14 19:46:46,839 INFO org.apache.hadoop.yarn.server.resourcemanager.scheduler.capacity.LeafQueue: Initializing default
capacity = 1.0 [= (float) configuredCapacity / 100 ]
asboluteCapacity = 1.0 [= parentAbsoluteCapacity * capacity ]
maxCapacity = 1.0 [= configuredMaxCapacity ]
absoluteMaxCapacity = 1.0 [= 1.0 maximumCapacity undefined, (parentAbsoluteMaxCapacity * maximumCapacity) / 100 otherwise ]
userLimit = 100 [= configuredUserLimit ]
userLimitFactor = 1.0 [= configuredUserLimitFactor ]
maxApplications = 10000 [= configuredMaximumSystemApplicationsPerQueue or (int)(configuredMaximumSystemApplications * absoluteCapacity)]
maxApplicationsPerUser = 10000 [= (int)(maxApplications * (userLimit / 100.0f) * userLimitFactor) ]
maxActiveApplications = 1 [= max((int)ceil((clusterResourceMemory / minimumAllocation) * maxAMResourcePerQueuePercent * absoluteMaxCapacity),1) ]
maxActiveAppsUsingAbsCap = 1 [= max((int)ceil((clusterResourceMemory / minimumAllocation) *maxAMResourcePercent * absoluteCapacity),1) ]
maxActiveApplicationsPerUser = 1 [= max((int)(maxActiveApplications * (userLimit / 100.0f) * userLimitFactor),1) ]
usedCapacity = 0.0 [= usedResourcesMemory / (clusterResourceMemory * absoluteCapacity)]
absoluteUsedCapacity = 0.0 [= usedResourcesMemory / clusterResourceMemory]
maxAMResourcePerQueuePercent = 0.1 [= configuredMaximumAMResourcePercent ]
minimumAllocationFactor = 0.875 [= (float)(maximumAllocationMemory - minimumAllocationMemory) / maximumAllocationMemory ]
numContainers = 0 [= currentNumContainers ]
state = RUNNING [= configuredState ]
acls = ADMINISTER_QUEUE:*SUBMIT_APPLICATIONS:* [= configuredAcls ]
nodeLocalityDelay = 40
labels=*,
nodeLocalityDelay = 40
reservationsContinueLooking = true

2015-01-14 19:46:46,845 INFO org.apache.hadoop.yarn.server.resourcemanager.scheduler.capacity.CapacityScheduler: Initialized queue: default: capacity=1.0, absoluteCapacity=1.0, usedResources=<memory:0, vCores:0>, usedCapacity=0.0, absoluteUsedCapacity=0.0, numApps=0, numContainers=0
2015-01-14 19:46:46,846 INFO org.apache.hadoop.yarn.server.resourcemanager.scheduler.capacity.CapacityScheduler: Initialized queue: root: numChildQueue= 1, capacity=1.0, absoluteCapacity=1.0, usedResources=<memory:0, vCores:0>usedCapacity=0.0, numApps=0, numContainers=0
2015-01-14 19:46:46,848 INFO org.apache.hadoop.yarn.server.resourcemanager.scheduler.capacity.CapacityScheduler: Initialized root queue root: numChildQueue= 1, capacity=1.0, absoluteCapacity=1.0, usedResources=<memory:0, vCores:0>usedCapacity=0.0, numApps=0, numContainers=0
2015-01-14 19:46:46,848 INFO org.apache.hadoop.yarn.server.resourcemanager.scheduler.capacity.CapacityScheduler: Initialized queue mappings, override: false
2015-01-14 19:46:46,849 INFO org.apache.hadoop.yarn.server.resourcemanager.scheduler.capacity.CapacityScheduler: Initialized CapacityScheduler with calculator=class org.apache.hadoop.yarn.util.resource.DefaultResourceCalculator, minimumAllocation=<<memory:1024, vCores:1>>, maximumAllocation=<<memory:8192, vCores:32>>, asynchronousScheduling=false, asyncScheduleInterval=5ms
2015-01-14 19:46:46,886 INFO org.apache.hadoop.yarn.server.resourcemanager.ResourceManager: Transitioning to active state
2015-01-14 19:46:46,939 INFO org.apache.hadoop.yarn.server.resourcemanager.security.RMContainerTokenSecretManager: Rolling master-key for container-tokens
2015-01-14 19:46:46,943 INFO org.apache.hadoop.yarn.server.resourcemanager.security.NMTokenSecretManagerInRM: Rolling master-key for nm-tokens
2015-01-14 19:46:46,943 INFO org.apache.hadoop.security.token.delegation.AbstractDelegationTokenSecretManager: Updating the current master key for generating delegation tokens
2015-01-14 19:46:46,945 INFO org.apache.hadoop.yarn.server.resourcemanager.security.RMDelegationTokenSecretManager: storing master key with keyID 1
2015-01-14 19:46:46,953 INFO org.apache.hadoop.security.token.delegation.AbstractDelegationTokenSecretManager: Starting expired delegation token remover thread, tokenRemoverScanInterval=60 min(s)
2015-01-14 19:46:46,961 INFO org.apache.hadoop.security.token.delegation.AbstractDelegationTokenSecretManager: Updating the current master key for generating delegation tokens
2015-01-14 19:46:46,961 INFO org.apache.hadoop.yarn.server.resourcemanager.security.RMDelegationTokenSecretManager: storing master key with keyID 2
2015-01-14 19:46:47,104 INFO org.apache.hadoop.ipc.CallQueueManager: Using callQueue class java.util.concurrent.LinkedBlockingQueue
2015-01-14 19:46:47,164 INFO org.apache.hadoop.ipc.Server: Starting Socket Reader #1 for port 8031
2015-01-14 19:46:47,257 INFO org.apache.hadoop.yarn.factories.impl.pb.RpcServerFactoryPBImpl: Adding protocol org.apache.hadoop.yarn.server.api.ResourceTrackerPB to the server
2015-01-14 19:46:47,257 INFO org.apache.hadoop.ipc.Server: IPC Server Responder: starting
2015-01-14 19:46:47,316 INFO org.apache.hadoop.ipc.Server: IPC Server listener on 8031: starting
2015-01-14 19:46:47,407 INFO org.apache.hadoop.ipc.CallQueueManager: Using callQueue class java.util.concurrent.LinkedBlockingQueue
2015-01-14 19:46:47,431 INFO org.apache.hadoop.ipc.Server: Starting Socket Reader #1 for port 8030
2015-01-14 19:46:47,604 INFO org.apache.hadoop.yarn.factories.impl.pb.RpcServerFactoryPBImpl: Adding protocol org.apache.hadoop.yarn.api.ApplicationMasterProtocolPB to the server
2015-01-14 19:46:47,612 INFO org.apache.hadoop.ipc.Server: IPC Server Responder: starting
2015-01-14 19:46:47,612 INFO org.apache.hadoop.ipc.Server: IPC Server listener on 8030: starting
2015-01-14 19:46:47,959 INFO org.apache.hadoop.ipc.CallQueueManager: Using callQueue class java.util.concurrent.LinkedBlockingQueue
2015-01-14 19:46:47,960 INFO org.apache.hadoop.ipc.Server: Starting Socket Reader #1 for port 8032
2015-01-14 19:46:47,977 INFO org.apache.hadoop.yarn.factories.impl.pb.RpcServerFactoryPBImpl: Adding protocol org.apache.hadoop.yarn.api.ApplicationClientProtocolPB to the server
2015-01-14 19:46:47,978 INFO org.apache.hadoop.ipc.Server: IPC Server Responder: starting
2015-01-14 19:46:47,980 INFO org.apache.hadoop.ipc.Server: IPC Server listener on 8032: starting
2015-01-14 19:46:48,023 INFO org.apache.hadoop.yarn.server.resourcemanager.ResourceManager: Transitioned to active state
2015-01-14 19:46:48,342 INFO org.mortbay.log: Logging to org.slf4j.impl.Log4jLoggerAdapter(org.mortbay.log) via org.mortbay.log.Slf4jLog
2015-01-14 19:46:48,369 INFO org.apache.hadoop.http.HttpRequestLog: Http request log for http.requests.resourcemanager is not defined
2015-01-14 19:46:48,462 INFO org.apache.hadoop.http.HttpServer2: Added global filter 'safety' (class=org.apache.hadoop.http.HttpServer2$QuotingInputFilter)
2015-01-14 19:46:48,551 INFO org.apache.hadoop.http.HttpServer2: Added filter RMAuthenticationFilter (class=org.apache.hadoop.yarn.server.security.http.RMAuthenticationFilter) to context cluster
2015-01-14 19:46:48,551 INFO org.apache.hadoop.http.HttpServer2: Added filter RMAuthenticationFilter (class=org.apache.hadoop.yarn.server.security.http.RMAuthenticationFilter) to context logs
2015-01-14 19:46:48,551 INFO org.apache.hadoop.http.HttpServer2: Added filter RMAuthenticationFilter (class=org.apache.hadoop.yarn.server.security.http.RMAuthenticationFilter) to context static
2015-01-14 19:46:48,555 INFO org.apache.hadoop.http.HttpServer2: Added filter static_user_filter (class=org.apache.hadoop.http.lib.StaticUserWebFilter$StaticUserFilter) to context cluster
2015-01-14 19:46:48,555 INFO org.apache.hadoop.http.HttpServer2: Added filter static_user_filter (class=org.apache.hadoop.http.lib.StaticUserWebFilter$StaticUserFilter) to context logs
2015-01-14 19:46:48,555 INFO org.apache.hadoop.http.HttpServer2: Added filter static_user_filter (class=org.apache.hadoop.http.lib.StaticUserWebFilter$StaticUserFilter) to context static
2015-01-14 19:46:48,584 INFO org.apache.hadoop.http.HttpServer2: adding path spec: /cluster/*
2015-01-14 19:46:48,584 INFO org.apache.hadoop.http.HttpServer2: adding path spec: /ws/*
2015-01-14 19:46:48,635 INFO org.apache.hadoop.http.HttpServer2: Jetty bound to port 8088
2015-01-14 19:46:48,635 INFO org.mortbay.log: jetty-6.1.26
2015-01-14 19:46:48,769 INFO org.mortbay.log: Extract jar:file:/usr/local/hadoop-2.6.0/share/hadoop/yarn/hadoop-yarn-common-2.6.0.jar!/webapps/cluster to /tmp/Jetty_0_0_0_0_8088_cluster____u0rgz3/webapp
2015-01-14 19:46:49,733 INFO org.apache.hadoop.security.token.delegation.AbstractDelegationTokenSecretManager: Updating the current master key for generating delegation tokens
2015-01-14 19:46:49,739 INFO org.apache.hadoop.security.token.delegation.AbstractDelegationTokenSecretManager: Starting expired delegation token remover thread, tokenRemoverScanInterval=60 min(s)
2015-01-14 19:46:49,740 INFO org.apache.hadoop.security.token.delegation.AbstractDelegationTokenSecretManager: Updating the current master key for generating delegation tokens
2015-01-14 19:46:49,878 INFO org.apache.hadoop.security.token.delegation.AbstractDelegationTokenSecretManager: Updating the current master key for generating delegation tokens
2015-01-14 19:46:49,884 INFO org.apache.hadoop.security.token.delegation.AbstractDelegationTokenSecretManager: Starting expired delegation token remover thread, tokenRemoverScanInterval=60 min(s)
2015-01-14 19:46:49,888 INFO org.apache.hadoop.security.token.delegation.AbstractDelegationTokenSecretManager: Updating the current master key for generating delegation tokens
2015-01-14 19:46:49,890 INFO org.apache.hadoop.security.token.delegation.AbstractDelegationTokenSecretManager: Updating the current master key for generating delegation tokens
2015-01-14 19:46:49,896 INFO org.apache.hadoop.security.token.delegation.AbstractDelegationTokenSecretManager: Starting expired delegation token remover thread, tokenRemoverScanInterval=60 min(s)
2015-01-14 19:46:49,908 INFO org.apache.hadoop.security.token.delegation.AbstractDelegationTokenSecretManager: Updating the current master key for generating delegation tokens
2015-01-14 19:46:49,921 INFO org.mortbay.log: Started HttpServer2$SelectChannelConnectorWithSafeStartup@0.0.0.0:8088
2015-01-14 19:46:49,921 INFO org.apache.hadoop.yarn.webapp.WebApps: Web app /cluster started at 8088
2015-01-14 19:46:51,711 INFO org.apache.hadoop.yarn.webapp.WebApps: Registered webapp guice modules
2015-01-14 19:46:51,855 INFO org.apache.hadoop.ipc.CallQueueManager: Using callQueue class java.util.concurrent.LinkedBlockingQueue
2015-01-14 19:46:51,856 INFO org.apache.hadoop.ipc.Server: Starting Socket Reader #1 for port 8033
2015-01-14 19:46:51,870 INFO org.apache.hadoop.yarn.factories.impl.pb.RpcServerFactoryPBImpl: Adding protocol org.apache.hadoop.yarn.server.api.ResourceManagerAdministrationProtocolPB to the server
2015-01-14 19:46:51,871 INFO org.apache.hadoop.ipc.Server: IPC Server Responder: starting
2015-01-14 19:46:51,877 INFO org.apache.hadoop.ipc.Server: IPC Server listener on 8033: starting
2015-01-14 19:46:59,535 INFO org.apache.hadoop.yarn.util.RackResolver: Resolved barbie to /default-rack
2015-01-14 19:46:59,544 INFO org.apache.hadoop.yarn.server.resourcemanager.ResourceTrackerService: NodeManager from node barbie(cmPort: 45258 httpPort: 8042) registered with capability: <memory:8192, vCores:8>, assigned nodeId barbie:45258
2015-01-14 19:46:59,545 INFO org.apache.hadoop.yarn.server.resourcemanager.rmnode.RMNodeImpl: barbie:45258 Node Transitioned from NEW to RUNNING
2015-01-14 19:46:59,557 INFO org.apache.hadoop.yarn.server.resourcemanager.scheduler.capacity.CapacityScheduler: Added node barbie:45258 clusterResource: <memory:8192, vCores:8>
2015-01-14 19:47:58,334 INFO org.apache.hadoop.yarn.server.resourcemanager.ClientRMService: Allocated new applicationId: 1
2015-01-14 19:48:00,843 INFO org.apache.hadoop.yarn.server.resourcemanager.rmapp.RMAppImpl: Storing application with id application_1421286406893_0001
2015-01-14 19:48:00,847 INFO org.apache.hadoop.yarn.server.resourcemanager.ClientRMService: Application with id 1 submitted by user doopy
2015-01-14 19:48:00,854 INFO org.apache.hadoop.yarn.server.resourcemanager.rmapp.RMAppImpl: application_1421286406893_0001 State change from NEW to NEW_SAVING
2015-01-14 19:48:00,858 INFO org.apache.hadoop.yarn.server.resourcemanager.RMAuditLogger: USER=doopy	IP=127.0.0.1	OPERATION=Submit Application Request	TARGET=ClientRMService	RESULT=SUCCESS	APPID=application_1421286406893_0001
2015-01-14 19:48:00,885 INFO org.apache.hadoop.yarn.server.resourcemanager.recovery.RMStateStore: Storing info for app: application_1421286406893_0001
2015-01-14 19:48:00,889 INFO org.apache.hadoop.yarn.server.resourcemanager.rmapp.RMAppImpl: application_1421286406893_0001 State change from NEW_SAVING to SUBMITTED
2015-01-14 19:48:00,893 INFO org.apache.hadoop.yarn.server.resourcemanager.scheduler.capacity.ParentQueue: Application added - appId: application_1421286406893_0001 user: doopy leaf-queue of parent: root #applications: 1
2015-01-14 19:48:00,894 INFO org.apache.hadoop.yarn.server.resourcemanager.scheduler.capacity.CapacityScheduler: Accepted application application_1421286406893_0001 from user: doopy, in queue: default
2015-01-14 19:48:00,927 INFO org.apache.hadoop.yarn.server.resourcemanager.rmapp.RMAppImpl: application_1421286406893_0001 State change from SUBMITTED to ACCEPTED
2015-01-14 19:48:00,997 INFO org.apache.hadoop.yarn.server.resourcemanager.ApplicationMasterService: Registering app attempt : appattempt_1421286406893_0001_000001
2015-01-14 19:48:00,999 INFO org.apache.hadoop.yarn.server.resourcemanager.rmapp.attempt.RMAppAttemptImpl: appattempt_1421286406893_0001_000001 State change from NEW to SUBMITTED
2015-01-14 19:48:01,053 INFO org.apache.hadoop.yarn.server.resourcemanager.scheduler.capacity.LeafQueue: Application application_1421286406893_0001 from user: doopy activated in queue: default
2015-01-14 19:48:01,053 INFO org.apache.hadoop.yarn.server.resourcemanager.scheduler.capacity.LeafQueue: Application added - appId: application_1421286406893_0001 user: org.apache.hadoop.yarn.server.resourcemanager.scheduler.capacity.LeafQueue$User@4d2ceb, leaf-queue: default #user-pending-applications: 0 #user-active-applications: 1 #queue-pending-applications: 0 #queue-active-applications: 1
2015-01-14 19:48:01,054 INFO org.apache.hadoop.yarn.server.resourcemanager.scheduler.capacity.CapacityScheduler: Added Application Attempt appattempt_1421286406893_0001_000001 to scheduler from user doopy in queue default
2015-01-14 19:48:01,060 INFO org.apache.hadoop.yarn.server.resourcemanager.rmapp.attempt.RMAppAttemptImpl: appattempt_1421286406893_0001_000001 State change from SUBMITTED to SCHEDULED
2015-01-14 19:48:01,956 INFO org.apache.hadoop.yarn.server.resourcemanager.rmcontainer.RMContainerImpl: container_1421286406893_0001_01_000001 Container Transitioned from NEW to ALLOCATED
2015-01-14 19:48:01,956 INFO org.apache.hadoop.yarn.server.resourcemanager.RMAuditLogger: USER=doopy	OPERATION=AM Allocated Container	TARGET=SchedulerApp	RESULT=SUCCESS	APPID=application_1421286406893_0001	CONTAINERID=container_1421286406893_0001_01_000001
2015-01-14 19:48:01,957 INFO org.apache.hadoop.yarn.server.resourcemanager.scheduler.SchedulerNode: Assigned container container_1421286406893_0001_01_000001 of capacity <memory:2048, vCores:1> on host barbie:45258, which has 1 containers, <memory:2048, vCores:1> used and <memory:6144, vCores:7> available after allocation
2015-01-14 19:48:01,957 INFO org.apache.hadoop.yarn.server.resourcemanager.scheduler.capacity.LeafQueue: assignedContainer application attempt=appattempt_1421286406893_0001_000001 container=Container: [ContainerId: container_1421286406893_0001_01_000001, NodeId: barbie:45258, NodeHttpAddress: barbie:8042, Resource: <memory:2048, vCores:1>, Priority: 0, Token: null, ] queue=default: capacity=1.0, absoluteCapacity=1.0, usedResources=<memory:0, vCores:0>, usedCapacity=0.0, absoluteUsedCapacity=0.0, numApps=1, numContainers=0 clusterResource=<memory:8192, vCores:8>
2015-01-14 19:48:01,963 INFO org.apache.hadoop.yarn.server.resourcemanager.scheduler.capacity.ParentQueue: Re-sorting assigned queue: root.default stats: default: capacity=1.0, absoluteCapacity=1.0, usedResources=<memory:2048, vCores:1>, usedCapacity=0.25, absoluteUsedCapacity=0.25, numApps=1, numContainers=1
2015-01-14 19:48:01,963 INFO org.apache.hadoop.yarn.server.resourcemanager.scheduler.capacity.ParentQueue: assignedContainer queue=root usedCapacity=0.25 absoluteUsedCapacity=0.25 used=<memory:2048, vCores:1> cluster=<memory:8192, vCores:8>
2015-01-14 19:48:02,012 INFO org.apache.hadoop.yarn.server.resourcemanager.security.NMTokenSecretManagerInRM: Sending NMToken for nodeId : barbie:45258 for container : container_1421286406893_0001_01_000001
2015-01-14 19:48:02,035 INFO org.apache.hadoop.yarn.server.resourcemanager.rmcontainer.RMContainerImpl: container_1421286406893_0001_01_000001 Container Transitioned from ALLOCATED to ACQUIRED
2015-01-14 19:48:02,036 INFO org.apache.hadoop.yarn.server.resourcemanager.security.NMTokenSecretManagerInRM: Clear node set for appattempt_1421286406893_0001_000001
2015-01-14 19:48:02,042 INFO org.apache.hadoop.yarn.server.resourcemanager.rmapp.attempt.RMAppAttemptImpl: Storing attempt: AppId: application_1421286406893_0001 AttemptId: appattempt_1421286406893_0001_000001 MasterContainer: Container: [ContainerId: container_1421286406893_0001_01_000001, NodeId: barbie:45258, NodeHttpAddress: barbie:8042, Resource: <memory:2048, vCores:1>, Priority: 0, Token: Token { kind: ContainerToken, service: 127.0.1.1:45258 }, ]
2015-01-14 19:48:02,053 INFO org.apache.hadoop.yarn.server.resourcemanager.rmapp.attempt.RMAppAttemptImpl: appattempt_1421286406893_0001_000001 State change from SCHEDULED to ALLOCATED_SAVING
2015-01-14 19:48:02,074 INFO org.apache.hadoop.yarn.server.resourcemanager.rmapp.attempt.RMAppAttemptImpl: appattempt_1421286406893_0001_000001 State change from ALLOCATED_SAVING to ALLOCATED
2015-01-14 19:48:02,080 INFO org.apache.hadoop.yarn.server.resourcemanager.amlauncher.AMLauncher: Launching masterappattempt_1421286406893_0001_000001
2015-01-14 19:48:02,154 INFO org.apache.hadoop.yarn.server.resourcemanager.amlauncher.AMLauncher: Setting up container Container: [ContainerId: container_1421286406893_0001_01_000001, NodeId: barbie:45258, NodeHttpAddress: barbie:8042, Resource: <memory:2048, vCores:1>, Priority: 0, Token: Token { kind: ContainerToken, service: 127.0.1.1:45258 }, ] for AM appattempt_1421286406893_0001_000001
2015-01-14 19:48:02,155 INFO org.apache.hadoop.yarn.server.resourcemanager.amlauncher.AMLauncher: Command to launch container container_1421286406893_0001_01_000001 : $JAVA_HOME/bin/java -Dlog4j.configuration=container-log4j.properties -Dyarn.app.container.log.dir=<LOG_DIR> -Dyarn.app.container.log.filesize=0 -Dhadoop.root.logger=INFO,CLA  -Xmx1024m org.apache.hadoop.mapreduce.v2.app.MRAppMaster 1><LOG_DIR>/stdout 2><LOG_DIR>/stderr 
2015-01-14 19:48:02,158 INFO org.apache.hadoop.yarn.server.resourcemanager.security.AMRMTokenSecretManager: Create AMRMToken for ApplicationAttempt: appattempt_1421286406893_0001_000001
2015-01-14 19:48:02,165 INFO org.apache.hadoop.yarn.server.resourcemanager.security.AMRMTokenSecretManager: Creating password for appattempt_1421286406893_0001_000001
2015-01-14 19:48:03,094 INFO org.apache.hadoop.yarn.server.resourcemanager.amlauncher.AMLauncher: Done launching container Container: [ContainerId: container_1421286406893_0001_01_000001, NodeId: barbie:45258, NodeHttpAddress: barbie:8042, Resource: <memory:2048, vCores:1>, Priority: 0, Token: Token { kind: ContainerToken, service: 127.0.1.1:45258 }, ] for AM appattempt_1421286406893_0001_000001
2015-01-14 19:48:03,095 INFO org.apache.hadoop.yarn.server.resourcemanager.rmapp.attempt.RMAppAttemptImpl: appattempt_1421286406893_0001_000001 State change from ALLOCATED to LAUNCHED
2015-01-14 19:48:03,989 INFO org.apache.hadoop.yarn.server.resourcemanager.rmcontainer.RMContainerImpl: container_1421286406893_0001_01_000001 Container Transitioned from ACQUIRED to RUNNING
2015-01-14 19:48:16,271 INFO SecurityLogger.org.apache.hadoop.ipc.Server: Auth successful for appattempt_1421286406893_0001_000001 (auth:SIMPLE)
2015-01-14 19:48:16,288 INFO org.apache.hadoop.yarn.server.resourcemanager.ApplicationMasterService: AM registration appattempt_1421286406893_0001_000001
2015-01-14 19:48:16,290 INFO org.apache.hadoop.yarn.server.resourcemanager.rmapp.attempt.RMAppAttemptImpl: appattempt_1421286406893_0001_000001 State change from LAUNCHED to RUNNING
2015-01-14 19:48:16,290 INFO org.apache.hadoop.yarn.server.resourcemanager.rmapp.RMAppImpl: application_1421286406893_0001 State change from ACCEPTED to RUNNING
2015-01-14 19:48:16,295 INFO org.apache.hadoop.yarn.server.resourcemanager.RMAuditLogger: USER=doopy	IP=127.0.0.1	OPERATION=Register App Master	TARGET=ApplicationMasterService	RESULT=SUCCESS	APPID=application_1421286406893_0001	APPATTEMPTID=appattempt_1421286406893_0001_000001
2015-01-14 19:48:18,065 INFO org.apache.hadoop.yarn.server.resourcemanager.rmcontainer.RMContainerImpl: container_1421286406893_0001_01_000002 Container Transitioned from NEW to ALLOCATED
2015-01-14 19:48:18,065 INFO org.apache.hadoop.yarn.server.resourcemanager.RMAuditLogger: USER=doopy	OPERATION=AM Allocated Container	TARGET=SchedulerApp	RESULT=SUCCESS	APPID=application_1421286406893_0001	CONTAINERID=container_1421286406893_0001_01_000002
2015-01-14 19:48:18,065 INFO org.apache.hadoop.yarn.server.resourcemanager.scheduler.SchedulerNode: Assigned container container_1421286406893_0001_01_000002 of capacity <memory:1024, vCores:1> on host barbie:45258, which has 2 containers, <memory:3072, vCores:2> used and <memory:5120, vCores:6> available after allocation
2015-01-14 19:48:18,065 INFO org.apache.hadoop.yarn.server.resourcemanager.scheduler.capacity.LeafQueue: assignedContainer application attempt=appattempt_1421286406893_0001_000001 container=Container: [ContainerId: container_1421286406893_0001_01_000002, NodeId: barbie:45258, NodeHttpAddress: barbie:8042, Resource: <memory:1024, vCores:1>, Priority: 20, Token: null, ] queue=default: capacity=1.0, absoluteCapacity=1.0, usedResources=<memory:2048, vCores:1>, usedCapacity=0.25, absoluteUsedCapacity=0.25, numApps=1, numContainers=1 clusterResource=<memory:8192, vCores:8>
2015-01-14 19:48:18,066 INFO org.apache.hadoop.yarn.server.resourcemanager.scheduler.capacity.ParentQueue: Re-sorting assigned queue: root.default stats: default: capacity=1.0, absoluteCapacity=1.0, usedResources=<memory:3072, vCores:2>, usedCapacity=0.375, absoluteUsedCapacity=0.375, numApps=1, numContainers=2
2015-01-14 19:48:18,066 INFO org.apache.hadoop.yarn.server.resourcemanager.scheduler.capacity.ParentQueue: assignedContainer queue=root usedCapacity=0.375 absoluteUsedCapacity=0.375 used=<memory:3072, vCores:2> cluster=<memory:8192, vCores:8>
2015-01-14 19:48:18,066 INFO org.apache.hadoop.yarn.server.resourcemanager.rmcontainer.RMContainerImpl: container_1421286406893_0001_01_000003 Container Transitioned from NEW to ALLOCATED
2015-01-14 19:48:18,067 INFO org.apache.hadoop.yarn.server.resourcemanager.RMAuditLogger: USER=doopy	OPERATION=AM Allocated Container	TARGET=SchedulerApp	RESULT=SUCCESS	APPID=application_1421286406893_0001	CONTAINERID=container_1421286406893_0001_01_000003
2015-01-14 19:48:18,067 INFO org.apache.hadoop.yarn.server.resourcemanager.scheduler.SchedulerNode: Assigned container container_1421286406893_0001_01_000003 of capacity <memory:1024, vCores:1> on host barbie:45258, which has 3 containers, <memory:4096, vCores:3> used and <memory:4096, vCores:5> available after allocation
2015-01-14 19:48:18,067 INFO org.apache.hadoop.yarn.server.resourcemanager.scheduler.capacity.LeafQueue: assignedContainer application attempt=appattempt_1421286406893_0001_000001 container=Container: [ContainerId: container_1421286406893_0001_01_000003, NodeId: barbie:45258, NodeHttpAddress: barbie:8042, Resource: <memory:1024, vCores:1>, Priority: 20, Token: null, ] queue=default: capacity=1.0, absoluteCapacity=1.0, usedResources=<memory:3072, vCores:2>, usedCapacity=0.375, absoluteUsedCapacity=0.375, numApps=1, numContainers=2 clusterResource=<memory:8192, vCores:8>
2015-01-14 19:48:18,067 INFO org.apache.hadoop.yarn.server.resourcemanager.scheduler.capacity.ParentQueue: Re-sorting assigned queue: root.default stats: default: capacity=1.0, absoluteCapacity=1.0, usedResources=<memory:4096, vCores:3>, usedCapacity=0.5, absoluteUsedCapacity=0.5, numApps=1, numContainers=3
2015-01-14 19:48:18,067 INFO org.apache.hadoop.yarn.server.resourcemanager.scheduler.capacity.ParentQueue: assignedContainer queue=root usedCapacity=0.5 absoluteUsedCapacity=0.5 used=<memory:4096, vCores:3> cluster=<memory:8192, vCores:8>
2015-01-14 19:48:18,070 INFO org.apache.hadoop.yarn.server.resourcemanager.rmcontainer.RMContainerImpl: container_1421286406893_0001_01_000004 Container Transitioned from NEW to ALLOCATED
2015-01-14 19:48:18,071 INFO org.apache.hadoop.yarn.server.resourcemanager.RMAuditLogger: USER=doopy	OPERATION=AM Allocated Container	TARGET=SchedulerApp	RESULT=SUCCESS	APPID=application_1421286406893_0001	CONTAINERID=container_1421286406893_0001_01_000004
2015-01-14 19:48:18,071 INFO org.apache.hadoop.yarn.server.resourcemanager.scheduler.SchedulerNode: Assigned container container_1421286406893_0001_01_000004 of capacity <memory:1024, vCores:1> on host barbie:45258, which has 4 containers, <memory:5120, vCores:4> used and <memory:3072, vCores:4> available after allocation
2015-01-14 19:48:18,071 INFO org.apache.hadoop.yarn.server.resourcemanager.scheduler.capacity.LeafQueue: assignedContainer application attempt=appattempt_1421286406893_0001_000001 container=Container: [ContainerId: container_1421286406893_0001_01_000004, NodeId: barbie:45258, NodeHttpAddress: barbie:8042, Resource: <memory:1024, vCores:1>, Priority: 20, Token: null, ] queue=default: capacity=1.0, absoluteCapacity=1.0, usedResources=<memory:4096, vCores:3>, usedCapacity=0.5, absoluteUsedCapacity=0.5, numApps=1, numContainers=3 clusterResource=<memory:8192, vCores:8>
2015-01-14 19:48:18,074 INFO org.apache.hadoop.yarn.server.resourcemanager.scheduler.capacity.ParentQueue: Re-sorting assigned queue: root.default stats: default: capacity=1.0, absoluteCapacity=1.0, usedResources=<memory:5120, vCores:4>, usedCapacity=0.625, absoluteUsedCapacity=0.625, numApps=1, numContainers=4
2015-01-14 19:48:18,074 INFO org.apache.hadoop.yarn.server.resourcemanager.scheduler.capacity.ParentQueue: assignedContainer queue=root usedCapacity=0.625 absoluteUsedCapacity=0.625 used=<memory:5120, vCores:4> cluster=<memory:8192, vCores:8>
2015-01-14 19:48:18,078 INFO org.apache.hadoop.yarn.server.resourcemanager.rmcontainer.RMContainerImpl: container_1421286406893_0001_01_000005 Container Transitioned from NEW to ALLOCATED
2015-01-14 19:48:18,078 INFO org.apache.hadoop.yarn.server.resourcemanager.RMAuditLogger: USER=doopy	OPERATION=AM Allocated Container	TARGET=SchedulerApp	RESULT=SUCCESS	APPID=application_1421286406893_0001	CONTAINERID=container_1421286406893_0001_01_000005
2015-01-14 19:48:18,078 INFO org.apache.hadoop.yarn.server.resourcemanager.scheduler.SchedulerNode: Assigned container container_1421286406893_0001_01_000005 of capacity <memory:1024, vCores:1> on host barbie:45258, which has 5 containers, <memory:6144, vCores:5> used and <memory:2048, vCores:3> available after allocation
2015-01-14 19:48:18,078 INFO org.apache.hadoop.yarn.server.resourcemanager.scheduler.capacity.LeafQueue: assignedContainer application attempt=appattempt_1421286406893_0001_000001 container=Container: [ContainerId: container_1421286406893_0001_01_000005, NodeId: barbie:45258, NodeHttpAddress: barbie:8042, Resource: <memory:1024, vCores:1>, Priority: 20, Token: null, ] queue=default: capacity=1.0, absoluteCapacity=1.0, usedResources=<memory:5120, vCores:4>, usedCapacity=0.625, absoluteUsedCapacity=0.625, numApps=1, numContainers=4 clusterResource=<memory:8192, vCores:8>
2015-01-14 19:48:18,079 INFO org.apache.hadoop.yarn.server.resourcemanager.scheduler.capacity.ParentQueue: Re-sorting assigned queue: root.default stats: default: capacity=1.0, absoluteCapacity=1.0, usedResources=<memory:6144, vCores:5>, usedCapacity=0.75, absoluteUsedCapacity=0.75, numApps=1, numContainers=5
2015-01-14 19:48:18,079 INFO org.apache.hadoop.yarn.server.resourcemanager.scheduler.capacity.ParentQueue: assignedContainer queue=root usedCapacity=0.75 absoluteUsedCapacity=0.75 used=<memory:6144, vCores:5> cluster=<memory:8192, vCores:8>
2015-01-14 19:48:18,080 INFO org.apache.hadoop.yarn.server.resourcemanager.rmcontainer.RMContainerImpl: container_1421286406893_0001_01_000006 Container Transitioned from NEW to ALLOCATED
2015-01-14 19:48:18,080 INFO org.apache.hadoop.yarn.server.resourcemanager.RMAuditLogger: USER=doopy	OPERATION=AM Allocated Container	TARGET=SchedulerApp	RESULT=SUCCESS	APPID=application_1421286406893_0001	CONTAINERID=container_1421286406893_0001_01_000006
2015-01-14 19:48:18,080 INFO org.apache.hadoop.yarn.server.resourcemanager.scheduler.SchedulerNode: Assigned container container_1421286406893_0001_01_000006 of capacity <memory:1024, vCores:1> on host barbie:45258, which has 6 containers, <memory:7168, vCores:6> used and <memory:1024, vCores:2> available after allocation
2015-01-14 19:48:18,081 INFO org.apache.hadoop.yarn.server.resourcemanager.scheduler.capacity.LeafQueue: assignedContainer application attempt=appattempt_1421286406893_0001_000001 container=Container: [ContainerId: container_1421286406893_0001_01_000006, NodeId: barbie:45258, NodeHttpAddress: barbie:8042, Resource: <memory:1024, vCores:1>, Priority: 20, Token: null, ] queue=default: capacity=1.0, absoluteCapacity=1.0, usedResources=<memory:6144, vCores:5>, usedCapacity=0.75, absoluteUsedCapacity=0.75, numApps=1, numContainers=5 clusterResource=<memory:8192, vCores:8>
2015-01-14 19:48:18,081 INFO org.apache.hadoop.yarn.server.resourcemanager.scheduler.capacity.ParentQueue: Re-sorting assigned queue: root.default stats: default: capacity=1.0, absoluteCapacity=1.0, usedResources=<memory:7168, vCores:6>, usedCapacity=0.875, absoluteUsedCapacity=0.875, numApps=1, numContainers=6
2015-01-14 19:48:18,081 INFO org.apache.hadoop.yarn.server.resourcemanager.scheduler.capacity.ParentQueue: assignedContainer queue=root usedCapacity=0.875 absoluteUsedCapacity=0.875 used=<memory:7168, vCores:6> cluster=<memory:8192, vCores:8>
2015-01-14 19:48:18,082 INFO org.apache.hadoop.yarn.server.resourcemanager.rmcontainer.RMContainerImpl: container_1421286406893_0001_01_000007 Container Transitioned from NEW to ALLOCATED
2015-01-14 19:48:18,083 INFO org.apache.hadoop.yarn.server.resourcemanager.RMAuditLogger: USER=doopy	OPERATION=AM Allocated Container	TARGET=SchedulerApp	RESULT=SUCCESS	APPID=application_1421286406893_0001	CONTAINERID=container_1421286406893_0001_01_000007
2015-01-14 19:48:18,084 INFO org.apache.hadoop.yarn.server.resourcemanager.scheduler.SchedulerNode: Assigned container container_1421286406893_0001_01_000007 of capacity <memory:1024, vCores:1> on host barbie:45258, which has 7 containers, <memory:8192, vCores:7> used and <memory:0, vCores:1> available after allocation
2015-01-14 19:48:18,084 INFO org.apache.hadoop.yarn.server.resourcemanager.scheduler.capacity.LeafQueue: assignedContainer application attempt=appattempt_1421286406893_0001_000001 container=Container: [ContainerId: container_1421286406893_0001_01_000007, NodeId: barbie:45258, NodeHttpAddress: barbie:8042, Resource: <memory:1024, vCores:1>, Priority: 20, Token: null, ] queue=default: capacity=1.0, absoluteCapacity=1.0, usedResources=<memory:7168, vCores:6>, usedCapacity=0.875, absoluteUsedCapacity=0.875, numApps=1, numContainers=6 clusterResource=<memory:8192, vCores:8>
2015-01-14 19:48:18,084 INFO org.apache.hadoop.yarn.server.resourcemanager.scheduler.capacity.ParentQueue: Re-sorting assigned queue: root.default stats: default: capacity=1.0, absoluteCapacity=1.0, usedResources=<memory:8192, vCores:7>, usedCapacity=1.0, absoluteUsedCapacity=1.0, numApps=1, numContainers=7
2015-01-14 19:48:18,086 INFO org.apache.hadoop.yarn.server.resourcemanager.scheduler.capacity.ParentQueue: assignedContainer queue=root usedCapacity=1.0 absoluteUsedCapacity=1.0 used=<memory:8192, vCores:7> cluster=<memory:8192, vCores:8>
2015-01-14 19:48:18,507 INFO org.apache.hadoop.yarn.server.resourcemanager.security.NMTokenSecretManagerInRM: Sending NMToken for nodeId : barbie:45258 for container : container_1421286406893_0001_01_000002
2015-01-14 19:48:18,516 INFO org.apache.hadoop.yarn.server.resourcemanager.rmcontainer.RMContainerImpl: container_1421286406893_0001_01_000002 Container Transitioned from ALLOCATED to ACQUIRED
2015-01-14 19:48:18,519 INFO org.apache.hadoop.yarn.server.resourcemanager.rmcontainer.RMContainerImpl: container_1421286406893_0001_01_000003 Container Transitioned from ALLOCATED to ACQUIRED
2015-01-14 19:48:18,528 INFO org.apache.hadoop.yarn.server.resourcemanager.rmcontainer.RMContainerImpl: container_1421286406893_0001_01_000004 Container Transitioned from ALLOCATED to ACQUIRED
2015-01-14 19:48:18,539 INFO org.apache.hadoop.yarn.server.resourcemanager.rmcontainer.RMContainerImpl: container_1421286406893_0001_01_000005 Container Transitioned from ALLOCATED to ACQUIRED
2015-01-14 19:48:18,542 INFO org.apache.hadoop.yarn.server.resourcemanager.rmcontainer.RMContainerImpl: container_1421286406893_0001_01_000006 Container Transitioned from ALLOCATED to ACQUIRED
2015-01-14 19:48:18,546 INFO org.apache.hadoop.yarn.server.resourcemanager.rmcontainer.RMContainerImpl: container_1421286406893_0001_01_000007 Container Transitioned from ALLOCATED to ACQUIRED
2015-01-14 19:48:20,078 INFO org.apache.hadoop.yarn.server.resourcemanager.rmcontainer.RMContainerImpl: container_1421286406893_0001_01_000002 Container Transitioned from ACQUIRED to RUNNING
2015-01-14 19:48:20,078 INFO org.apache.hadoop.yarn.server.resourcemanager.rmcontainer.RMContainerImpl: container_1421286406893_0001_01_000003 Container Transitioned from ACQUIRED to RUNNING
2015-01-14 19:48:20,079 INFO org.apache.hadoop.yarn.server.resourcemanager.rmcontainer.RMContainerImpl: container_1421286406893_0001_01_000004 Container Transitioned from ACQUIRED to RUNNING
2015-01-14 19:48:20,079 INFO org.apache.hadoop.yarn.server.resourcemanager.rmcontainer.RMContainerImpl: container_1421286406893_0001_01_000005 Container Transitioned from ACQUIRED to RUNNING
2015-01-14 19:48:20,082 INFO org.apache.hadoop.yarn.server.resourcemanager.rmcontainer.RMContainerImpl: container_1421286406893_0001_01_000006 Container Transitioned from ACQUIRED to RUNNING
2015-01-14 19:48:20,082 INFO org.apache.hadoop.yarn.server.resourcemanager.rmcontainer.RMContainerImpl: container_1421286406893_0001_01_000007 Container Transitioned from ACQUIRED to RUNNING
2015-01-14 19:50:22,858 INFO SecurityLogger.org.apache.hadoop.ipc.Server: Auth successful for appattempt_1421286406893_0001_000001 (auth:SIMPLE)
2015-01-14 19:50:54,458 INFO org.apache.hadoop.yarn.server.resourcemanager.rmcontainer.RMContainerImpl: container_1421286406893_0001_01_000002 Container Transitioned from RUNNING to COMPLETED
2015-01-14 19:50:54,544 INFO org.apache.hadoop.yarn.server.resourcemanager.scheduler.common.fica.FiCaSchedulerApp: Completed container: container_1421286406893_0001_01_000002 in state: COMPLETED event:FINISHED
2015-01-14 19:50:54,585 INFO org.apache.hadoop.yarn.server.resourcemanager.RMAuditLogger: USER=doopy	OPERATION=AM Released Container	TARGET=SchedulerApp	RESULT=SUCCESS	APPID=application_1421286406893_0001	CONTAINERID=container_1421286406893_0001_01_000002
2015-01-14 19:50:54,587 INFO org.apache.hadoop.yarn.server.resourcemanager.scheduler.SchedulerNode: Released container container_1421286406893_0001_01_000002 of capacity <memory:1024, vCores:1> on host barbie:45258, which currently has 6 containers, <memory:7168, vCores:6> used and <memory:1024, vCores:2> available, release resources=true
2015-01-14 19:50:54,657 INFO org.apache.hadoop.yarn.server.resourcemanager.scheduler.capacity.LeafQueue: default used=<memory:7168, vCores:6> numContainers=6 user=doopy user-resources=<memory:7168, vCores:6>
2015-01-14 19:50:54,835 INFO org.apache.hadoop.yarn.server.resourcemanager.scheduler.capacity.LeafQueue: completedContainer container=Container: [ContainerId: container_1421286406893_0001_01_000002, NodeId: barbie:45258, NodeHttpAddress: barbie:8042, Resource: <memory:1024, vCores:1>, Priority: 20, Token: Token { kind: ContainerToken, service: 127.0.1.1:45258 }, ] queue=default: capacity=1.0, absoluteCapacity=1.0, usedResources=<memory:7168, vCores:6>, usedCapacity=0.875, absoluteUsedCapacity=0.875, numApps=1, numContainers=6 cluster=<memory:8192, vCores:8>
2015-01-14 19:50:54,835 INFO org.apache.hadoop.yarn.server.resourcemanager.scheduler.capacity.ParentQueue: completedContainer queue=root usedCapacity=0.875 absoluteUsedCapacity=0.875 used=<memory:7168, vCores:6> cluster=<memory:8192, vCores:8>
2015-01-14 19:50:55,048 INFO org.apache.hadoop.yarn.server.resourcemanager.scheduler.capacity.ParentQueue: Re-sorting completed queue: root.default stats: default: capacity=1.0, absoluteCapacity=1.0, usedResources=<memory:7168, vCores:6>, usedCapacity=0.875, absoluteUsedCapacity=0.875, numApps=1, numContainers=6
2015-01-14 19:50:55,049 INFO org.apache.hadoop.yarn.server.resourcemanager.scheduler.capacity.CapacityScheduler: Application attempt appattempt_1421286406893_0001_000001 released container container_1421286406893_0001_01_000002 on node: host: barbie:45258 #containers=6 available=1024 used=7168 with event: FINISHED
2015-01-14 19:50:55,049 INFO org.apache.hadoop.yarn.server.resourcemanager.rmcontainer.RMContainerImpl: container_1421286406893_0001_01_000003 Container Transitioned from RUNNING to COMPLETED
2015-01-14 19:50:55,049 INFO org.apache.hadoop.yarn.server.resourcemanager.scheduler.common.fica.FiCaSchedulerApp: Completed container: container_1421286406893_0001_01_000003 in state: COMPLETED event:FINISHED
2015-01-14 19:50:55,049 INFO org.apache.hadoop.yarn.server.resourcemanager.RMAuditLogger: USER=doopy	OPERATION=AM Released Container	TARGET=SchedulerApp	RESULT=SUCCESS	APPID=application_1421286406893_0001	CONTAINERID=container_1421286406893_0001_01_000003
2015-01-14 19:50:55,050 INFO org.apache.hadoop.yarn.server.resourcemanager.scheduler.SchedulerNode: Released container container_1421286406893_0001_01_000003 of capacity <memory:1024, vCores:1> on host barbie:45258, which currently has 5 containers, <memory:6144, vCores:5> used and <memory:2048, vCores:3> available, release resources=true
2015-01-14 19:50:55,050 INFO org.apache.hadoop.yarn.server.resourcemanager.scheduler.capacity.LeafQueue: default used=<memory:6144, vCores:5> numContainers=5 user=doopy user-resources=<memory:6144, vCores:5>
2015-01-14 19:50:55,050 INFO org.apache.hadoop.yarn.server.resourcemanager.scheduler.capacity.LeafQueue: completedContainer container=Container: [ContainerId: container_1421286406893_0001_01_000003, NodeId: barbie:45258, NodeHttpAddress: barbie:8042, Resource: <memory:1024, vCores:1>, Priority: 20, Token: Token { kind: ContainerToken, service: 127.0.1.1:45258 }, ] queue=default: capacity=1.0, absoluteCapacity=1.0, usedResources=<memory:6144, vCores:5>, usedCapacity=0.75, absoluteUsedCapacity=0.75, numApps=1, numContainers=5 cluster=<memory:8192, vCores:8>
2015-01-14 19:50:55,050 INFO org.apache.hadoop.yarn.server.resourcemanager.scheduler.capacity.ParentQueue: completedContainer queue=root usedCapacity=0.75 absoluteUsedCapacity=0.75 used=<memory:6144, vCores:5> cluster=<memory:8192, vCores:8>
2015-01-14 19:50:55,051 INFO org.apache.hadoop.yarn.server.resourcemanager.scheduler.capacity.ParentQueue: Re-sorting completed queue: root.default stats: default: capacity=1.0, absoluteCapacity=1.0, usedResources=<memory:6144, vCores:5>, usedCapacity=0.75, absoluteUsedCapacity=0.75, numApps=1, numContainers=5
2015-01-14 19:50:55,051 INFO org.apache.hadoop.yarn.server.resourcemanager.scheduler.capacity.CapacityScheduler: Application attempt appattempt_1421286406893_0001_000001 released container container_1421286406893_0001_01_000003 on node: host: barbie:45258 #containers=5 available=2048 used=6144 with event: FINISHED
2015-01-14 19:50:55,051 INFO org.apache.hadoop.yarn.server.resourcemanager.rmcontainer.RMContainerImpl: container_1421286406893_0001_01_000004 Container Transitioned from RUNNING to COMPLETED
2015-01-14 19:50:55,082 INFO org.apache.hadoop.yarn.server.resourcemanager.scheduler.common.fica.FiCaSchedulerApp: Completed container: container_1421286406893_0001_01_000004 in state: COMPLETED event:FINISHED
2015-01-14 19:50:55,082 INFO org.apache.hadoop.yarn.server.resourcemanager.RMAuditLogger: USER=doopy	OPERATION=AM Released Container	TARGET=SchedulerApp	RESULT=SUCCESS	APPID=application_1421286406893_0001	CONTAINERID=container_1421286406893_0001_01_000004
2015-01-14 19:50:55,082 INFO org.apache.hadoop.yarn.server.resourcemanager.scheduler.SchedulerNode: Released container container_1421286406893_0001_01_000004 of capacity <memory:1024, vCores:1> on host barbie:45258, which currently has 4 containers, <memory:5120, vCores:4> used and <memory:3072, vCores:4> available, release resources=true
2015-01-14 19:50:55,082 INFO org.apache.hadoop.yarn.server.resourcemanager.scheduler.capacity.LeafQueue: default used=<memory:5120, vCores:4> numContainers=4 user=doopy user-resources=<memory:5120, vCores:4>
2015-01-14 19:50:55,083 INFO org.apache.hadoop.yarn.server.resourcemanager.scheduler.capacity.LeafQueue: completedContainer container=Container: [ContainerId: container_1421286406893_0001_01_000004, NodeId: barbie:45258, NodeHttpAddress: barbie:8042, Resource: <memory:1024, vCores:1>, Priority: 20, Token: Token { kind: ContainerToken, service: 127.0.1.1:45258 }, ] queue=default: capacity=1.0, absoluteCapacity=1.0, usedResources=<memory:5120, vCores:4>, usedCapacity=0.625, absoluteUsedCapacity=0.625, numApps=1, numContainers=4 cluster=<memory:8192, vCores:8>
2015-01-14 19:50:55,083 INFO org.apache.hadoop.yarn.server.resourcemanager.scheduler.capacity.ParentQueue: completedContainer queue=root usedCapacity=0.625 absoluteUsedCapacity=0.625 used=<memory:5120, vCores:4> cluster=<memory:8192, vCores:8>
2015-01-14 19:50:55,116 INFO org.apache.hadoop.yarn.server.resourcemanager.scheduler.capacity.ParentQueue: Re-sorting completed queue: root.default stats: default: capacity=1.0, absoluteCapacity=1.0, usedResources=<memory:5120, vCores:4>, usedCapacity=0.625, absoluteUsedCapacity=0.625, numApps=1, numContainers=4
2015-01-14 19:50:55,116 INFO org.apache.hadoop.yarn.server.resourcemanager.scheduler.capacity.CapacityScheduler: Application attempt appattempt_1421286406893_0001_000001 released container container_1421286406893_0001_01_000004 on node: host: barbie:45258 #containers=4 available=3072 used=5120 with event: FINISHED
2015-01-14 19:50:55,117 INFO org.apache.hadoop.yarn.server.resourcemanager.rmcontainer.RMContainerImpl: container_1421286406893_0001_01_000005 Container Transitioned from RUNNING to COMPLETED
2015-01-14 19:50:55,117 INFO org.apache.hadoop.yarn.server.resourcemanager.scheduler.common.fica.FiCaSchedulerApp: Completed container: container_1421286406893_0001_01_000005 in state: COMPLETED event:FINISHED
2015-01-14 19:50:55,117 INFO org.apache.hadoop.yarn.server.resourcemanager.RMAuditLogger: USER=doopy	OPERATION=AM Released Container	TARGET=SchedulerApp	RESULT=SUCCESS	APPID=application_1421286406893_0001	CONTAINERID=container_1421286406893_0001_01_000005
2015-01-14 19:50:55,117 INFO org.apache.hadoop.yarn.server.resourcemanager.scheduler.SchedulerNode: Released container container_1421286406893_0001_01_000005 of capacity <memory:1024, vCores:1> on host barbie:45258, which currently has 3 containers, <memory:4096, vCores:3> used and <memory:4096, vCores:5> available, release resources=true
2015-01-14 19:50:55,118 INFO org.apache.hadoop.yarn.server.resourcemanager.scheduler.capacity.LeafQueue: default used=<memory:4096, vCores:3> numContainers=3 user=doopy user-resources=<memory:4096, vCores:3>
2015-01-14 19:50:55,184 INFO org.apache.hadoop.yarn.server.resourcemanager.scheduler.capacity.LeafQueue: completedContainer container=Container: [ContainerId: container_1421286406893_0001_01_000005, NodeId: barbie:45258, NodeHttpAddress: barbie:8042, Resource: <memory:1024, vCores:1>, Priority: 20, Token: Token { kind: ContainerToken, service: 127.0.1.1:45258 }, ] queue=default: capacity=1.0, absoluteCapacity=1.0, usedResources=<memory:4096, vCores:3>, usedCapacity=0.5, absoluteUsedCapacity=0.5, numApps=1, numContainers=3 cluster=<memory:8192, vCores:8>
2015-01-14 19:50:55,184 INFO org.apache.hadoop.yarn.server.resourcemanager.scheduler.capacity.ParentQueue: completedContainer queue=root usedCapacity=0.5 absoluteUsedCapacity=0.5 used=<memory:4096, vCores:3> cluster=<memory:8192, vCores:8>
2015-01-14 19:50:55,184 INFO org.apache.hadoop.yarn.server.resourcemanager.scheduler.capacity.ParentQueue: Re-sorting completed queue: root.default stats: default: capacity=1.0, absoluteCapacity=1.0, usedResources=<memory:4096, vCores:3>, usedCapacity=0.5, absoluteUsedCapacity=0.5, numApps=1, numContainers=3
2015-01-14 19:50:55,184 INFO org.apache.hadoop.yarn.server.resourcemanager.scheduler.capacity.CapacityScheduler: Application attempt appattempt_1421286406893_0001_000001 released container container_1421286406893_0001_01_000005 on node: host: barbie:45258 #containers=3 available=4096 used=4096 with event: FINISHED
2015-01-14 19:50:55,185 INFO org.apache.hadoop.yarn.server.resourcemanager.rmcontainer.RMContainerImpl: container_1421286406893_0001_01_000006 Container Transitioned from RUNNING to COMPLETED
2015-01-14 19:50:55,218 INFO org.apache.hadoop.yarn.server.resourcemanager.scheduler.common.fica.FiCaSchedulerApp: Completed container: container_1421286406893_0001_01_000006 in state: COMPLETED event:FINISHED
2015-01-14 19:50:55,218 INFO org.apache.hadoop.yarn.server.resourcemanager.RMAuditLogger: USER=doopy	OPERATION=AM Released Container	TARGET=SchedulerApp	RESULT=SUCCESS	APPID=application_1421286406893_0001	CONTAINERID=container_1421286406893_0001_01_000006
2015-01-14 19:50:55,218 INFO org.apache.hadoop.yarn.server.resourcemanager.scheduler.SchedulerNode: Released container container_1421286406893_0001_01_000006 of capacity <memory:1024, vCores:1> on host barbie:45258, which currently has 2 containers, <memory:3072, vCores:2> used and <memory:5120, vCores:6> available, release resources=true
2015-01-14 19:50:55,218 INFO org.apache.hadoop.yarn.server.resourcemanager.scheduler.capacity.LeafQueue: default used=<memory:3072, vCores:2> numContainers=2 user=doopy user-resources=<memory:3072, vCores:2>
2015-01-14 19:50:55,219 INFO org.apache.hadoop.yarn.server.resourcemanager.scheduler.capacity.LeafQueue: completedContainer container=Container: [ContainerId: container_1421286406893_0001_01_000006, NodeId: barbie:45258, NodeHttpAddress: barbie:8042, Resource: <memory:1024, vCores:1>, Priority: 20, Token: Token { kind: ContainerToken, service: 127.0.1.1:45258 }, ] queue=default: capacity=1.0, absoluteCapacity=1.0, usedResources=<memory:3072, vCores:2>, usedCapacity=0.375, absoluteUsedCapacity=0.375, numApps=1, numContainers=2 cluster=<memory:8192, vCores:8>
2015-01-14 19:50:55,219 INFO org.apache.hadoop.yarn.server.resourcemanager.scheduler.capacity.ParentQueue: completedContainer queue=root usedCapacity=0.375 absoluteUsedCapacity=0.375 used=<memory:3072, vCores:2> cluster=<memory:8192, vCores:8>
2015-01-14 19:50:55,264 INFO org.apache.hadoop.yarn.server.resourcemanager.scheduler.capacity.ParentQueue: Re-sorting completed queue: root.default stats: default: capacity=1.0, absoluteCapacity=1.0, usedResources=<memory:3072, vCores:2>, usedCapacity=0.375, absoluteUsedCapacity=0.375, numApps=1, numContainers=2
2015-01-14 19:50:55,265 INFO org.apache.hadoop.yarn.server.resourcemanager.scheduler.capacity.CapacityScheduler: Application attempt appattempt_1421286406893_0001_000001 released container container_1421286406893_0001_01_000006 on node: host: barbie:45258 #containers=2 available=5120 used=3072 with event: FINISHED
2015-01-14 19:50:55,287 INFO org.apache.hadoop.yarn.server.resourcemanager.rmcontainer.RMContainerImpl: container_1421286406893_0001_01_000007 Container Transitioned from RUNNING to COMPLETED
2015-01-14 19:50:55,287 INFO org.apache.hadoop.yarn.server.resourcemanager.scheduler.common.fica.FiCaSchedulerApp: Completed container: container_1421286406893_0001_01_000007 in state: COMPLETED event:FINISHED
2015-01-14 19:50:55,287 INFO org.apache.hadoop.yarn.server.resourcemanager.RMAuditLogger: USER=doopy	OPERATION=AM Released Container	TARGET=SchedulerApp	RESULT=SUCCESS	APPID=application_1421286406893_0001	CONTAINERID=container_1421286406893_0001_01_000007
2015-01-14 19:50:55,287 INFO org.apache.hadoop.yarn.server.resourcemanager.scheduler.SchedulerNode: Released container container_1421286406893_0001_01_000007 of capacity <memory:1024, vCores:1> on host barbie:45258, which currently has 1 containers, <memory:2048, vCores:1> used and <memory:6144, vCores:7> available, release resources=true
2015-01-14 19:50:55,317 INFO org.apache.hadoop.yarn.server.resourcemanager.scheduler.capacity.LeafQueue: default used=<memory:2048, vCores:1> numContainers=1 user=doopy user-resources=<memory:2048, vCores:1>
2015-01-14 19:50:55,317 INFO org.apache.hadoop.yarn.server.resourcemanager.scheduler.capacity.LeafQueue: completedContainer container=Container: [ContainerId: container_1421286406893_0001_01_000007, NodeId: barbie:45258, NodeHttpAddress: barbie:8042, Resource: <memory:1024, vCores:1>, Priority: 20, Token: Token { kind: ContainerToken, service: 127.0.1.1:45258 }, ] queue=default: capacity=1.0, absoluteCapacity=1.0, usedResources=<memory:2048, vCores:1>, usedCapacity=0.25, absoluteUsedCapacity=0.25, numApps=1, numContainers=1 cluster=<memory:8192, vCores:8>
2015-01-14 19:50:55,318 INFO org.apache.hadoop.yarn.server.resourcemanager.scheduler.capacity.ParentQueue: completedContainer queue=root usedCapacity=0.25 absoluteUsedCapacity=0.25 used=<memory:2048, vCores:1> cluster=<memory:8192, vCores:8>
2015-01-14 19:50:55,318 INFO org.apache.hadoop.yarn.server.resourcemanager.scheduler.capacity.ParentQueue: Re-sorting completed queue: root.default stats: default: capacity=1.0, absoluteCapacity=1.0, usedResources=<memory:2048, vCores:1>, usedCapacity=0.25, absoluteUsedCapacity=0.25, numApps=1, numContainers=1
2015-01-14 19:50:55,318 INFO org.apache.hadoop.yarn.server.resourcemanager.scheduler.capacity.CapacityScheduler: Application attempt appattempt_1421286406893_0001_000001 released container container_1421286406893_0001_01_000007 on node: host: barbie:45258 #containers=1 available=6144 used=2048 with event: FINISHED
2015-01-14 19:50:55,326 INFO org.apache.hadoop.yarn.server.resourcemanager.rmcontainer.RMContainerImpl: container_1421286406893_0001_01_000008 Container Transitioned from NEW to ALLOCATED
2015-01-14 19:50:55,326 INFO org.apache.hadoop.yarn.server.resourcemanager.RMAuditLogger: USER=doopy	OPERATION=AM Allocated Container	TARGET=SchedulerApp	RESULT=SUCCESS	APPID=application_1421286406893_0001	CONTAINERID=container_1421286406893_0001_01_000008
2015-01-14 19:50:55,326 INFO org.apache.hadoop.yarn.server.resourcemanager.scheduler.SchedulerNode: Assigned container container_1421286406893_0001_01_000008 of capacity <memory:1024, vCores:1> on host barbie:45258, which has 2 containers, <memory:3072, vCores:2> used and <memory:5120, vCores:6> available after allocation
2015-01-14 19:50:55,326 INFO org.apache.hadoop.yarn.server.resourcemanager.scheduler.capacity.LeafQueue: assignedContainer application attempt=appattempt_1421286406893_0001_000001 container=Container: [ContainerId: container_1421286406893_0001_01_000008, NodeId: barbie:45258, NodeHttpAddress: barbie:8042, Resource: <memory:1024, vCores:1>, Priority: 10, Token: null, ] queue=default: capacity=1.0, absoluteCapacity=1.0, usedResources=<memory:2048, vCores:1>, usedCapacity=0.25, absoluteUsedCapacity=0.25, numApps=1, numContainers=1 clusterResource=<memory:8192, vCores:8>
2015-01-14 19:50:55,362 INFO org.apache.hadoop.yarn.server.resourcemanager.scheduler.capacity.ParentQueue: Re-sorting assigned queue: root.default stats: default: capacity=1.0, absoluteCapacity=1.0, usedResources=<memory:3072, vCores:2>, usedCapacity=0.375, absoluteUsedCapacity=0.375, numApps=1, numContainers=2
2015-01-14 19:50:55,362 INFO org.apache.hadoop.yarn.server.resourcemanager.scheduler.capacity.ParentQueue: assignedContainer queue=root usedCapacity=0.375 absoluteUsedCapacity=0.375 used=<memory:3072, vCores:2> cluster=<memory:8192, vCores:8>
2015-01-14 19:50:55,362 INFO org.apache.hadoop.yarn.server.resourcemanager.scheduler.capacity.CapacityScheduler: Null container completed...
2015-01-14 19:50:55,363 INFO org.apache.hadoop.yarn.server.resourcemanager.scheduler.capacity.CapacityScheduler: Null container completed...
2015-01-14 19:50:55,363 INFO org.apache.hadoop.yarn.server.resourcemanager.scheduler.capacity.CapacityScheduler: Null container completed...
2015-01-14 19:50:55,363 INFO org.apache.hadoop.yarn.server.resourcemanager.scheduler.capacity.CapacityScheduler: Null container completed...
2015-01-14 19:50:55,363 INFO org.apache.hadoop.yarn.server.resourcemanager.scheduler.capacity.CapacityScheduler: Null container completed...
2015-01-14 19:50:55,364 INFO org.apache.hadoop.yarn.server.resourcemanager.scheduler.capacity.CapacityScheduler: Null container completed...
2015-01-14 19:50:55,365 INFO org.apache.hadoop.yarn.server.resourcemanager.rmcontainer.RMContainerImpl: container_1421286406893_0001_01_000009 Container Transitioned from NEW to ALLOCATED
2015-01-14 19:50:55,365 INFO org.apache.hadoop.yarn.server.resourcemanager.RMAuditLogger: USER=doopy	OPERATION=AM Allocated Container	TARGET=SchedulerApp	RESULT=SUCCESS	APPID=application_1421286406893_0001	CONTAINERID=container_1421286406893_0001_01_000009
2015-01-14 19:50:55,413 INFO org.apache.hadoop.yarn.server.resourcemanager.scheduler.SchedulerNode: Assigned container container_1421286406893_0001_01_000009 of capacity <memory:1024, vCores:1> on host barbie:45258, which has 3 containers, <memory:4096, vCores:3> used and <memory:4096, vCores:5> available after allocation
2015-01-14 19:50:55,413 INFO org.apache.hadoop.yarn.server.resourcemanager.scheduler.capacity.LeafQueue: assignedContainer application attempt=appattempt_1421286406893_0001_000001 container=Container: [ContainerId: container_1421286406893_0001_01_000009, NodeId: barbie:45258, NodeHttpAddress: barbie:8042, Resource: <memory:1024, vCores:1>, Priority: 20, Token: null, ] queue=default: capacity=1.0, absoluteCapacity=1.0, usedResources=<memory:3072, vCores:2>, usedCapacity=0.375, absoluteUsedCapacity=0.375, numApps=1, numContainers=2 clusterResource=<memory:8192, vCores:8>
2015-01-14 19:50:55,414 INFO org.apache.hadoop.yarn.server.resourcemanager.scheduler.capacity.ParentQueue: Re-sorting assigned queue: root.default stats: default: capacity=1.0, absoluteCapacity=1.0, usedResources=<memory:4096, vCores:3>, usedCapacity=0.5, absoluteUsedCapacity=0.5, numApps=1, numContainers=3
2015-01-14 19:50:55,414 INFO org.apache.hadoop.yarn.server.resourcemanager.scheduler.capacity.ParentQueue: assignedContainer queue=root usedCapacity=0.5 absoluteUsedCapacity=0.5 used=<memory:4096, vCores:3> cluster=<memory:8192, vCores:8>
2015-01-14 19:50:55,443 INFO org.apache.hadoop.yarn.server.resourcemanager.rmcontainer.RMContainerImpl: container_1421286406893_0001_01_000010 Container Transitioned from NEW to ALLOCATED
2015-01-14 19:50:55,443 INFO org.apache.hadoop.yarn.server.resourcemanager.RMAuditLogger: USER=doopy	OPERATION=AM Allocated Container	TARGET=SchedulerApp	RESULT=SUCCESS	APPID=application_1421286406893_0001	CONTAINERID=container_1421286406893_0001_01_000010
2015-01-14 19:50:55,443 INFO org.apache.hadoop.yarn.server.resourcemanager.scheduler.SchedulerNode: Assigned container container_1421286406893_0001_01_000010 of capacity <memory:1024, vCores:1> on host barbie:45258, which has 4 containers, <memory:5120, vCores:4> used and <memory:3072, vCores:4> available after allocation
2015-01-14 19:50:55,465 INFO org.apache.hadoop.yarn.server.resourcemanager.scheduler.capacity.LeafQueue: assignedContainer application attempt=appattempt_1421286406893_0001_000001 container=Container: [ContainerId: container_1421286406893_0001_01_000010, NodeId: barbie:45258, NodeHttpAddress: barbie:8042, Resource: <memory:1024, vCores:1>, Priority: 20, Token: null, ] queue=default: capacity=1.0, absoluteCapacity=1.0, usedResources=<memory:4096, vCores:3>, usedCapacity=0.5, absoluteUsedCapacity=0.5, numApps=1, numContainers=3 clusterResource=<memory:8192, vCores:8>
2015-01-14 19:50:55,466 INFO org.apache.hadoop.yarn.server.resourcemanager.scheduler.capacity.ParentQueue: Re-sorting assigned queue: root.default stats: default: capacity=1.0, absoluteCapacity=1.0, usedResources=<memory:5120, vCores:4>, usedCapacity=0.625, absoluteUsedCapacity=0.625, numApps=1, numContainers=4
2015-01-14 19:50:55,466 INFO org.apache.hadoop.yarn.server.resourcemanager.scheduler.capacity.ParentQueue: assignedContainer queue=root usedCapacity=0.625 absoluteUsedCapacity=0.625 used=<memory:5120, vCores:4> cluster=<memory:8192, vCores:8>
2015-01-14 19:50:55,467 INFO org.apache.hadoop.yarn.server.resourcemanager.rmcontainer.RMContainerImpl: container_1421286406893_0001_01_000011 Container Transitioned from NEW to ALLOCATED
2015-01-14 19:50:55,467 INFO org.apache.hadoop.yarn.server.resourcemanager.RMAuditLogger: USER=doopy	OPERATION=AM Allocated Container	TARGET=SchedulerApp	RESULT=SUCCESS	APPID=application_1421286406893_0001	CONTAINERID=container_1421286406893_0001_01_000011
2015-01-14 19:50:55,498 INFO org.apache.hadoop.yarn.server.resourcemanager.scheduler.SchedulerNode: Assigned container container_1421286406893_0001_01_000011 of capacity <memory:1024, vCores:1> on host barbie:45258, which has 5 containers, <memory:6144, vCores:5> used and <memory:2048, vCores:3> available after allocation
2015-01-14 19:50:55,498 INFO org.apache.hadoop.yarn.server.resourcemanager.scheduler.capacity.LeafQueue: assignedContainer application attempt=appattempt_1421286406893_0001_000001 container=Container: [ContainerId: container_1421286406893_0001_01_000011, NodeId: barbie:45258, NodeHttpAddress: barbie:8042, Resource: <memory:1024, vCores:1>, Priority: 20, Token: null, ] queue=default: capacity=1.0, absoluteCapacity=1.0, usedResources=<memory:5120, vCores:4>, usedCapacity=0.625, absoluteUsedCapacity=0.625, numApps=1, numContainers=4 clusterResource=<memory:8192, vCores:8>
2015-01-14 19:50:55,498 INFO org.apache.hadoop.yarn.server.resourcemanager.scheduler.capacity.ParentQueue: Re-sorting assigned queue: root.default stats: default: capacity=1.0, absoluteCapacity=1.0, usedResources=<memory:6144, vCores:5>, usedCapacity=0.75, absoluteUsedCapacity=0.75, numApps=1, numContainers=5
2015-01-14 19:50:55,498 INFO org.apache.hadoop.yarn.server.resourcemanager.scheduler.capacity.ParentQueue: assignedContainer queue=root usedCapacity=0.75 absoluteUsedCapacity=0.75 used=<memory:6144, vCores:5> cluster=<memory:8192, vCores:8>
2015-01-14 19:50:55,578 INFO org.apache.hadoop.yarn.server.resourcemanager.rmcontainer.RMContainerImpl: container_1421286406893_0001_01_000012 Container Transitioned from NEW to ALLOCATED
2015-01-14 19:50:55,579 INFO org.apache.hadoop.yarn.server.resourcemanager.RMAuditLogger: USER=doopy	OPERATION=AM Allocated Container	TARGET=SchedulerApp	RESULT=SUCCESS	APPID=application_1421286406893_0001	CONTAINERID=container_1421286406893_0001_01_000012
2015-01-14 19:50:55,579 INFO org.apache.hadoop.yarn.server.resourcemanager.scheduler.SchedulerNode: Assigned container container_1421286406893_0001_01_000012 of capacity <memory:1024, vCores:1> on host barbie:45258, which has 6 containers, <memory:7168, vCores:6> used and <memory:1024, vCores:2> available after allocation
2015-01-14 19:50:55,579 INFO org.apache.hadoop.yarn.server.resourcemanager.scheduler.capacity.LeafQueue: assignedContainer application attempt=appattempt_1421286406893_0001_000001 container=Container: [ContainerId: container_1421286406893_0001_01_000012, NodeId: barbie:45258, NodeHttpAddress: barbie:8042, Resource: <memory:1024, vCores:1>, Priority: 20, Token: null, ] queue=default: capacity=1.0, absoluteCapacity=1.0, usedResources=<memory:6144, vCores:5>, usedCapacity=0.75, absoluteUsedCapacity=0.75, numApps=1, numContainers=5 clusterResource=<memory:8192, vCores:8>
2015-01-14 19:50:55,612 INFO org.apache.hadoop.yarn.server.resourcemanager.scheduler.capacity.ParentQueue: Re-sorting assigned queue: root.default stats: default: capacity=1.0, absoluteCapacity=1.0, usedResources=<memory:7168, vCores:6>, usedCapacity=0.875, absoluteUsedCapacity=0.875, numApps=1, numContainers=6
2015-01-14 19:50:55,612 INFO org.apache.hadoop.yarn.server.resourcemanager.scheduler.capacity.ParentQueue: assignedContainer queue=root usedCapacity=0.875 absoluteUsedCapacity=0.875 used=<memory:7168, vCores:6> cluster=<memory:8192, vCores:8>
2015-01-14 19:50:55,670 INFO org.apache.hadoop.yarn.server.resourcemanager.rmcontainer.RMContainerImpl: container_1421286406893_0001_01_000013 Container Transitioned from NEW to ALLOCATED
2015-01-14 19:50:55,670 INFO org.apache.hadoop.yarn.server.resourcemanager.RMAuditLogger: USER=doopy	OPERATION=AM Allocated Container	TARGET=SchedulerApp	RESULT=SUCCESS	APPID=application_1421286406893_0001	CONTAINERID=container_1421286406893_0001_01_000013
2015-01-14 19:50:55,670 INFO org.apache.hadoop.yarn.server.resourcemanager.scheduler.SchedulerNode: Assigned container container_1421286406893_0001_01_000013 of capacity <memory:1024, vCores:1> on host barbie:45258, which has 7 containers, <memory:8192, vCores:7> used and <memory:0, vCores:1> available after allocation
2015-01-14 19:50:55,670 INFO org.apache.hadoop.yarn.server.resourcemanager.scheduler.capacity.LeafQueue: assignedContainer application attempt=appattempt_1421286406893_0001_000001 container=Container: [ContainerId: container_1421286406893_0001_01_000013, NodeId: barbie:45258, NodeHttpAddress: barbie:8042, Resource: <memory:1024, vCores:1>, Priority: 20, Token: null, ] queue=default: capacity=1.0, absoluteCapacity=1.0, usedResources=<memory:7168, vCores:6>, usedCapacity=0.875, absoluteUsedCapacity=0.875, numApps=1, numContainers=6 clusterResource=<memory:8192, vCores:8>
2015-01-14 19:50:55,719 INFO org.apache.hadoop.yarn.server.resourcemanager.scheduler.capacity.ParentQueue: Re-sorting assigned queue: root.default stats: default: capacity=1.0, absoluteCapacity=1.0, usedResources=<memory:8192, vCores:7>, usedCapacity=1.0, absoluteUsedCapacity=1.0, numApps=1, numContainers=7
2015-01-14 19:50:55,719 INFO org.apache.hadoop.yarn.server.resourcemanager.scheduler.capacity.ParentQueue: assignedContainer queue=root usedCapacity=1.0 absoluteUsedCapacity=1.0 used=<memory:8192, vCores:7> cluster=<memory:8192, vCores:8>
2015-01-14 19:50:55,793 INFO org.apache.hadoop.yarn.server.resourcemanager.scheduler.capacity.CapacityScheduler: Null container completed...
2015-01-14 19:50:55,794 INFO org.apache.hadoop.yarn.server.resourcemanager.scheduler.capacity.CapacityScheduler: Null container completed...
2015-01-14 19:50:55,794 INFO org.apache.hadoop.yarn.server.resourcemanager.scheduler.capacity.CapacityScheduler: Null container completed...
2015-01-14 19:50:55,794 INFO org.apache.hadoop.yarn.server.resourcemanager.scheduler.capacity.CapacityScheduler: Null container completed...
2015-01-14 19:50:55,794 INFO org.apache.hadoop.yarn.server.resourcemanager.scheduler.capacity.CapacityScheduler: Null container completed...
2015-01-14 19:50:55,794 INFO org.apache.hadoop.yarn.server.resourcemanager.scheduler.capacity.CapacityScheduler: Null container completed...
2015-01-14 19:50:56,654 INFO org.apache.hadoop.yarn.server.resourcemanager.scheduler.capacity.CapacityScheduler: Null container completed...
2015-01-14 19:50:56,655 INFO org.apache.hadoop.yarn.server.resourcemanager.scheduler.capacity.CapacityScheduler: Null container completed...
2015-01-14 19:50:56,655 INFO org.apache.hadoop.yarn.server.resourcemanager.scheduler.capacity.CapacityScheduler: Null container completed...
2015-01-14 19:50:56,655 INFO org.apache.hadoop.yarn.server.resourcemanager.scheduler.capacity.CapacityScheduler: Null container completed...
2015-01-14 19:50:56,656 INFO org.apache.hadoop.yarn.server.resourcemanager.scheduler.capacity.CapacityScheduler: Null container completed...
2015-01-14 19:50:56,656 INFO org.apache.hadoop.yarn.server.resourcemanager.scheduler.capacity.CapacityScheduler: Null container completed...
2015-01-14 19:50:57,674 INFO org.apache.hadoop.yarn.server.resourcemanager.scheduler.capacity.CapacityScheduler: Null container completed...
2015-01-14 19:50:57,700 INFO org.apache.hadoop.yarn.server.resourcemanager.scheduler.capacity.CapacityScheduler: Null container completed...
2015-01-14 19:50:57,717 INFO org.apache.hadoop.yarn.server.resourcemanager.scheduler.capacity.CapacityScheduler: Null container completed...
2015-01-14 19:50:57,717 INFO org.apache.hadoop.yarn.server.resourcemanager.scheduler.capacity.CapacityScheduler: Null container completed...
2015-01-14 19:50:57,718 INFO org.apache.hadoop.yarn.server.resourcemanager.scheduler.capacity.CapacityScheduler: Null container completed...
2015-01-14 19:50:57,718 INFO org.apache.hadoop.yarn.server.resourcemanager.scheduler.capacity.CapacityScheduler: Null container completed...
2015-01-14 19:50:58,699 INFO org.apache.hadoop.yarn.server.resourcemanager.scheduler.capacity.CapacityScheduler: Null container completed...
2015-01-14 19:50:58,700 INFO org.apache.hadoop.yarn.server.resourcemanager.scheduler.capacity.CapacityScheduler: Null container completed...
2015-01-14 19:50:58,701 INFO org.apache.hadoop.yarn.server.resourcemanager.scheduler.capacity.CapacityScheduler: Null container completed...
2015-01-14 19:50:58,701 INFO org.apache.hadoop.yarn.server.resourcemanager.scheduler.capacity.CapacityScheduler: Null container completed...
2015-01-14 19:50:58,701 INFO org.apache.hadoop.yarn.server.resourcemanager.scheduler.capacity.CapacityScheduler: Null container completed...
2015-01-14 19:50:58,701 INFO org.apache.hadoop.yarn.server.resourcemanager.scheduler.capacity.CapacityScheduler: Null container completed...
2015-01-14 19:50:59,322 INFO org.apache.hadoop.yarn.server.resourcemanager.rmcontainer.RMContainerImpl: container_1421286406893_0001_01_000008 Container Transitioned from ALLOCATED to ACQUIRED
2015-01-14 19:50:59,378 INFO org.apache.hadoop.yarn.server.resourcemanager.rmcontainer.RMContainerImpl: container_1421286406893_0001_01_000009 Container Transitioned from ALLOCATED to ACQUIRED
2015-01-14 19:50:59,386 INFO org.apache.hadoop.yarn.server.resourcemanager.rmcontainer.RMContainerImpl: container_1421286406893_0001_01_000010 Container Transitioned from ALLOCATED to ACQUIRED
2015-01-14 19:50:59,390 INFO org.apache.hadoop.yarn.server.resourcemanager.rmcontainer.RMContainerImpl: container_1421286406893_0001_01_000011 Container Transitioned from ALLOCATED to ACQUIRED
2015-01-14 19:50:59,393 INFO org.apache.hadoop.yarn.server.resourcemanager.rmcontainer.RMContainerImpl: container_1421286406893_0001_01_000012 Container Transitioned from ALLOCATED to ACQUIRED
2015-01-14 19:50:59,396 INFO org.apache.hadoop.yarn.server.resourcemanager.rmcontainer.RMContainerImpl: container_1421286406893_0001_01_000013 Container Transitioned from ALLOCATED to ACQUIRED
2015-01-14 19:50:59,710 INFO org.apache.hadoop.yarn.server.resourcemanager.rmcontainer.RMContainerImpl: container_1421286406893_0001_01_000009 Container Transitioned from ACQUIRED to RUNNING
2015-01-14 19:50:59,712 INFO org.apache.hadoop.yarn.server.resourcemanager.rmcontainer.RMContainerImpl: container_1421286406893_0001_01_000011 Container Transitioned from ACQUIRED to RUNNING
2015-01-14 19:50:59,712 INFO org.apache.hadoop.yarn.server.resourcemanager.rmcontainer.RMContainerImpl: container_1421286406893_0001_01_000013 Container Transitioned from ACQUIRED to RUNNING
2015-01-14 19:50:59,726 INFO org.apache.hadoop.yarn.server.resourcemanager.scheduler.capacity.CapacityScheduler: Null container completed...
2015-01-14 19:50:59,726 INFO org.apache.hadoop.yarn.server.resourcemanager.scheduler.capacity.CapacityScheduler: Null container completed...
2015-01-14 19:50:59,726 INFO org.apache.hadoop.yarn.server.resourcemanager.scheduler.capacity.CapacityScheduler: Null container completed...
2015-01-14 19:50:59,726 INFO org.apache.hadoop.yarn.server.resourcemanager.scheduler.capacity.CapacityScheduler: Null container completed...
2015-01-14 19:50:59,726 INFO org.apache.hadoop.yarn.server.resourcemanager.scheduler.capacity.CapacityScheduler: Null container completed...
2015-01-14 19:50:59,726 INFO org.apache.hadoop.yarn.server.resourcemanager.scheduler.capacity.CapacityScheduler: Null container completed...
2015-01-14 19:51:00,483 INFO org.apache.hadoop.yarn.server.resourcemanager.scheduler.AppSchedulingInfo: checking for deactivate... 
2015-01-14 19:51:03,910 INFO org.apache.hadoop.yarn.server.resourcemanager.rmcontainer.RMContainerImpl: container_1421286406893_0001_01_000008 Container Transitioned from ACQUIRED to RUNNING
2015-01-14 19:51:03,910 INFO org.apache.hadoop.yarn.server.resourcemanager.rmcontainer.RMContainerImpl: container_1421286406893_0001_01_000010 Container Transitioned from ACQUIRED to RUNNING
2015-01-14 19:51:03,910 INFO org.apache.hadoop.yarn.server.resourcemanager.rmcontainer.RMContainerImpl: container_1421286406893_0001_01_000012 Container Transitioned from ACQUIRED to RUNNING
2015-01-14 19:51:03,952 INFO org.apache.hadoop.yarn.server.resourcemanager.scheduler.capacity.CapacityScheduler: Null container completed...
2015-01-14 19:51:03,952 INFO org.apache.hadoop.yarn.server.resourcemanager.scheduler.capacity.CapacityScheduler: Null container completed...
2015-01-14 19:51:03,952 INFO org.apache.hadoop.yarn.server.resourcemanager.scheduler.capacity.CapacityScheduler: Null container completed...
2015-01-14 19:51:03,952 INFO org.apache.hadoop.yarn.server.resourcemanager.scheduler.capacity.CapacityScheduler: Null container completed...
2015-01-14 19:51:03,952 INFO org.apache.hadoop.yarn.server.resourcemanager.scheduler.capacity.CapacityScheduler: Null container completed...
2015-01-14 19:52:26,164 INFO SecurityLogger.org.apache.hadoop.ipc.Server: Auth successful for appattempt_1421286406893_0001_000001 (auth:SIMPLE)
2015-01-14 19:53:07,419 INFO org.apache.hadoop.yarn.server.resourcemanager.rmcontainer.RMContainerImpl: container_1421286406893_0001_01_000009 Container Transitioned from RUNNING to COMPLETED
2015-01-14 19:53:07,419 INFO org.apache.hadoop.yarn.server.resourcemanager.scheduler.common.fica.FiCaSchedulerApp: Completed container: container_1421286406893_0001_01_000009 in state: COMPLETED event:FINISHED
2015-01-14 19:53:07,420 INFO org.apache.hadoop.yarn.server.resourcemanager.RMAuditLogger: USER=doopy	OPERATION=AM Released Container	TARGET=SchedulerApp	RESULT=SUCCESS	APPID=application_1421286406893_0001	CONTAINERID=container_1421286406893_0001_01_000009
2015-01-14 19:53:07,420 INFO org.apache.hadoop.yarn.server.resourcemanager.scheduler.SchedulerNode: Released container container_1421286406893_0001_01_000009 of capacity <memory:1024, vCores:1> on host barbie:45258, which currently has 6 containers, <memory:7168, vCores:6> used and <memory:1024, vCores:2> available, release resources=true
2015-01-14 19:53:07,420 INFO org.apache.hadoop.yarn.server.resourcemanager.scheduler.capacity.LeafQueue: default used=<memory:7168, vCores:6> numContainers=6 user=doopy user-resources=<memory:7168, vCores:6>
2015-01-14 19:53:07,427 INFO org.apache.hadoop.yarn.server.resourcemanager.scheduler.capacity.LeafQueue: completedContainer container=Container: [ContainerId: container_1421286406893_0001_01_000009, NodeId: barbie:45258, NodeHttpAddress: barbie:8042, Resource: <memory:1024, vCores:1>, Priority: 20, Token: Token { kind: ContainerToken, service: 127.0.1.1:45258 }, ] queue=default: capacity=1.0, absoluteCapacity=1.0, usedResources=<memory:7168, vCores:6>, usedCapacity=0.875, absoluteUsedCapacity=0.875, numApps=1, numContainers=6 cluster=<memory:8192, vCores:8>
2015-01-14 19:53:07,443 INFO org.apache.hadoop.yarn.server.resourcemanager.scheduler.capacity.ParentQueue: completedContainer queue=root usedCapacity=0.875 absoluteUsedCapacity=0.875 used=<memory:7168, vCores:6> cluster=<memory:8192, vCores:8>
2015-01-14 19:53:07,443 INFO org.apache.hadoop.yarn.server.resourcemanager.scheduler.capacity.ParentQueue: Re-sorting completed queue: root.default stats: default: capacity=1.0, absoluteCapacity=1.0, usedResources=<memory:7168, vCores:6>, usedCapacity=0.875, absoluteUsedCapacity=0.875, numApps=1, numContainers=6
2015-01-14 19:53:07,444 INFO org.apache.hadoop.yarn.server.resourcemanager.scheduler.capacity.CapacityScheduler: Application attempt appattempt_1421286406893_0001_000001 released container container_1421286406893_0001_01_000009 on node: host: barbie:45258 #containers=6 available=1024 used=7168 with event: FINISHED
2015-01-14 19:53:07,444 INFO org.apache.hadoop.yarn.server.resourcemanager.rmcontainer.RMContainerImpl: container_1421286406893_0001_01_000010 Container Transitioned from RUNNING to COMPLETED
2015-01-14 19:53:07,444 INFO org.apache.hadoop.yarn.server.resourcemanager.scheduler.common.fica.FiCaSchedulerApp: Completed container: container_1421286406893_0001_01_000010 in state: COMPLETED event:FINISHED
2015-01-14 19:53:07,444 INFO org.apache.hadoop.yarn.server.resourcemanager.RMAuditLogger: USER=doopy	OPERATION=AM Released Container	TARGET=SchedulerApp	RESULT=SUCCESS	APPID=application_1421286406893_0001	CONTAINERID=container_1421286406893_0001_01_000010
2015-01-14 19:53:07,444 INFO org.apache.hadoop.yarn.server.resourcemanager.scheduler.SchedulerNode: Released container container_1421286406893_0001_01_000010 of capacity <memory:1024, vCores:1> on host barbie:45258, which currently has 5 containers, <memory:6144, vCores:5> used and <memory:2048, vCores:3> available, release resources=true
2015-01-14 19:53:07,444 INFO org.apache.hadoop.yarn.server.resourcemanager.scheduler.capacity.LeafQueue: default used=<memory:6144, vCores:5> numContainers=5 user=doopy user-resources=<memory:6144, vCores:5>
2015-01-14 19:53:07,445 INFO org.apache.hadoop.yarn.server.resourcemanager.scheduler.capacity.LeafQueue: completedContainer container=Container: [ContainerId: container_1421286406893_0001_01_000010, NodeId: barbie:45258, NodeHttpAddress: barbie:8042, Resource: <memory:1024, vCores:1>, Priority: 20, Token: Token { kind: ContainerToken, service: 127.0.1.1:45258 }, ] queue=default: capacity=1.0, absoluteCapacity=1.0, usedResources=<memory:6144, vCores:5>, usedCapacity=0.75, absoluteUsedCapacity=0.75, numApps=1, numContainers=5 cluster=<memory:8192, vCores:8>
2015-01-14 19:53:07,445 INFO org.apache.hadoop.yarn.server.resourcemanager.scheduler.capacity.ParentQueue: completedContainer queue=root usedCapacity=0.75 absoluteUsedCapacity=0.75 used=<memory:6144, vCores:5> cluster=<memory:8192, vCores:8>
2015-01-14 19:53:07,445 INFO org.apache.hadoop.yarn.server.resourcemanager.scheduler.capacity.ParentQueue: Re-sorting completed queue: root.default stats: default: capacity=1.0, absoluteCapacity=1.0, usedResources=<memory:6144, vCores:5>, usedCapacity=0.75, absoluteUsedCapacity=0.75, numApps=1, numContainers=5
2015-01-14 19:53:07,445 INFO org.apache.hadoop.yarn.server.resourcemanager.scheduler.capacity.CapacityScheduler: Application attempt appattempt_1421286406893_0001_000001 released container container_1421286406893_0001_01_000010 on node: host: barbie:45258 #containers=5 available=2048 used=6144 with event: FINISHED
2015-01-14 19:53:07,446 INFO org.apache.hadoop.yarn.server.resourcemanager.rmcontainer.RMContainerImpl: container_1421286406893_0001_01_000011 Container Transitioned from RUNNING to COMPLETED
2015-01-14 19:53:07,446 INFO org.apache.hadoop.yarn.server.resourcemanager.scheduler.common.fica.FiCaSchedulerApp: Completed container: container_1421286406893_0001_01_000011 in state: COMPLETED event:FINISHED
2015-01-14 19:53:07,446 INFO org.apache.hadoop.yarn.server.resourcemanager.RMAuditLogger: USER=doopy	OPERATION=AM Released Container	TARGET=SchedulerApp	RESULT=SUCCESS	APPID=application_1421286406893_0001	CONTAINERID=container_1421286406893_0001_01_000011
2015-01-14 19:53:07,446 INFO org.apache.hadoop.yarn.server.resourcemanager.scheduler.SchedulerNode: Released container container_1421286406893_0001_01_000011 of capacity <memory:1024, vCores:1> on host barbie:45258, which currently has 4 containers, <memory:5120, vCores:4> used and <memory:3072, vCores:4> available, release resources=true
2015-01-14 19:53:07,446 INFO org.apache.hadoop.yarn.server.resourcemanager.scheduler.capacity.LeafQueue: default used=<memory:5120, vCores:4> numContainers=4 user=doopy user-resources=<memory:5120, vCores:4>
2015-01-14 19:53:07,455 INFO org.apache.hadoop.yarn.server.resourcemanager.scheduler.capacity.LeafQueue: completedContainer container=Container: [ContainerId: container_1421286406893_0001_01_000011, NodeId: barbie:45258, NodeHttpAddress: barbie:8042, Resource: <memory:1024, vCores:1>, Priority: 20, Token: Token { kind: ContainerToken, service: 127.0.1.1:45258 }, ] queue=default: capacity=1.0, absoluteCapacity=1.0, usedResources=<memory:5120, vCores:4>, usedCapacity=0.625, absoluteUsedCapacity=0.625, numApps=1, numContainers=4 cluster=<memory:8192, vCores:8>
2015-01-14 19:53:07,455 INFO org.apache.hadoop.yarn.server.resourcemanager.scheduler.capacity.ParentQueue: completedContainer queue=root usedCapacity=0.625 absoluteUsedCapacity=0.625 used=<memory:5120, vCores:4> cluster=<memory:8192, vCores:8>
2015-01-14 19:53:07,455 INFO org.apache.hadoop.yarn.server.resourcemanager.scheduler.capacity.ParentQueue: Re-sorting completed queue: root.default stats: default: capacity=1.0, absoluteCapacity=1.0, usedResources=<memory:5120, vCores:4>, usedCapacity=0.625, absoluteUsedCapacity=0.625, numApps=1, numContainers=4
2015-01-14 19:53:07,455 INFO org.apache.hadoop.yarn.server.resourcemanager.scheduler.capacity.CapacityScheduler: Application attempt appattempt_1421286406893_0001_000001 released container container_1421286406893_0001_01_000011 on node: host: barbie:45258 #containers=4 available=3072 used=5120 with event: FINISHED
2015-01-14 19:53:07,455 INFO org.apache.hadoop.yarn.server.resourcemanager.rmcontainer.RMContainerImpl: container_1421286406893_0001_01_000012 Container Transitioned from RUNNING to COMPLETED
2015-01-14 19:53:07,455 INFO org.apache.hadoop.yarn.server.resourcemanager.scheduler.common.fica.FiCaSchedulerApp: Completed container: container_1421286406893_0001_01_000012 in state: COMPLETED event:FINISHED
2015-01-14 19:53:07,456 INFO org.apache.hadoop.yarn.server.resourcemanager.RMAuditLogger: USER=doopy	OPERATION=AM Released Container	TARGET=SchedulerApp	RESULT=SUCCESS	APPID=application_1421286406893_0001	CONTAINERID=container_1421286406893_0001_01_000012
2015-01-14 19:53:07,456 INFO org.apache.hadoop.yarn.server.resourcemanager.scheduler.SchedulerNode: Released container container_1421286406893_0001_01_000012 of capacity <memory:1024, vCores:1> on host barbie:45258, which currently has 3 containers, <memory:4096, vCores:3> used and <memory:4096, vCores:5> available, release resources=true
2015-01-14 19:53:07,456 INFO org.apache.hadoop.yarn.server.resourcemanager.scheduler.capacity.LeafQueue: default used=<memory:4096, vCores:3> numContainers=3 user=doopy user-resources=<memory:4096, vCores:3>
2015-01-14 19:53:07,456 INFO org.apache.hadoop.yarn.server.resourcemanager.scheduler.capacity.LeafQueue: completedContainer container=Container: [ContainerId: container_1421286406893_0001_01_000012, NodeId: barbie:45258, NodeHttpAddress: barbie:8042, Resource: <memory:1024, vCores:1>, Priority: 20, Token: Token { kind: ContainerToken, service: 127.0.1.1:45258 }, ] queue=default: capacity=1.0, absoluteCapacity=1.0, usedResources=<memory:4096, vCores:3>, usedCapacity=0.5, absoluteUsedCapacity=0.5, numApps=1, numContainers=3 cluster=<memory:8192, vCores:8>
2015-01-14 19:53:07,456 INFO org.apache.hadoop.yarn.server.resourcemanager.scheduler.capacity.ParentQueue: completedContainer queue=root usedCapacity=0.5 absoluteUsedCapacity=0.5 used=<memory:4096, vCores:3> cluster=<memory:8192, vCores:8>
2015-01-14 19:53:07,457 INFO org.apache.hadoop.yarn.server.resourcemanager.scheduler.capacity.ParentQueue: Re-sorting completed queue: root.default stats: default: capacity=1.0, absoluteCapacity=1.0, usedResources=<memory:4096, vCores:3>, usedCapacity=0.5, absoluteUsedCapacity=0.5, numApps=1, numContainers=3
2015-01-14 19:53:07,457 INFO org.apache.hadoop.yarn.server.resourcemanager.scheduler.capacity.CapacityScheduler: Application attempt appattempt_1421286406893_0001_000001 released container container_1421286406893_0001_01_000012 on node: host: barbie:45258 #containers=3 available=4096 used=4096 with event: FINISHED
2015-01-14 19:53:07,457 INFO org.apache.hadoop.yarn.server.resourcemanager.rmcontainer.RMContainerImpl: container_1421286406893_0001_01_000013 Container Transitioned from RUNNING to COMPLETED
2015-01-14 19:53:07,457 INFO org.apache.hadoop.yarn.server.resourcemanager.scheduler.common.fica.FiCaSchedulerApp: Completed container: container_1421286406893_0001_01_000013 in state: COMPLETED event:FINISHED
2015-01-14 19:53:07,457 INFO org.apache.hadoop.yarn.server.resourcemanager.RMAuditLogger: USER=doopy	OPERATION=AM Released Container	TARGET=SchedulerApp	RESULT=SUCCESS	APPID=application_1421286406893_0001	CONTAINERID=container_1421286406893_0001_01_000013
2015-01-14 19:53:07,457 INFO org.apache.hadoop.yarn.server.resourcemanager.scheduler.SchedulerNode: Released container container_1421286406893_0001_01_000013 of capacity <memory:1024, vCores:1> on host barbie:45258, which currently has 2 containers, <memory:3072, vCores:2> used and <memory:5120, vCores:6> available, release resources=true
2015-01-14 19:53:07,457 INFO org.apache.hadoop.yarn.server.resourcemanager.scheduler.capacity.LeafQueue: default used=<memory:3072, vCores:2> numContainers=2 user=doopy user-resources=<memory:3072, vCores:2>
2015-01-14 19:53:07,458 INFO org.apache.hadoop.yarn.server.resourcemanager.scheduler.capacity.LeafQueue: completedContainer container=Container: [ContainerId: container_1421286406893_0001_01_000013, NodeId: barbie:45258, NodeHttpAddress: barbie:8042, Resource: <memory:1024, vCores:1>, Priority: 20, Token: Token { kind: ContainerToken, service: 127.0.1.1:45258 }, ] queue=default: capacity=1.0, absoluteCapacity=1.0, usedResources=<memory:3072, vCores:2>, usedCapacity=0.375, absoluteUsedCapacity=0.375, numApps=1, numContainers=2 cluster=<memory:8192, vCores:8>
2015-01-14 19:53:07,458 INFO org.apache.hadoop.yarn.server.resourcemanager.scheduler.capacity.ParentQueue: completedContainer queue=root usedCapacity=0.375 absoluteUsedCapacity=0.375 used=<memory:3072, vCores:2> cluster=<memory:8192, vCores:8>
2015-01-14 19:53:07,458 INFO org.apache.hadoop.yarn.server.resourcemanager.scheduler.capacity.ParentQueue: Re-sorting completed queue: root.default stats: default: capacity=1.0, absoluteCapacity=1.0, usedResources=<memory:3072, vCores:2>, usedCapacity=0.375, absoluteUsedCapacity=0.375, numApps=1, numContainers=2
2015-01-14 19:53:07,458 INFO org.apache.hadoop.yarn.server.resourcemanager.scheduler.capacity.CapacityScheduler: Application attempt appattempt_1421286406893_0001_000001 released container container_1421286406893_0001_01_000013 on node: host: barbie:45258 #containers=2 available=5120 used=3072 with event: FINISHED
2015-01-14 19:53:07,480 INFO org.apache.hadoop.yarn.server.resourcemanager.rmcontainer.RMContainerImpl: container_1421286406893_0001_01_000014 Container Transitioned from NEW to ALLOCATED
2015-01-14 19:53:07,480 INFO org.apache.hadoop.yarn.server.resourcemanager.RMAuditLogger: USER=doopy	OPERATION=AM Allocated Container	TARGET=SchedulerApp	RESULT=SUCCESS	APPID=application_1421286406893_0001	CONTAINERID=container_1421286406893_0001_01_000014
2015-01-14 19:53:07,480 INFO org.apache.hadoop.yarn.server.resourcemanager.scheduler.SchedulerNode: Assigned container container_1421286406893_0001_01_000014 of capacity <memory:1024, vCores:1> on host barbie:45258, which has 3 containers, <memory:4096, vCores:3> used and <memory:4096, vCores:5> available after allocation
2015-01-14 19:53:07,481 INFO org.apache.hadoop.yarn.server.resourcemanager.scheduler.capacity.LeafQueue: assignedContainer application attempt=appattempt_1421286406893_0001_000001 container=Container: [ContainerId: container_1421286406893_0001_01_000014, NodeId: barbie:45258, NodeHttpAddress: barbie:8042, Resource: <memory:1024, vCores:1>, Priority: 20, Token: null, ] queue=default: capacity=1.0, absoluteCapacity=1.0, usedResources=<memory:3072, vCores:2>, usedCapacity=0.375, absoluteUsedCapacity=0.375, numApps=1, numContainers=2 clusterResource=<memory:8192, vCores:8>
2015-01-14 19:53:07,481 INFO org.apache.hadoop.yarn.server.resourcemanager.scheduler.capacity.ParentQueue: Re-sorting assigned queue: root.default stats: default: capacity=1.0, absoluteCapacity=1.0, usedResources=<memory:4096, vCores:3>, usedCapacity=0.5, absoluteUsedCapacity=0.5, numApps=1, numContainers=3
2015-01-14 19:53:07,481 INFO org.apache.hadoop.yarn.server.resourcemanager.scheduler.capacity.ParentQueue: assignedContainer queue=root usedCapacity=0.5 absoluteUsedCapacity=0.5 used=<memory:4096, vCores:3> cluster=<memory:8192, vCores:8>
2015-01-14 19:53:07,481 INFO org.apache.hadoop.yarn.server.resourcemanager.rmcontainer.RMContainerImpl: container_1421286406893_0001_01_000015 Container Transitioned from NEW to ALLOCATED
2015-01-14 19:53:07,482 INFO org.apache.hadoop.yarn.server.resourcemanager.RMAuditLogger: USER=doopy	OPERATION=AM Allocated Container	TARGET=SchedulerApp	RESULT=SUCCESS	APPID=application_1421286406893_0001	CONTAINERID=container_1421286406893_0001_01_000015
2015-01-14 19:53:07,482 INFO org.apache.hadoop.yarn.server.resourcemanager.scheduler.SchedulerNode: Assigned container container_1421286406893_0001_01_000015 of capacity <memory:1024, vCores:1> on host barbie:45258, which has 4 containers, <memory:5120, vCores:4> used and <memory:3072, vCores:4> available after allocation
2015-01-14 19:53:07,482 INFO org.apache.hadoop.yarn.server.resourcemanager.scheduler.capacity.LeafQueue: assignedContainer application attempt=appattempt_1421286406893_0001_000001 container=Container: [ContainerId: container_1421286406893_0001_01_000015, NodeId: barbie:45258, NodeHttpAddress: barbie:8042, Resource: <memory:1024, vCores:1>, Priority: 20, Token: null, ] queue=default: capacity=1.0, absoluteCapacity=1.0, usedResources=<memory:4096, vCores:3>, usedCapacity=0.5, absoluteUsedCapacity=0.5, numApps=1, numContainers=3 clusterResource=<memory:8192, vCores:8>
2015-01-14 19:53:07,482 INFO org.apache.hadoop.yarn.server.resourcemanager.scheduler.capacity.ParentQueue: Re-sorting assigned queue: root.default stats: default: capacity=1.0, absoluteCapacity=1.0, usedResources=<memory:5120, vCores:4>, usedCapacity=0.625, absoluteUsedCapacity=0.625, numApps=1, numContainers=4
2015-01-14 19:53:07,482 INFO org.apache.hadoop.yarn.server.resourcemanager.scheduler.capacity.ParentQueue: assignedContainer queue=root usedCapacity=0.625 absoluteUsedCapacity=0.625 used=<memory:5120, vCores:4> cluster=<memory:8192, vCores:8>
2015-01-14 19:53:07,609 INFO org.apache.hadoop.yarn.server.resourcemanager.rmcontainer.RMContainerImpl: container_1421286406893_0001_01_000016 Container Transitioned from NEW to ALLOCATED
2015-01-14 19:53:07,610 INFO org.apache.hadoop.yarn.server.resourcemanager.RMAuditLogger: USER=doopy	OPERATION=AM Allocated Container	TARGET=SchedulerApp	RESULT=SUCCESS	APPID=application_1421286406893_0001	CONTAINERID=container_1421286406893_0001_01_000016
2015-01-14 19:53:07,610 INFO org.apache.hadoop.yarn.server.resourcemanager.scheduler.SchedulerNode: Assigned container container_1421286406893_0001_01_000016 of capacity <memory:1024, vCores:1> on host barbie:45258, which has 5 containers, <memory:6144, vCores:5> used and <memory:2048, vCores:3> available after allocation
2015-01-14 19:53:07,610 INFO org.apache.hadoop.yarn.server.resourcemanager.scheduler.capacity.LeafQueue: assignedContainer application attempt=appattempt_1421286406893_0001_000001 container=Container: [ContainerId: container_1421286406893_0001_01_000016, NodeId: barbie:45258, NodeHttpAddress: barbie:8042, Resource: <memory:1024, vCores:1>, Priority: 20, Token: null, ] queue=default: capacity=1.0, absoluteCapacity=1.0, usedResources=<memory:5120, vCores:4>, usedCapacity=0.625, absoluteUsedCapacity=0.625, numApps=1, numContainers=4 clusterResource=<memory:8192, vCores:8>
2015-01-14 19:53:07,610 INFO org.apache.hadoop.yarn.server.resourcemanager.scheduler.capacity.ParentQueue: Re-sorting assigned queue: root.default stats: default: capacity=1.0, absoluteCapacity=1.0, usedResources=<memory:6144, vCores:5>, usedCapacity=0.75, absoluteUsedCapacity=0.75, numApps=1, numContainers=5
2015-01-14 19:53:07,610 INFO org.apache.hadoop.yarn.server.resourcemanager.scheduler.capacity.ParentQueue: assignedContainer queue=root usedCapacity=0.75 absoluteUsedCapacity=0.75 used=<memory:6144, vCores:5> cluster=<memory:8192, vCores:8>
2015-01-14 19:53:07,611 INFO org.apache.hadoop.yarn.server.resourcemanager.rmcontainer.RMContainerImpl: container_1421286406893_0001_01_000017 Container Transitioned from NEW to ALLOCATED
2015-01-14 19:53:07,611 INFO org.apache.hadoop.yarn.server.resourcemanager.RMAuditLogger: USER=doopy	OPERATION=AM Allocated Container	TARGET=SchedulerApp	RESULT=SUCCESS	APPID=application_1421286406893_0001	CONTAINERID=container_1421286406893_0001_01_000017
2015-01-14 19:53:07,611 INFO org.apache.hadoop.yarn.server.resourcemanager.scheduler.SchedulerNode: Assigned container container_1421286406893_0001_01_000017 of capacity <memory:1024, vCores:1> on host barbie:45258, which has 6 containers, <memory:7168, vCores:6> used and <memory:1024, vCores:2> available after allocation
2015-01-14 19:53:07,611 INFO org.apache.hadoop.yarn.server.resourcemanager.scheduler.capacity.LeafQueue: assignedContainer application attempt=appattempt_1421286406893_0001_000001 container=Container: [ContainerId: container_1421286406893_0001_01_000017, NodeId: barbie:45258, NodeHttpAddress: barbie:8042, Resource: <memory:1024, vCores:1>, Priority: 20, Token: null, ] queue=default: capacity=1.0, absoluteCapacity=1.0, usedResources=<memory:6144, vCores:5>, usedCapacity=0.75, absoluteUsedCapacity=0.75, numApps=1, numContainers=5 clusterResource=<memory:8192, vCores:8>
2015-01-14 19:53:07,612 INFO org.apache.hadoop.yarn.server.resourcemanager.scheduler.capacity.ParentQueue: Re-sorting assigned queue: root.default stats: default: capacity=1.0, absoluteCapacity=1.0, usedResources=<memory:7168, vCores:6>, usedCapacity=0.875, absoluteUsedCapacity=0.875, numApps=1, numContainers=6
2015-01-14 19:53:07,612 INFO org.apache.hadoop.yarn.server.resourcemanager.scheduler.capacity.ParentQueue: assignedContainer queue=root usedCapacity=0.875 absoluteUsedCapacity=0.875 used=<memory:7168, vCores:6> cluster=<memory:8192, vCores:8>
2015-01-14 19:53:07,612 INFO org.apache.hadoop.yarn.server.resourcemanager.rmcontainer.RMContainerImpl: container_1421286406893_0001_01_000018 Container Transitioned from NEW to ALLOCATED
2015-01-14 19:53:07,612 INFO org.apache.hadoop.yarn.server.resourcemanager.RMAuditLogger: USER=doopy	OPERATION=AM Allocated Container	TARGET=SchedulerApp	RESULT=SUCCESS	APPID=application_1421286406893_0001	CONTAINERID=container_1421286406893_0001_01_000018
2015-01-14 19:53:07,612 INFO org.apache.hadoop.yarn.server.resourcemanager.scheduler.SchedulerNode: Assigned container container_1421286406893_0001_01_000018 of capacity <memory:1024, vCores:1> on host barbie:45258, which has 7 containers, <memory:8192, vCores:7> used and <memory:0, vCores:1> available after allocation
2015-01-14 19:53:07,613 INFO org.apache.hadoop.yarn.server.resourcemanager.scheduler.capacity.LeafQueue: assignedContainer application attempt=appattempt_1421286406893_0001_000001 container=Container: [ContainerId: container_1421286406893_0001_01_000018, NodeId: barbie:45258, NodeHttpAddress: barbie:8042, Resource: <memory:1024, vCores:1>, Priority: 20, Token: null, ] queue=default: capacity=1.0, absoluteCapacity=1.0, usedResources=<memory:7168, vCores:6>, usedCapacity=0.875, absoluteUsedCapacity=0.875, numApps=1, numContainers=6 clusterResource=<memory:8192, vCores:8>
2015-01-14 19:53:07,613 INFO org.apache.hadoop.yarn.server.resourcemanager.scheduler.capacity.ParentQueue: Re-sorting assigned queue: root.default stats: default: capacity=1.0, absoluteCapacity=1.0, usedResources=<memory:8192, vCores:7>, usedCapacity=1.0, absoluteUsedCapacity=1.0, numApps=1, numContainers=7
2015-01-14 19:53:07,613 INFO org.apache.hadoop.yarn.server.resourcemanager.scheduler.capacity.ParentQueue: assignedContainer queue=root usedCapacity=1.0 absoluteUsedCapacity=1.0 used=<memory:8192, vCores:7> cluster=<memory:8192, vCores:8>
2015-01-14 19:53:07,862 INFO org.apache.hadoop.yarn.server.resourcemanager.rmcontainer.RMContainerImpl: container_1421286406893_0001_01_000014 Container Transitioned from ALLOCATED to ACQUIRED
2015-01-14 19:53:07,897 INFO org.apache.hadoop.yarn.server.resourcemanager.rmcontainer.RMContainerImpl: container_1421286406893_0001_01_000015 Container Transitioned from ALLOCATED to ACQUIRED
2015-01-14 19:53:07,902 INFO org.apache.hadoop.yarn.server.resourcemanager.rmcontainer.RMContainerImpl: container_1421286406893_0001_01_000016 Container Transitioned from ALLOCATED to ACQUIRED
2015-01-14 19:53:07,908 INFO org.apache.hadoop.yarn.server.resourcemanager.rmcontainer.RMContainerImpl: container_1421286406893_0001_01_000017 Container Transitioned from ALLOCATED to ACQUIRED
2015-01-14 19:53:07,985 INFO org.apache.hadoop.yarn.server.resourcemanager.rmcontainer.RMContainerImpl: container_1421286406893_0001_01_000018 Container Transitioned from ALLOCATED to ACQUIRED
2015-01-14 19:53:08,431 INFO org.apache.hadoop.yarn.server.resourcemanager.rmcontainer.RMContainerImpl: container_1421286406893_0001_01_000014 Container Transitioned from ACQUIRED to RUNNING
2015-01-14 19:53:08,431 INFO org.apache.hadoop.yarn.server.resourcemanager.rmcontainer.RMContainerImpl: container_1421286406893_0001_01_000015 Container Transitioned from ACQUIRED to RUNNING
2015-01-14 19:53:08,431 INFO org.apache.hadoop.yarn.server.resourcemanager.rmcontainer.RMContainerImpl: container_1421286406893_0001_01_000016 Container Transitioned from ACQUIRED to RUNNING
2015-01-14 19:53:08,432 INFO org.apache.hadoop.yarn.server.resourcemanager.rmcontainer.RMContainerImpl: container_1421286406893_0001_01_000017 Container Transitioned from ACQUIRED to RUNNING
2015-01-14 19:53:08,454 INFO org.apache.hadoop.yarn.server.resourcemanager.rmcontainer.RMContainerImpl: container_1421286406893_0001_01_000018 Container Transitioned from ACQUIRED to RUNNING
2015-01-14 19:53:08,454 INFO org.apache.hadoop.yarn.server.resourcemanager.scheduler.capacity.CapacityScheduler: Null container completed...
2015-01-14 19:53:08,454 INFO org.apache.hadoop.yarn.server.resourcemanager.scheduler.capacity.CapacityScheduler: Null container completed...
2015-01-14 19:53:08,454 INFO org.apache.hadoop.yarn.server.resourcemanager.scheduler.capacity.CapacityScheduler: Null container completed...
2015-01-14 19:53:08,454 INFO org.apache.hadoop.yarn.server.resourcemanager.scheduler.capacity.CapacityScheduler: Null container completed...
2015-01-14 19:53:08,454 INFO org.apache.hadoop.yarn.server.resourcemanager.scheduler.capacity.CapacityScheduler: Null container completed...
2015-01-14 19:53:09,437 INFO org.apache.hadoop.yarn.server.resourcemanager.scheduler.capacity.CapacityScheduler: Null container completed...
2015-01-14 19:53:09,437 INFO org.apache.hadoop.yarn.server.resourcemanager.scheduler.capacity.CapacityScheduler: Null container completed...
2015-01-14 19:53:09,437 INFO org.apache.hadoop.yarn.server.resourcemanager.scheduler.capacity.CapacityScheduler: Null container completed...
2015-01-14 19:53:09,437 INFO org.apache.hadoop.yarn.server.resourcemanager.scheduler.capacity.CapacityScheduler: Null container completed...
2015-01-14 19:53:09,437 INFO org.apache.hadoop.yarn.server.resourcemanager.scheduler.capacity.CapacityScheduler: Null container completed...
2015-01-14 19:54:31,897 INFO SecurityLogger.org.apache.hadoop.ipc.Server: Auth successful for appattempt_1421286406893_0001_000001 (auth:SIMPLE)
2015-01-14 19:55:09,745 INFO org.apache.hadoop.yarn.server.resourcemanager.rmcontainer.RMContainerImpl: container_1421286406893_0001_01_000014 Container Transitioned from RUNNING to COMPLETED
2015-01-14 19:55:09,745 INFO org.apache.hadoop.yarn.server.resourcemanager.scheduler.common.fica.FiCaSchedulerApp: Completed container: container_1421286406893_0001_01_000014 in state: COMPLETED event:FINISHED
2015-01-14 19:55:09,745 INFO org.apache.hadoop.yarn.server.resourcemanager.RMAuditLogger: USER=doopy	OPERATION=AM Released Container	TARGET=SchedulerApp	RESULT=SUCCESS	APPID=application_1421286406893_0001	CONTAINERID=container_1421286406893_0001_01_000014
2015-01-14 19:55:09,745 INFO org.apache.hadoop.yarn.server.resourcemanager.scheduler.SchedulerNode: Released container container_1421286406893_0001_01_000014 of capacity <memory:1024, vCores:1> on host barbie:45258, which currently has 6 containers, <memory:7168, vCores:6> used and <memory:1024, vCores:2> available, release resources=true
2015-01-14 19:55:09,769 INFO org.apache.hadoop.yarn.server.resourcemanager.scheduler.capacity.LeafQueue: default used=<memory:7168, vCores:6> numContainers=6 user=doopy user-resources=<memory:7168, vCores:6>
2015-01-14 19:55:09,786 INFO org.apache.hadoop.yarn.server.resourcemanager.scheduler.capacity.LeafQueue: completedContainer container=Container: [ContainerId: container_1421286406893_0001_01_000014, NodeId: barbie:45258, NodeHttpAddress: barbie:8042, Resource: <memory:1024, vCores:1>, Priority: 20, Token: Token { kind: ContainerToken, service: 127.0.1.1:45258 }, ] queue=default: capacity=1.0, absoluteCapacity=1.0, usedResources=<memory:7168, vCores:6>, usedCapacity=0.875, absoluteUsedCapacity=0.875, numApps=1, numContainers=6 cluster=<memory:8192, vCores:8>
2015-01-14 19:55:09,786 INFO org.apache.hadoop.yarn.server.resourcemanager.scheduler.capacity.ParentQueue: completedContainer queue=root usedCapacity=0.875 absoluteUsedCapacity=0.875 used=<memory:7168, vCores:6> cluster=<memory:8192, vCores:8>
2015-01-14 19:55:09,786 INFO org.apache.hadoop.yarn.server.resourcemanager.scheduler.capacity.ParentQueue: Re-sorting completed queue: root.default stats: default: capacity=1.0, absoluteCapacity=1.0, usedResources=<memory:7168, vCores:6>, usedCapacity=0.875, absoluteUsedCapacity=0.875, numApps=1, numContainers=6
2015-01-14 19:55:09,786 INFO org.apache.hadoop.yarn.server.resourcemanager.scheduler.capacity.CapacityScheduler: Application attempt appattempt_1421286406893_0001_000001 released container container_1421286406893_0001_01_000014 on node: host: barbie:45258 #containers=6 available=1024 used=7168 with event: FINISHED
2015-01-14 19:55:09,786 INFO org.apache.hadoop.yarn.server.resourcemanager.rmcontainer.RMContainerImpl: container_1421286406893_0001_01_000015 Container Transitioned from RUNNING to COMPLETED
2015-01-14 19:55:09,786 INFO org.apache.hadoop.yarn.server.resourcemanager.scheduler.common.fica.FiCaSchedulerApp: Completed container: container_1421286406893_0001_01_000015 in state: COMPLETED event:FINISHED
2015-01-14 19:55:09,787 INFO org.apache.hadoop.yarn.server.resourcemanager.RMAuditLogger: USER=doopy	OPERATION=AM Released Container	TARGET=SchedulerApp	RESULT=SUCCESS	APPID=application_1421286406893_0001	CONTAINERID=container_1421286406893_0001_01_000015
2015-01-14 19:55:09,787 INFO org.apache.hadoop.yarn.server.resourcemanager.scheduler.SchedulerNode: Released container container_1421286406893_0001_01_000015 of capacity <memory:1024, vCores:1> on host barbie:45258, which currently has 5 containers, <memory:6144, vCores:5> used and <memory:2048, vCores:3> available, release resources=true
2015-01-14 19:55:09,787 INFO org.apache.hadoop.yarn.server.resourcemanager.scheduler.capacity.LeafQueue: default used=<memory:6144, vCores:5> numContainers=5 user=doopy user-resources=<memory:6144, vCores:5>
2015-01-14 19:55:09,787 INFO org.apache.hadoop.yarn.server.resourcemanager.scheduler.capacity.LeafQueue: completedContainer container=Container: [ContainerId: container_1421286406893_0001_01_000015, NodeId: barbie:45258, NodeHttpAddress: barbie:8042, Resource: <memory:1024, vCores:1>, Priority: 20, Token: Token { kind: ContainerToken, service: 127.0.1.1:45258 }, ] queue=default: capacity=1.0, absoluteCapacity=1.0, usedResources=<memory:6144, vCores:5>, usedCapacity=0.75, absoluteUsedCapacity=0.75, numApps=1, numContainers=5 cluster=<memory:8192, vCores:8>
2015-01-14 19:55:09,788 INFO org.apache.hadoop.yarn.server.resourcemanager.scheduler.capacity.ParentQueue: completedContainer queue=root usedCapacity=0.75 absoluteUsedCapacity=0.75 used=<memory:6144, vCores:5> cluster=<memory:8192, vCores:8>
2015-01-14 19:55:09,788 INFO org.apache.hadoop.yarn.server.resourcemanager.scheduler.capacity.ParentQueue: Re-sorting completed queue: root.default stats: default: capacity=1.0, absoluteCapacity=1.0, usedResources=<memory:6144, vCores:5>, usedCapacity=0.75, absoluteUsedCapacity=0.75, numApps=1, numContainers=5
2015-01-14 19:55:09,788 INFO org.apache.hadoop.yarn.server.resourcemanager.scheduler.capacity.CapacityScheduler: Application attempt appattempt_1421286406893_0001_000001 released container container_1421286406893_0001_01_000015 on node: host: barbie:45258 #containers=5 available=2048 used=6144 with event: FINISHED
2015-01-14 19:55:09,788 INFO org.apache.hadoop.yarn.server.resourcemanager.rmcontainer.RMContainerImpl: container_1421286406893_0001_01_000016 Container Transitioned from RUNNING to COMPLETED
2015-01-14 19:55:09,788 INFO org.apache.hadoop.yarn.server.resourcemanager.scheduler.common.fica.FiCaSchedulerApp: Completed container: container_1421286406893_0001_01_000016 in state: COMPLETED event:FINISHED
2015-01-14 19:55:09,797 INFO org.apache.hadoop.yarn.server.resourcemanager.RMAuditLogger: USER=doopy	OPERATION=AM Released Container	TARGET=SchedulerApp	RESULT=SUCCESS	APPID=application_1421286406893_0001	CONTAINERID=container_1421286406893_0001_01_000016
2015-01-14 19:55:09,797 INFO org.apache.hadoop.yarn.server.resourcemanager.scheduler.SchedulerNode: Released container container_1421286406893_0001_01_000016 of capacity <memory:1024, vCores:1> on host barbie:45258, which currently has 4 containers, <memory:5120, vCores:4> used and <memory:3072, vCores:4> available, release resources=true
2015-01-14 19:55:09,797 INFO org.apache.hadoop.yarn.server.resourcemanager.scheduler.capacity.LeafQueue: default used=<memory:5120, vCores:4> numContainers=4 user=doopy user-resources=<memory:5120, vCores:4>
2015-01-14 19:55:09,798 INFO org.apache.hadoop.yarn.server.resourcemanager.scheduler.capacity.LeafQueue: completedContainer container=Container: [ContainerId: container_1421286406893_0001_01_000016, NodeId: barbie:45258, NodeHttpAddress: barbie:8042, Resource: <memory:1024, vCores:1>, Priority: 20, Token: Token { kind: ContainerToken, service: 127.0.1.1:45258 }, ] queue=default: capacity=1.0, absoluteCapacity=1.0, usedResources=<memory:5120, vCores:4>, usedCapacity=0.625, absoluteUsedCapacity=0.625, numApps=1, numContainers=4 cluster=<memory:8192, vCores:8>
2015-01-14 19:55:09,798 INFO org.apache.hadoop.yarn.server.resourcemanager.scheduler.capacity.ParentQueue: completedContainer queue=root usedCapacity=0.625 absoluteUsedCapacity=0.625 used=<memory:5120, vCores:4> cluster=<memory:8192, vCores:8>
2015-01-14 19:55:09,798 INFO org.apache.hadoop.yarn.server.resourcemanager.scheduler.capacity.ParentQueue: Re-sorting completed queue: root.default stats: default: capacity=1.0, absoluteCapacity=1.0, usedResources=<memory:5120, vCores:4>, usedCapacity=0.625, absoluteUsedCapacity=0.625, numApps=1, numContainers=4
2015-01-14 19:55:09,799 INFO org.apache.hadoop.yarn.server.resourcemanager.scheduler.capacity.CapacityScheduler: Application attempt appattempt_1421286406893_0001_000001 released container container_1421286406893_0001_01_000016 on node: host: barbie:45258 #containers=4 available=3072 used=5120 with event: FINISHED
2015-01-14 19:55:09,799 INFO org.apache.hadoop.yarn.server.resourcemanager.rmcontainer.RMContainerImpl: container_1421286406893_0001_01_000017 Container Transitioned from RUNNING to COMPLETED
2015-01-14 19:55:09,799 INFO org.apache.hadoop.yarn.server.resourcemanager.scheduler.common.fica.FiCaSchedulerApp: Completed container: container_1421286406893_0001_01_000017 in state: COMPLETED event:FINISHED
2015-01-14 19:55:09,799 INFO org.apache.hadoop.yarn.server.resourcemanager.RMAuditLogger: USER=doopy	OPERATION=AM Released Container	TARGET=SchedulerApp	RESULT=SUCCESS	APPID=application_1421286406893_0001	CONTAINERID=container_1421286406893_0001_01_000017
2015-01-14 19:55:09,799 INFO org.apache.hadoop.yarn.server.resourcemanager.scheduler.SchedulerNode: Released container container_1421286406893_0001_01_000017 of capacity <memory:1024, vCores:1> on host barbie:45258, which currently has 3 containers, <memory:4096, vCores:3> used and <memory:4096, vCores:5> available, release resources=true
2015-01-14 19:55:09,800 INFO org.apache.hadoop.yarn.server.resourcemanager.scheduler.capacity.LeafQueue: default used=<memory:4096, vCores:3> numContainers=3 user=doopy user-resources=<memory:4096, vCores:3>
2015-01-14 19:55:09,800 INFO org.apache.hadoop.yarn.server.resourcemanager.scheduler.capacity.LeafQueue: completedContainer container=Container: [ContainerId: container_1421286406893_0001_01_000017, NodeId: barbie:45258, NodeHttpAddress: barbie:8042, Resource: <memory:1024, vCores:1>, Priority: 20, Token: Token { kind: ContainerToken, service: 127.0.1.1:45258 }, ] queue=default: capacity=1.0, absoluteCapacity=1.0, usedResources=<memory:4096, vCores:3>, usedCapacity=0.5, absoluteUsedCapacity=0.5, numApps=1, numContainers=3 cluster=<memory:8192, vCores:8>
2015-01-14 19:55:09,801 INFO org.apache.hadoop.yarn.server.resourcemanager.scheduler.capacity.ParentQueue: completedContainer queue=root usedCapacity=0.5 absoluteUsedCapacity=0.5 used=<memory:4096, vCores:3> cluster=<memory:8192, vCores:8>
2015-01-14 19:55:09,801 INFO org.apache.hadoop.yarn.server.resourcemanager.scheduler.capacity.ParentQueue: Re-sorting completed queue: root.default stats: default: capacity=1.0, absoluteCapacity=1.0, usedResources=<memory:4096, vCores:3>, usedCapacity=0.5, absoluteUsedCapacity=0.5, numApps=1, numContainers=3
2015-01-14 19:55:09,801 INFO org.apache.hadoop.yarn.server.resourcemanager.scheduler.capacity.CapacityScheduler: Application attempt appattempt_1421286406893_0001_000001 released container container_1421286406893_0001_01_000017 on node: host: barbie:45258 #containers=3 available=4096 used=4096 with event: FINISHED
2015-01-14 19:55:09,801 INFO org.apache.hadoop.yarn.server.resourcemanager.rmcontainer.RMContainerImpl: container_1421286406893_0001_01_000018 Container Transitioned from RUNNING to COMPLETED
2015-01-14 19:55:09,801 INFO org.apache.hadoop.yarn.server.resourcemanager.scheduler.common.fica.FiCaSchedulerApp: Completed container: container_1421286406893_0001_01_000018 in state: COMPLETED event:FINISHED
2015-01-14 19:55:09,802 INFO org.apache.hadoop.yarn.server.resourcemanager.RMAuditLogger: USER=doopy	OPERATION=AM Released Container	TARGET=SchedulerApp	RESULT=SUCCESS	APPID=application_1421286406893_0001	CONTAINERID=container_1421286406893_0001_01_000018
2015-01-14 19:55:09,802 INFO org.apache.hadoop.yarn.server.resourcemanager.scheduler.SchedulerNode: Released container container_1421286406893_0001_01_000018 of capacity <memory:1024, vCores:1> on host barbie:45258, which currently has 2 containers, <memory:3072, vCores:2> used and <memory:5120, vCores:6> available, release resources=true
2015-01-14 19:55:09,802 INFO org.apache.hadoop.yarn.server.resourcemanager.scheduler.capacity.LeafQueue: default used=<memory:3072, vCores:2> numContainers=2 user=doopy user-resources=<memory:3072, vCores:2>
2015-01-14 19:55:09,803 INFO org.apache.hadoop.yarn.server.resourcemanager.scheduler.capacity.LeafQueue: completedContainer container=Container: [ContainerId: container_1421286406893_0001_01_000018, NodeId: barbie:45258, NodeHttpAddress: barbie:8042, Resource: <memory:1024, vCores:1>, Priority: 20, Token: Token { kind: ContainerToken, service: 127.0.1.1:45258 }, ] queue=default: capacity=1.0, absoluteCapacity=1.0, usedResources=<memory:3072, vCores:2>, usedCapacity=0.375, absoluteUsedCapacity=0.375, numApps=1, numContainers=2 cluster=<memory:8192, vCores:8>
2015-01-14 19:55:09,803 INFO org.apache.hadoop.yarn.server.resourcemanager.scheduler.capacity.ParentQueue: completedContainer queue=root usedCapacity=0.375 absoluteUsedCapacity=0.375 used=<memory:3072, vCores:2> cluster=<memory:8192, vCores:8>
2015-01-14 19:55:09,803 INFO org.apache.hadoop.yarn.server.resourcemanager.scheduler.capacity.ParentQueue: Re-sorting completed queue: root.default stats: default: capacity=1.0, absoluteCapacity=1.0, usedResources=<memory:3072, vCores:2>, usedCapacity=0.375, absoluteUsedCapacity=0.375, numApps=1, numContainers=2
2015-01-14 19:55:09,803 INFO org.apache.hadoop.yarn.server.resourcemanager.scheduler.capacity.CapacityScheduler: Application attempt appattempt_1421286406893_0001_000001 released container container_1421286406893_0001_01_000018 on node: host: barbie:45258 #containers=2 available=5120 used=3072 with event: FINISHED
2015-01-14 19:55:09,804 INFO org.apache.hadoop.yarn.server.resourcemanager.rmcontainer.RMContainerImpl: container_1421286406893_0001_01_000019 Container Transitioned from NEW to ALLOCATED
2015-01-14 19:55:09,804 INFO org.apache.hadoop.yarn.server.resourcemanager.RMAuditLogger: USER=doopy	OPERATION=AM Allocated Container	TARGET=SchedulerApp	RESULT=SUCCESS	APPID=application_1421286406893_0001	CONTAINERID=container_1421286406893_0001_01_000019
2015-01-14 19:55:09,805 INFO org.apache.hadoop.yarn.server.resourcemanager.scheduler.SchedulerNode: Assigned container container_1421286406893_0001_01_000019 of capacity <memory:1024, vCores:1> on host barbie:45258, which has 3 containers, <memory:4096, vCores:3> used and <memory:4096, vCores:5> available after allocation
2015-01-14 19:55:09,805 INFO org.apache.hadoop.yarn.server.resourcemanager.scheduler.capacity.LeafQueue: assignedContainer application attempt=appattempt_1421286406893_0001_000001 container=Container: [ContainerId: container_1421286406893_0001_01_000019, NodeId: barbie:45258, NodeHttpAddress: barbie:8042, Resource: <memory:1024, vCores:1>, Priority: 20, Token: null, ] queue=default: capacity=1.0, absoluteCapacity=1.0, usedResources=<memory:3072, vCores:2>, usedCapacity=0.375, absoluteUsedCapacity=0.375, numApps=1, numContainers=2 clusterResource=<memory:8192, vCores:8>
2015-01-14 19:55:09,805 INFO org.apache.hadoop.yarn.server.resourcemanager.scheduler.capacity.ParentQueue: Re-sorting assigned queue: root.default stats: default: capacity=1.0, absoluteCapacity=1.0, usedResources=<memory:4096, vCores:3>, usedCapacity=0.5, absoluteUsedCapacity=0.5, numApps=1, numContainers=3
2015-01-14 19:55:09,805 INFO org.apache.hadoop.yarn.server.resourcemanager.scheduler.capacity.ParentQueue: assignedContainer queue=root usedCapacity=0.5 absoluteUsedCapacity=0.5 used=<memory:4096, vCores:3> cluster=<memory:8192, vCores:8>
2015-01-14 19:55:09,806 INFO org.apache.hadoop.yarn.server.resourcemanager.rmcontainer.RMContainerImpl: container_1421286406893_0001_01_000020 Container Transitioned from NEW to ALLOCATED
2015-01-14 19:55:09,806 INFO org.apache.hadoop.yarn.server.resourcemanager.RMAuditLogger: USER=doopy	OPERATION=AM Allocated Container	TARGET=SchedulerApp	RESULT=SUCCESS	APPID=application_1421286406893_0001	CONTAINERID=container_1421286406893_0001_01_000020
2015-01-14 19:55:09,806 INFO org.apache.hadoop.yarn.server.resourcemanager.scheduler.SchedulerNode: Assigned container container_1421286406893_0001_01_000020 of capacity <memory:1024, vCores:1> on host barbie:45258, which has 4 containers, <memory:5120, vCores:4> used and <memory:3072, vCores:4> available after allocation
2015-01-14 19:55:09,807 INFO org.apache.hadoop.yarn.server.resourcemanager.scheduler.capacity.LeafQueue: assignedContainer application attempt=appattempt_1421286406893_0001_000001 container=Container: [ContainerId: container_1421286406893_0001_01_000020, NodeId: barbie:45258, NodeHttpAddress: barbie:8042, Resource: <memory:1024, vCores:1>, Priority: 20, Token: null, ] queue=default: capacity=1.0, absoluteCapacity=1.0, usedResources=<memory:4096, vCores:3>, usedCapacity=0.5, absoluteUsedCapacity=0.5, numApps=1, numContainers=3 clusterResource=<memory:8192, vCores:8>
2015-01-14 19:55:09,807 INFO org.apache.hadoop.yarn.server.resourcemanager.scheduler.capacity.ParentQueue: Re-sorting assigned queue: root.default stats: default: capacity=1.0, absoluteCapacity=1.0, usedResources=<memory:5120, vCores:4>, usedCapacity=0.625, absoluteUsedCapacity=0.625, numApps=1, numContainers=4
2015-01-14 19:55:09,807 INFO org.apache.hadoop.yarn.server.resourcemanager.scheduler.capacity.ParentQueue: assignedContainer queue=root usedCapacity=0.625 absoluteUsedCapacity=0.625 used=<memory:5120, vCores:4> cluster=<memory:8192, vCores:8>
2015-01-14 19:55:09,808 INFO org.apache.hadoop.yarn.server.resourcemanager.rmcontainer.RMContainerImpl: container_1421286406893_0001_01_000021 Container Transitioned from NEW to ALLOCATED
2015-01-14 19:55:09,808 INFO org.apache.hadoop.yarn.server.resourcemanager.RMAuditLogger: USER=doopy	OPERATION=AM Allocated Container	TARGET=SchedulerApp	RESULT=SUCCESS	APPID=application_1421286406893_0001	CONTAINERID=container_1421286406893_0001_01_000021
2015-01-14 19:55:09,808 INFO org.apache.hadoop.yarn.server.resourcemanager.scheduler.SchedulerNode: Assigned container container_1421286406893_0001_01_000021 of capacity <memory:1024, vCores:1> on host barbie:45258, which has 5 containers, <memory:6144, vCores:5> used and <memory:2048, vCores:3> available after allocation
2015-01-14 19:55:09,808 INFO org.apache.hadoop.yarn.server.resourcemanager.scheduler.capacity.LeafQueue: assignedContainer application attempt=appattempt_1421286406893_0001_000001 container=Container: [ContainerId: container_1421286406893_0001_01_000021, NodeId: barbie:45258, NodeHttpAddress: barbie:8042, Resource: <memory:1024, vCores:1>, Priority: 20, Token: null, ] queue=default: capacity=1.0, absoluteCapacity=1.0, usedResources=<memory:5120, vCores:4>, usedCapacity=0.625, absoluteUsedCapacity=0.625, numApps=1, numContainers=4 clusterResource=<memory:8192, vCores:8>
2015-01-14 19:55:09,809 INFO org.apache.hadoop.yarn.server.resourcemanager.scheduler.capacity.ParentQueue: Re-sorting assigned queue: root.default stats: default: capacity=1.0, absoluteCapacity=1.0, usedResources=<memory:6144, vCores:5>, usedCapacity=0.75, absoluteUsedCapacity=0.75, numApps=1, numContainers=5
2015-01-14 19:55:09,809 INFO org.apache.hadoop.yarn.server.resourcemanager.scheduler.capacity.ParentQueue: assignedContainer queue=root usedCapacity=0.75 absoluteUsedCapacity=0.75 used=<memory:6144, vCores:5> cluster=<memory:8192, vCores:8>
2015-01-14 19:55:09,809 INFO org.apache.hadoop.yarn.server.resourcemanager.rmcontainer.RMContainerImpl: container_1421286406893_0001_01_000022 Container Transitioned from NEW to ALLOCATED
2015-01-14 19:55:09,809 INFO org.apache.hadoop.yarn.server.resourcemanager.RMAuditLogger: USER=doopy	OPERATION=AM Allocated Container	TARGET=SchedulerApp	RESULT=SUCCESS	APPID=application_1421286406893_0001	CONTAINERID=container_1421286406893_0001_01_000022
2015-01-14 19:55:09,810 INFO org.apache.hadoop.yarn.server.resourcemanager.scheduler.SchedulerNode: Assigned container container_1421286406893_0001_01_000022 of capacity <memory:1024, vCores:1> on host barbie:45258, which has 6 containers, <memory:7168, vCores:6> used and <memory:1024, vCores:2> available after allocation
2015-01-14 19:55:09,810 INFO org.apache.hadoop.yarn.server.resourcemanager.scheduler.capacity.LeafQueue: assignedContainer application attempt=appattempt_1421286406893_0001_000001 container=Container: [ContainerId: container_1421286406893_0001_01_000022, NodeId: barbie:45258, NodeHttpAddress: barbie:8042, Resource: <memory:1024, vCores:1>, Priority: 20, Token: null, ] queue=default: capacity=1.0, absoluteCapacity=1.0, usedResources=<memory:6144, vCores:5>, usedCapacity=0.75, absoluteUsedCapacity=0.75, numApps=1, numContainers=5 clusterResource=<memory:8192, vCores:8>
2015-01-14 19:55:09,810 INFO org.apache.hadoop.yarn.server.resourcemanager.scheduler.capacity.ParentQueue: Re-sorting assigned queue: root.default stats: default: capacity=1.0, absoluteCapacity=1.0, usedResources=<memory:7168, vCores:6>, usedCapacity=0.875, absoluteUsedCapacity=0.875, numApps=1, numContainers=6
2015-01-14 19:55:09,811 INFO org.apache.hadoop.yarn.server.resourcemanager.scheduler.capacity.ParentQueue: assignedContainer queue=root usedCapacity=0.875 absoluteUsedCapacity=0.875 used=<memory:7168, vCores:6> cluster=<memory:8192, vCores:8>
2015-01-14 19:55:09,811 INFO org.apache.hadoop.yarn.server.resourcemanager.rmcontainer.RMContainerImpl: container_1421286406893_0001_01_000023 Container Transitioned from NEW to ALLOCATED
2015-01-14 19:55:09,811 INFO org.apache.hadoop.yarn.server.resourcemanager.RMAuditLogger: USER=doopy	OPERATION=AM Allocated Container	TARGET=SchedulerApp	RESULT=SUCCESS	APPID=application_1421286406893_0001	CONTAINERID=container_1421286406893_0001_01_000023
2015-01-14 19:55:09,811 INFO org.apache.hadoop.yarn.server.resourcemanager.scheduler.SchedulerNode: Assigned container container_1421286406893_0001_01_000023 of capacity <memory:1024, vCores:1> on host barbie:45258, which has 7 containers, <memory:8192, vCores:7> used and <memory:0, vCores:1> available after allocation
2015-01-14 19:55:09,812 INFO org.apache.hadoop.yarn.server.resourcemanager.scheduler.capacity.LeafQueue: assignedContainer application attempt=appattempt_1421286406893_0001_000001 container=Container: [ContainerId: container_1421286406893_0001_01_000023, NodeId: barbie:45258, NodeHttpAddress: barbie:8042, Resource: <memory:1024, vCores:1>, Priority: 20, Token: null, ] queue=default: capacity=1.0, absoluteCapacity=1.0, usedResources=<memory:7168, vCores:6>, usedCapacity=0.875, absoluteUsedCapacity=0.875, numApps=1, numContainers=6 clusterResource=<memory:8192, vCores:8>
2015-01-14 19:55:09,812 INFO org.apache.hadoop.yarn.server.resourcemanager.scheduler.capacity.ParentQueue: Re-sorting assigned queue: root.default stats: default: capacity=1.0, absoluteCapacity=1.0, usedResources=<memory:8192, vCores:7>, usedCapacity=1.0, absoluteUsedCapacity=1.0, numApps=1, numContainers=7
2015-01-14 19:55:09,812 INFO org.apache.hadoop.yarn.server.resourcemanager.scheduler.capacity.ParentQueue: assignedContainer queue=root usedCapacity=1.0 absoluteUsedCapacity=1.0 used=<memory:8192, vCores:7> cluster=<memory:8192, vCores:8>
2015-01-14 19:55:10,347 INFO org.apache.hadoop.yarn.server.resourcemanager.rmcontainer.RMContainerImpl: container_1421286406893_0001_01_000019 Container Transitioned from ALLOCATED to ACQUIRED
2015-01-14 19:55:10,398 INFO org.apache.hadoop.yarn.server.resourcemanager.rmcontainer.RMContainerImpl: container_1421286406893_0001_01_000020 Container Transitioned from ALLOCATED to ACQUIRED
2015-01-14 19:55:10,401 INFO org.apache.hadoop.yarn.server.resourcemanager.rmcontainer.RMContainerImpl: container_1421286406893_0001_01_000021 Container Transitioned from ALLOCATED to ACQUIRED
2015-01-14 19:55:10,404 INFO org.apache.hadoop.yarn.server.resourcemanager.rmcontainer.RMContainerImpl: container_1421286406893_0001_01_000022 Container Transitioned from ALLOCATED to ACQUIRED
2015-01-14 19:55:10,408 INFO org.apache.hadoop.yarn.server.resourcemanager.rmcontainer.RMContainerImpl: container_1421286406893_0001_01_000023 Container Transitioned from ALLOCATED to ACQUIRED
2015-01-14 19:55:10,881 INFO org.apache.hadoop.yarn.server.resourcemanager.scheduler.capacity.CapacityScheduler: Null container completed...
2015-01-14 19:55:10,881 INFO org.apache.hadoop.yarn.server.resourcemanager.scheduler.capacity.CapacityScheduler: Null container completed...
2015-01-14 19:55:10,881 INFO org.apache.hadoop.yarn.server.resourcemanager.scheduler.capacity.CapacityScheduler: Null container completed...
2015-01-14 19:55:10,882 INFO org.apache.hadoop.yarn.server.resourcemanager.scheduler.capacity.CapacityScheduler: Null container completed...
2015-01-14 19:55:10,882 INFO org.apache.hadoop.yarn.server.resourcemanager.scheduler.capacity.CapacityScheduler: Null container completed...
2015-01-14 19:55:12,002 INFO org.apache.hadoop.yarn.server.resourcemanager.rmcontainer.RMContainerImpl: container_1421286406893_0001_01_000019 Container Transitioned from ACQUIRED to RUNNING
2015-01-14 19:55:12,003 INFO org.apache.hadoop.yarn.server.resourcemanager.rmcontainer.RMContainerImpl: container_1421286406893_0001_01_000020 Container Transitioned from ACQUIRED to RUNNING
2015-01-14 19:55:12,003 INFO org.apache.hadoop.yarn.server.resourcemanager.rmcontainer.RMContainerImpl: container_1421286406893_0001_01_000021 Container Transitioned from ACQUIRED to RUNNING
2015-01-14 19:55:12,003 INFO org.apache.hadoop.yarn.server.resourcemanager.rmcontainer.RMContainerImpl: container_1421286406893_0001_01_000022 Container Transitioned from ACQUIRED to RUNNING
2015-01-14 19:55:12,003 INFO org.apache.hadoop.yarn.server.resourcemanager.rmcontainer.RMContainerImpl: container_1421286406893_0001_01_000023 Container Transitioned from ACQUIRED to RUNNING
2015-01-14 19:55:12,003 INFO org.apache.hadoop.yarn.server.resourcemanager.scheduler.capacity.CapacityScheduler: Null container completed...
2015-01-14 19:55:12,003 INFO org.apache.hadoop.yarn.server.resourcemanager.scheduler.capacity.CapacityScheduler: Null container completed...
2015-01-14 19:55:12,003 INFO org.apache.hadoop.yarn.server.resourcemanager.scheduler.capacity.CapacityScheduler: Null container completed...
2015-01-14 19:55:12,003 INFO org.apache.hadoop.yarn.server.resourcemanager.scheduler.capacity.CapacityScheduler: Null container completed...
2015-01-14 19:55:12,003 INFO org.apache.hadoop.yarn.server.resourcemanager.scheduler.capacity.CapacityScheduler: Null container completed...
2015-01-14 19:56:47,753 INFO SecurityLogger.org.apache.hadoop.ipc.Server: Auth successful for appattempt_1421286406893_0001_000001 (auth:SIMPLE)
2015-01-14 19:56:52,508 INFO org.apache.hadoop.yarn.server.resourcemanager.scheduler.AbstractYarnScheduler: Release request cache is cleaned up
2015-01-14 19:57:27,840 INFO org.apache.hadoop.yarn.server.resourcemanager.rmcontainer.RMContainerImpl: container_1421286406893_0001_01_000019 Container Transitioned from RUNNING to COMPLETED
2015-01-14 19:57:27,841 INFO org.apache.hadoop.yarn.server.resourcemanager.scheduler.common.fica.FiCaSchedulerApp: Completed container: container_1421286406893_0001_01_000019 in state: COMPLETED event:FINISHED
2015-01-14 19:57:27,853 INFO org.apache.hadoop.yarn.server.resourcemanager.RMAuditLogger: USER=doopy	OPERATION=AM Released Container	TARGET=SchedulerApp	RESULT=SUCCESS	APPID=application_1421286406893_0001	CONTAINERID=container_1421286406893_0001_01_000019
2015-01-14 19:57:27,872 INFO org.apache.hadoop.yarn.server.resourcemanager.scheduler.SchedulerNode: Released container container_1421286406893_0001_01_000019 of capacity <memory:1024, vCores:1> on host barbie:45258, which currently has 6 containers, <memory:7168, vCores:6> used and <memory:1024, vCores:2> available, release resources=true
2015-01-14 19:57:27,882 INFO org.apache.hadoop.yarn.server.resourcemanager.scheduler.capacity.LeafQueue: default used=<memory:7168, vCores:6> numContainers=6 user=doopy user-resources=<memory:7168, vCores:6>
2015-01-14 19:57:27,985 INFO org.apache.hadoop.yarn.server.resourcemanager.scheduler.capacity.LeafQueue: completedContainer container=Container: [ContainerId: container_1421286406893_0001_01_000019, NodeId: barbie:45258, NodeHttpAddress: barbie:8042, Resource: <memory:1024, vCores:1>, Priority: 20, Token: Token { kind: ContainerToken, service: 127.0.1.1:45258 }, ] queue=default: capacity=1.0, absoluteCapacity=1.0, usedResources=<memory:7168, vCores:6>, usedCapacity=0.875, absoluteUsedCapacity=0.875, numApps=1, numContainers=6 cluster=<memory:8192, vCores:8>
2015-01-14 19:57:27,991 INFO org.apache.hadoop.yarn.server.resourcemanager.scheduler.capacity.ParentQueue: completedContainer queue=root usedCapacity=0.875 absoluteUsedCapacity=0.875 used=<memory:7168, vCores:6> cluster=<memory:8192, vCores:8>
2015-01-14 19:57:27,992 INFO org.apache.hadoop.yarn.server.resourcemanager.scheduler.capacity.ParentQueue: Re-sorting completed queue: root.default stats: default: capacity=1.0, absoluteCapacity=1.0, usedResources=<memory:7168, vCores:6>, usedCapacity=0.875, absoluteUsedCapacity=0.875, numApps=1, numContainers=6
2015-01-14 19:57:28,000 INFO org.apache.hadoop.yarn.server.resourcemanager.scheduler.capacity.CapacityScheduler: Application attempt appattempt_1421286406893_0001_000001 released container container_1421286406893_0001_01_000019 on node: host: barbie:45258 #containers=6 available=1024 used=7168 with event: FINISHED
2015-01-14 19:57:28,001 INFO org.apache.hadoop.yarn.server.resourcemanager.rmcontainer.RMContainerImpl: container_1421286406893_0001_01_000020 Container Transitioned from RUNNING to COMPLETED
2015-01-14 19:57:28,008 INFO org.apache.hadoop.yarn.server.resourcemanager.scheduler.common.fica.FiCaSchedulerApp: Completed container: container_1421286406893_0001_01_000020 in state: COMPLETED event:FINISHED
2015-01-14 19:57:28,008 INFO org.apache.hadoop.yarn.server.resourcemanager.RMAuditLogger: USER=doopy	OPERATION=AM Released Container	TARGET=SchedulerApp	RESULT=SUCCESS	APPID=application_1421286406893_0001	CONTAINERID=container_1421286406893_0001_01_000020
2015-01-14 19:57:28,008 INFO org.apache.hadoop.yarn.server.resourcemanager.scheduler.SchedulerNode: Released container container_1421286406893_0001_01_000020 of capacity <memory:1024, vCores:1> on host barbie:45258, which currently has 5 containers, <memory:6144, vCores:5> used and <memory:2048, vCores:3> available, release resources=true
2015-01-14 19:57:28,009 INFO org.apache.hadoop.yarn.server.resourcemanager.scheduler.capacity.LeafQueue: default used=<memory:6144, vCores:5> numContainers=5 user=doopy user-resources=<memory:6144, vCores:5>
2015-01-14 19:57:28,009 INFO org.apache.hadoop.yarn.server.resourcemanager.scheduler.capacity.LeafQueue: completedContainer container=Container: [ContainerId: container_1421286406893_0001_01_000020, NodeId: barbie:45258, NodeHttpAddress: barbie:8042, Resource: <memory:1024, vCores:1>, Priority: 20, Token: Token { kind: ContainerToken, service: 127.0.1.1:45258 }, ] queue=default: capacity=1.0, absoluteCapacity=1.0, usedResources=<memory:6144, vCores:5>, usedCapacity=0.75, absoluteUsedCapacity=0.75, numApps=1, numContainers=5 cluster=<memory:8192, vCores:8>
2015-01-14 19:57:28,009 INFO org.apache.hadoop.yarn.server.resourcemanager.scheduler.capacity.ParentQueue: completedContainer queue=root usedCapacity=0.75 absoluteUsedCapacity=0.75 used=<memory:6144, vCores:5> cluster=<memory:8192, vCores:8>
2015-01-14 19:57:28,009 INFO org.apache.hadoop.yarn.server.resourcemanager.scheduler.capacity.ParentQueue: Re-sorting completed queue: root.default stats: default: capacity=1.0, absoluteCapacity=1.0, usedResources=<memory:6144, vCores:5>, usedCapacity=0.75, absoluteUsedCapacity=0.75, numApps=1, numContainers=5
2015-01-14 19:57:28,010 INFO org.apache.hadoop.yarn.server.resourcemanager.scheduler.capacity.CapacityScheduler: Application attempt appattempt_1421286406893_0001_000001 released container container_1421286406893_0001_01_000020 on node: host: barbie:45258 #containers=5 available=2048 used=6144 with event: FINISHED
2015-01-14 19:57:28,010 INFO org.apache.hadoop.yarn.server.resourcemanager.rmcontainer.RMContainerImpl: container_1421286406893_0001_01_000021 Container Transitioned from RUNNING to COMPLETED
2015-01-14 19:57:28,010 INFO org.apache.hadoop.yarn.server.resourcemanager.scheduler.common.fica.FiCaSchedulerApp: Completed container: container_1421286406893_0001_01_000021 in state: COMPLETED event:FINISHED
2015-01-14 19:57:28,010 INFO org.apache.hadoop.yarn.server.resourcemanager.RMAuditLogger: USER=doopy	OPERATION=AM Released Container	TARGET=SchedulerApp	RESULT=SUCCESS	APPID=application_1421286406893_0001	CONTAINERID=container_1421286406893_0001_01_000021
2015-01-14 19:57:28,010 INFO org.apache.hadoop.yarn.server.resourcemanager.scheduler.SchedulerNode: Released container container_1421286406893_0001_01_000021 of capacity <memory:1024, vCores:1> on host barbie:45258, which currently has 4 containers, <memory:5120, vCores:4> used and <memory:3072, vCores:4> available, release resources=true
2015-01-14 19:57:28,010 INFO org.apache.hadoop.yarn.server.resourcemanager.scheduler.capacity.LeafQueue: default used=<memory:5120, vCores:4> numContainers=4 user=doopy user-resources=<memory:5120, vCores:4>
2015-01-14 19:57:28,021 INFO org.apache.hadoop.yarn.server.resourcemanager.scheduler.capacity.LeafQueue: completedContainer container=Container: [ContainerId: container_1421286406893_0001_01_000021, NodeId: barbie:45258, NodeHttpAddress: barbie:8042, Resource: <memory:1024, vCores:1>, Priority: 20, Token: Token { kind: ContainerToken, service: 127.0.1.1:45258 }, ] queue=default: capacity=1.0, absoluteCapacity=1.0, usedResources=<memory:5120, vCores:4>, usedCapacity=0.625, absoluteUsedCapacity=0.625, numApps=1, numContainers=4 cluster=<memory:8192, vCores:8>
2015-01-14 19:57:28,021 INFO org.apache.hadoop.yarn.server.resourcemanager.scheduler.capacity.ParentQueue: completedContainer queue=root usedCapacity=0.625 absoluteUsedCapacity=0.625 used=<memory:5120, vCores:4> cluster=<memory:8192, vCores:8>
2015-01-14 19:57:28,022 INFO org.apache.hadoop.yarn.server.resourcemanager.scheduler.capacity.ParentQueue: Re-sorting completed queue: root.default stats: default: capacity=1.0, absoluteCapacity=1.0, usedResources=<memory:5120, vCores:4>, usedCapacity=0.625, absoluteUsedCapacity=0.625, numApps=1, numContainers=4
2015-01-14 19:57:28,022 INFO org.apache.hadoop.yarn.server.resourcemanager.scheduler.capacity.CapacityScheduler: Application attempt appattempt_1421286406893_0001_000001 released container container_1421286406893_0001_01_000021 on node: host: barbie:45258 #containers=4 available=3072 used=5120 with event: FINISHED
2015-01-14 19:57:28,022 INFO org.apache.hadoop.yarn.server.resourcemanager.rmcontainer.RMContainerImpl: container_1421286406893_0001_01_000022 Container Transitioned from RUNNING to COMPLETED
2015-01-14 19:57:28,023 INFO org.apache.hadoop.yarn.server.resourcemanager.scheduler.common.fica.FiCaSchedulerApp: Completed container: container_1421286406893_0001_01_000022 in state: COMPLETED event:FINISHED
2015-01-14 19:57:28,023 INFO org.apache.hadoop.yarn.server.resourcemanager.RMAuditLogger: USER=doopy	OPERATION=AM Released Container	TARGET=SchedulerApp	RESULT=SUCCESS	APPID=application_1421286406893_0001	CONTAINERID=container_1421286406893_0001_01_000022
2015-01-14 19:57:28,023 INFO org.apache.hadoop.yarn.server.resourcemanager.scheduler.SchedulerNode: Released container container_1421286406893_0001_01_000022 of capacity <memory:1024, vCores:1> on host barbie:45258, which currently has 3 containers, <memory:4096, vCores:3> used and <memory:4096, vCores:5> available, release resources=true
2015-01-14 19:57:28,023 INFO org.apache.hadoop.yarn.server.resourcemanager.scheduler.capacity.LeafQueue: default used=<memory:4096, vCores:3> numContainers=3 user=doopy user-resources=<memory:4096, vCores:3>
2015-01-14 19:57:28,027 INFO org.apache.hadoop.yarn.server.resourcemanager.scheduler.capacity.LeafQueue: completedContainer container=Container: [ContainerId: container_1421286406893_0001_01_000022, NodeId: barbie:45258, NodeHttpAddress: barbie:8042, Resource: <memory:1024, vCores:1>, Priority: 20, Token: Token { kind: ContainerToken, service: 127.0.1.1:45258 }, ] queue=default: capacity=1.0, absoluteCapacity=1.0, usedResources=<memory:4096, vCores:3>, usedCapacity=0.5, absoluteUsedCapacity=0.5, numApps=1, numContainers=3 cluster=<memory:8192, vCores:8>
2015-01-14 19:57:28,027 INFO org.apache.hadoop.yarn.server.resourcemanager.scheduler.capacity.ParentQueue: completedContainer queue=root usedCapacity=0.5 absoluteUsedCapacity=0.5 used=<memory:4096, vCores:3> cluster=<memory:8192, vCores:8>
2015-01-14 19:57:28,037 INFO org.apache.hadoop.yarn.server.resourcemanager.scheduler.capacity.ParentQueue: Re-sorting completed queue: root.default stats: default: capacity=1.0, absoluteCapacity=1.0, usedResources=<memory:4096, vCores:3>, usedCapacity=0.5, absoluteUsedCapacity=0.5, numApps=1, numContainers=3
2015-01-14 19:57:28,045 INFO org.apache.hadoop.yarn.server.resourcemanager.scheduler.capacity.CapacityScheduler: Application attempt appattempt_1421286406893_0001_000001 released container container_1421286406893_0001_01_000022 on node: host: barbie:45258 #containers=3 available=4096 used=4096 with event: FINISHED
2015-01-14 19:57:28,046 INFO org.apache.hadoop.yarn.server.resourcemanager.rmcontainer.RMContainerImpl: container_1421286406893_0001_01_000023 Container Transitioned from RUNNING to COMPLETED
2015-01-14 19:57:28,046 INFO org.apache.hadoop.yarn.server.resourcemanager.scheduler.common.fica.FiCaSchedulerApp: Completed container: container_1421286406893_0001_01_000023 in state: COMPLETED event:FINISHED
2015-01-14 19:57:28,046 INFO org.apache.hadoop.yarn.server.resourcemanager.RMAuditLogger: USER=doopy	OPERATION=AM Released Container	TARGET=SchedulerApp	RESULT=SUCCESS	APPID=application_1421286406893_0001	CONTAINERID=container_1421286406893_0001_01_000023
2015-01-14 19:57:28,046 INFO org.apache.hadoop.yarn.server.resourcemanager.scheduler.SchedulerNode: Released container container_1421286406893_0001_01_000023 of capacity <memory:1024, vCores:1> on host barbie:45258, which currently has 2 containers, <memory:3072, vCores:2> used and <memory:5120, vCores:6> available, release resources=true
2015-01-14 19:57:28,046 INFO org.apache.hadoop.yarn.server.resourcemanager.scheduler.capacity.LeafQueue: default used=<memory:3072, vCores:2> numContainers=2 user=doopy user-resources=<memory:3072, vCores:2>
2015-01-14 19:57:28,046 INFO org.apache.hadoop.yarn.server.resourcemanager.scheduler.capacity.LeafQueue: completedContainer container=Container: [ContainerId: container_1421286406893_0001_01_000023, NodeId: barbie:45258, NodeHttpAddress: barbie:8042, Resource: <memory:1024, vCores:1>, Priority: 20, Token: Token { kind: ContainerToken, service: 127.0.1.1:45258 }, ] queue=default: capacity=1.0, absoluteCapacity=1.0, usedResources=<memory:3072, vCores:2>, usedCapacity=0.375, absoluteUsedCapacity=0.375, numApps=1, numContainers=2 cluster=<memory:8192, vCores:8>
2015-01-14 19:57:28,046 INFO org.apache.hadoop.yarn.server.resourcemanager.scheduler.capacity.ParentQueue: completedContainer queue=root usedCapacity=0.375 absoluteUsedCapacity=0.375 used=<memory:3072, vCores:2> cluster=<memory:8192, vCores:8>
2015-01-14 19:57:28,046 INFO org.apache.hadoop.yarn.server.resourcemanager.scheduler.capacity.ParentQueue: Re-sorting completed queue: root.default stats: default: capacity=1.0, absoluteCapacity=1.0, usedResources=<memory:3072, vCores:2>, usedCapacity=0.375, absoluteUsedCapacity=0.375, numApps=1, numContainers=2
2015-01-14 19:57:28,047 INFO org.apache.hadoop.yarn.server.resourcemanager.scheduler.capacity.CapacityScheduler: Application attempt appattempt_1421286406893_0001_000001 released container container_1421286406893_0001_01_000023 on node: host: barbie:45258 #containers=2 available=5120 used=3072 with event: FINISHED
2015-01-14 19:57:28,085 INFO org.apache.hadoop.yarn.server.resourcemanager.rmcontainer.RMContainerImpl: container_1421286406893_0001_01_000024 Container Transitioned from NEW to ALLOCATED
2015-01-14 19:57:28,085 INFO org.apache.hadoop.yarn.server.resourcemanager.RMAuditLogger: USER=doopy	OPERATION=AM Allocated Container	TARGET=SchedulerApp	RESULT=SUCCESS	APPID=application_1421286406893_0001	CONTAINERID=container_1421286406893_0001_01_000024
2015-01-14 19:57:28,085 INFO org.apache.hadoop.yarn.server.resourcemanager.scheduler.SchedulerNode: Assigned container container_1421286406893_0001_01_000024 of capacity <memory:1024, vCores:1> on host barbie:45258, which has 3 containers, <memory:4096, vCores:3> used and <memory:4096, vCores:5> available after allocation
2015-01-14 19:57:28,085 INFO org.apache.hadoop.yarn.server.resourcemanager.scheduler.capacity.LeafQueue: assignedContainer application attempt=appattempt_1421286406893_0001_000001 container=Container: [ContainerId: container_1421286406893_0001_01_000024, NodeId: barbie:45258, NodeHttpAddress: barbie:8042, Resource: <memory:1024, vCores:1>, Priority: 20, Token: null, ] queue=default: capacity=1.0, absoluteCapacity=1.0, usedResources=<memory:3072, vCores:2>, usedCapacity=0.375, absoluteUsedCapacity=0.375, numApps=1, numContainers=2 clusterResource=<memory:8192, vCores:8>
2015-01-14 19:57:28,085 INFO org.apache.hadoop.yarn.server.resourcemanager.scheduler.capacity.ParentQueue: Re-sorting assigned queue: root.default stats: default: capacity=1.0, absoluteCapacity=1.0, usedResources=<memory:4096, vCores:3>, usedCapacity=0.5, absoluteUsedCapacity=0.5, numApps=1, numContainers=3
2015-01-14 19:57:28,086 INFO org.apache.hadoop.yarn.server.resourcemanager.scheduler.capacity.ParentQueue: assignedContainer queue=root usedCapacity=0.5 absoluteUsedCapacity=0.5 used=<memory:4096, vCores:3> cluster=<memory:8192, vCores:8>
2015-01-14 19:57:28,086 INFO org.apache.hadoop.yarn.server.resourcemanager.rmcontainer.RMContainerImpl: container_1421286406893_0001_01_000025 Container Transitioned from NEW to ALLOCATED
2015-01-14 19:57:28,086 INFO org.apache.hadoop.yarn.server.resourcemanager.RMAuditLogger: USER=doopy	OPERATION=AM Allocated Container	TARGET=SchedulerApp	RESULT=SUCCESS	APPID=application_1421286406893_0001	CONTAINERID=container_1421286406893_0001_01_000025
2015-01-14 19:57:28,086 INFO org.apache.hadoop.yarn.server.resourcemanager.scheduler.SchedulerNode: Assigned container container_1421286406893_0001_01_000025 of capacity <memory:1024, vCores:1> on host barbie:45258, which has 4 containers, <memory:5120, vCores:4> used and <memory:3072, vCores:4> available after allocation
2015-01-14 19:57:28,086 INFO org.apache.hadoop.yarn.server.resourcemanager.scheduler.capacity.LeafQueue: assignedContainer application attempt=appattempt_1421286406893_0001_000001 container=Container: [ContainerId: container_1421286406893_0001_01_000025, NodeId: barbie:45258, NodeHttpAddress: barbie:8042, Resource: <memory:1024, vCores:1>, Priority: 20, Token: null, ] queue=default: capacity=1.0, absoluteCapacity=1.0, usedResources=<memory:4096, vCores:3>, usedCapacity=0.5, absoluteUsedCapacity=0.5, numApps=1, numContainers=3 clusterResource=<memory:8192, vCores:8>
2015-01-14 19:57:28,087 INFO org.apache.hadoop.yarn.server.resourcemanager.scheduler.capacity.ParentQueue: Re-sorting assigned queue: root.default stats: default: capacity=1.0, absoluteCapacity=1.0, usedResources=<memory:5120, vCores:4>, usedCapacity=0.625, absoluteUsedCapacity=0.625, numApps=1, numContainers=4
2015-01-14 19:57:28,087 INFO org.apache.hadoop.yarn.server.resourcemanager.scheduler.capacity.ParentQueue: assignedContainer queue=root usedCapacity=0.625 absoluteUsedCapacity=0.625 used=<memory:5120, vCores:4> cluster=<memory:8192, vCores:8>
2015-01-14 19:57:28,087 INFO org.apache.hadoop.yarn.server.resourcemanager.rmcontainer.RMContainerImpl: container_1421286406893_0001_01_000026 Container Transitioned from NEW to ALLOCATED
2015-01-14 19:57:28,087 INFO org.apache.hadoop.yarn.server.resourcemanager.RMAuditLogger: USER=doopy	OPERATION=AM Allocated Container	TARGET=SchedulerApp	RESULT=SUCCESS	APPID=application_1421286406893_0001	CONTAINERID=container_1421286406893_0001_01_000026
2015-01-14 19:57:28,087 INFO org.apache.hadoop.yarn.server.resourcemanager.scheduler.SchedulerNode: Assigned container container_1421286406893_0001_01_000026 of capacity <memory:1024, vCores:1> on host barbie:45258, which has 5 containers, <memory:6144, vCores:5> used and <memory:2048, vCores:3> available after allocation
2015-01-14 19:57:28,088 INFO org.apache.hadoop.yarn.server.resourcemanager.scheduler.capacity.LeafQueue: assignedContainer application attempt=appattempt_1421286406893_0001_000001 container=Container: [ContainerId: container_1421286406893_0001_01_000026, NodeId: barbie:45258, NodeHttpAddress: barbie:8042, Resource: <memory:1024, vCores:1>, Priority: 20, Token: null, ] queue=default: capacity=1.0, absoluteCapacity=1.0, usedResources=<memory:5120, vCores:4>, usedCapacity=0.625, absoluteUsedCapacity=0.625, numApps=1, numContainers=4 clusterResource=<memory:8192, vCores:8>
2015-01-14 19:57:28,088 INFO org.apache.hadoop.yarn.server.resourcemanager.scheduler.capacity.ParentQueue: Re-sorting assigned queue: root.default stats: default: capacity=1.0, absoluteCapacity=1.0, usedResources=<memory:6144, vCores:5>, usedCapacity=0.75, absoluteUsedCapacity=0.75, numApps=1, numContainers=5
2015-01-14 19:57:28,116 INFO org.apache.hadoop.yarn.server.resourcemanager.scheduler.capacity.ParentQueue: assignedContainer queue=root usedCapacity=0.75 absoluteUsedCapacity=0.75 used=<memory:6144, vCores:5> cluster=<memory:8192, vCores:8>
2015-01-14 19:57:28,117 INFO org.apache.hadoop.yarn.server.resourcemanager.rmcontainer.RMContainerImpl: container_1421286406893_0001_01_000027 Container Transitioned from NEW to ALLOCATED
2015-01-14 19:57:28,119 INFO org.apache.hadoop.yarn.server.resourcemanager.RMAuditLogger: USER=doopy	OPERATION=AM Allocated Container	TARGET=SchedulerApp	RESULT=SUCCESS	APPID=application_1421286406893_0001	CONTAINERID=container_1421286406893_0001_01_000027
2015-01-14 19:57:28,119 INFO org.apache.hadoop.yarn.server.resourcemanager.scheduler.SchedulerNode: Assigned container container_1421286406893_0001_01_000027 of capacity <memory:1024, vCores:1> on host barbie:45258, which has 6 containers, <memory:7168, vCores:6> used and <memory:1024, vCores:2> available after allocation
2015-01-14 19:57:28,127 INFO org.apache.hadoop.yarn.server.resourcemanager.scheduler.capacity.LeafQueue: assignedContainer application attempt=appattempt_1421286406893_0001_000001 container=Container: [ContainerId: container_1421286406893_0001_01_000027, NodeId: barbie:45258, NodeHttpAddress: barbie:8042, Resource: <memory:1024, vCores:1>, Priority: 20, Token: null, ] queue=default: capacity=1.0, absoluteCapacity=1.0, usedResources=<memory:6144, vCores:5>, usedCapacity=0.75, absoluteUsedCapacity=0.75, numApps=1, numContainers=5 clusterResource=<memory:8192, vCores:8>
2015-01-14 19:57:28,127 INFO org.apache.hadoop.yarn.server.resourcemanager.scheduler.capacity.ParentQueue: Re-sorting assigned queue: root.default stats: default: capacity=1.0, absoluteCapacity=1.0, usedResources=<memory:7168, vCores:6>, usedCapacity=0.875, absoluteUsedCapacity=0.875, numApps=1, numContainers=6
2015-01-14 19:57:28,136 INFO org.apache.hadoop.yarn.server.resourcemanager.scheduler.capacity.ParentQueue: assignedContainer queue=root usedCapacity=0.875 absoluteUsedCapacity=0.875 used=<memory:7168, vCores:6> cluster=<memory:8192, vCores:8>
2015-01-14 19:57:28,137 INFO org.apache.hadoop.yarn.server.resourcemanager.rmcontainer.RMContainerImpl: container_1421286406893_0001_01_000028 Container Transitioned from NEW to ALLOCATED
2015-01-14 19:57:28,137 INFO org.apache.hadoop.yarn.server.resourcemanager.RMAuditLogger: USER=doopy	OPERATION=AM Allocated Container	TARGET=SchedulerApp	RESULT=SUCCESS	APPID=application_1421286406893_0001	CONTAINERID=container_1421286406893_0001_01_000028
2015-01-14 19:57:28,137 INFO org.apache.hadoop.yarn.server.resourcemanager.scheduler.SchedulerNode: Assigned container container_1421286406893_0001_01_000028 of capacity <memory:1024, vCores:1> on host barbie:45258, which has 7 containers, <memory:8192, vCores:7> used and <memory:0, vCores:1> available after allocation
2015-01-14 19:57:28,137 INFO org.apache.hadoop.yarn.server.resourcemanager.scheduler.capacity.LeafQueue: assignedContainer application attempt=appattempt_1421286406893_0001_000001 container=Container: [ContainerId: container_1421286406893_0001_01_000028, NodeId: barbie:45258, NodeHttpAddress: barbie:8042, Resource: <memory:1024, vCores:1>, Priority: 20, Token: null, ] queue=default: capacity=1.0, absoluteCapacity=1.0, usedResources=<memory:7168, vCores:6>, usedCapacity=0.875, absoluteUsedCapacity=0.875, numApps=1, numContainers=6 clusterResource=<memory:8192, vCores:8>
2015-01-14 19:57:28,138 INFO org.apache.hadoop.yarn.server.resourcemanager.scheduler.capacity.ParentQueue: Re-sorting assigned queue: root.default stats: default: capacity=1.0, absoluteCapacity=1.0, usedResources=<memory:8192, vCores:7>, usedCapacity=1.0, absoluteUsedCapacity=1.0, numApps=1, numContainers=7
2015-01-14 19:57:28,138 INFO org.apache.hadoop.yarn.server.resourcemanager.scheduler.capacity.ParentQueue: assignedContainer queue=root usedCapacity=1.0 absoluteUsedCapacity=1.0 used=<memory:8192, vCores:7> cluster=<memory:8192, vCores:8>
2015-01-14 19:57:28,722 INFO org.apache.hadoop.yarn.server.resourcemanager.rmcontainer.RMContainerImpl: container_1421286406893_0001_01_000024 Container Transitioned from ALLOCATED to ACQUIRED
2015-01-14 19:57:28,749 INFO org.apache.hadoop.yarn.server.resourcemanager.rmcontainer.RMContainerImpl: container_1421286406893_0001_01_000025 Container Transitioned from ALLOCATED to ACQUIRED
2015-01-14 19:57:28,853 INFO org.apache.hadoop.yarn.server.resourcemanager.rmcontainer.RMContainerImpl: container_1421286406893_0001_01_000026 Container Transitioned from ALLOCATED to ACQUIRED
2015-01-14 19:57:28,894 INFO org.apache.hadoop.yarn.server.resourcemanager.rmcontainer.RMContainerImpl: container_1421286406893_0001_01_000027 Container Transitioned from ALLOCATED to ACQUIRED
2015-01-14 19:57:28,910 INFO org.apache.hadoop.yarn.server.resourcemanager.rmcontainer.RMContainerImpl: container_1421286406893_0001_01_000028 Container Transitioned from ALLOCATED to ACQUIRED
2015-01-14 19:57:28,910 INFO org.apache.hadoop.yarn.server.resourcemanager.scheduler.capacity.CapacityScheduler: Null container completed...
2015-01-14 19:57:28,910 INFO org.apache.hadoop.yarn.server.resourcemanager.scheduler.capacity.CapacityScheduler: Null container completed...
2015-01-14 19:57:28,910 INFO org.apache.hadoop.yarn.server.resourcemanager.scheduler.capacity.CapacityScheduler: Null container completed...
2015-01-14 19:57:28,910 INFO org.apache.hadoop.yarn.server.resourcemanager.scheduler.capacity.CapacityScheduler: Null container completed...
2015-01-14 19:57:28,910 INFO org.apache.hadoop.yarn.server.resourcemanager.scheduler.capacity.CapacityScheduler: Null container completed...
2015-01-14 19:57:33,367 INFO org.apache.hadoop.yarn.server.resourcemanager.scheduler.capacity.CapacityScheduler: Null container completed...
2015-01-14 19:57:33,367 INFO org.apache.hadoop.yarn.server.resourcemanager.scheduler.capacity.CapacityScheduler: Null container completed...
2015-01-14 19:57:33,367 INFO org.apache.hadoop.yarn.server.resourcemanager.scheduler.capacity.CapacityScheduler: Null container completed...
2015-01-14 19:57:33,367 INFO org.apache.hadoop.yarn.server.resourcemanager.scheduler.capacity.CapacityScheduler: Null container completed...
2015-01-14 19:57:33,367 INFO org.apache.hadoop.yarn.server.resourcemanager.scheduler.capacity.CapacityScheduler: Null container completed...
2015-01-14 19:57:34,373 INFO org.apache.hadoop.yarn.server.resourcemanager.rmcontainer.RMContainerImpl: container_1421286406893_0001_01_000024 Container Transitioned from ACQUIRED to RUNNING
2015-01-14 19:57:34,373 INFO org.apache.hadoop.yarn.server.resourcemanager.rmcontainer.RMContainerImpl: container_1421286406893_0001_01_000025 Container Transitioned from ACQUIRED to RUNNING
2015-01-14 19:57:34,373 INFO org.apache.hadoop.yarn.server.resourcemanager.rmcontainer.RMContainerImpl: container_1421286406893_0001_01_000026 Container Transitioned from ACQUIRED to RUNNING
2015-01-14 19:57:34,373 INFO org.apache.hadoop.yarn.server.resourcemanager.rmcontainer.RMContainerImpl: container_1421286406893_0001_01_000027 Container Transitioned from ACQUIRED to RUNNING
2015-01-14 19:57:34,374 INFO org.apache.hadoop.yarn.server.resourcemanager.rmcontainer.RMContainerImpl: container_1421286406893_0001_01_000028 Container Transitioned from ACQUIRED to RUNNING
2015-01-14 19:58:59,688 INFO SecurityLogger.org.apache.hadoop.ipc.Server: Auth successful for appattempt_1421286406893_0001_000001 (auth:SIMPLE)
2015-01-14 19:59:49,168 INFO org.apache.hadoop.yarn.server.resourcemanager.rmcontainer.RMContainerImpl: container_1421286406893_0001_01_000024 Container Transitioned from RUNNING to COMPLETED
2015-01-14 19:59:49,168 INFO org.apache.hadoop.yarn.server.resourcemanager.scheduler.common.fica.FiCaSchedulerApp: Completed container: container_1421286406893_0001_01_000024 in state: COMPLETED event:FINISHED
2015-01-14 19:59:49,169 INFO org.apache.hadoop.yarn.server.resourcemanager.RMAuditLogger: USER=doopy	OPERATION=AM Released Container	TARGET=SchedulerApp	RESULT=SUCCESS	APPID=application_1421286406893_0001	CONTAINERID=container_1421286406893_0001_01_000024
2015-01-14 19:59:49,188 INFO org.apache.hadoop.yarn.server.resourcemanager.scheduler.SchedulerNode: Released container container_1421286406893_0001_01_000024 of capacity <memory:1024, vCores:1> on host barbie:45258, which currently has 6 containers, <memory:7168, vCores:6> used and <memory:1024, vCores:2> available, release resources=true
2015-01-14 19:59:49,188 INFO org.apache.hadoop.yarn.server.resourcemanager.scheduler.capacity.LeafQueue: default used=<memory:7168, vCores:6> numContainers=6 user=doopy user-resources=<memory:7168, vCores:6>
2015-01-14 19:59:49,348 INFO org.apache.hadoop.yarn.server.resourcemanager.scheduler.capacity.LeafQueue: completedContainer container=Container: [ContainerId: container_1421286406893_0001_01_000024, NodeId: barbie:45258, NodeHttpAddress: barbie:8042, Resource: <memory:1024, vCores:1>, Priority: 20, Token: Token { kind: ContainerToken, service: 127.0.1.1:45258 }, ] queue=default: capacity=1.0, absoluteCapacity=1.0, usedResources=<memory:7168, vCores:6>, usedCapacity=0.875, absoluteUsedCapacity=0.875, numApps=1, numContainers=6 cluster=<memory:8192, vCores:8>
2015-01-14 19:59:49,379 INFO org.apache.hadoop.yarn.server.resourcemanager.scheduler.capacity.ParentQueue: completedContainer queue=root usedCapacity=0.875 absoluteUsedCapacity=0.875 used=<memory:7168, vCores:6> cluster=<memory:8192, vCores:8>
2015-01-14 19:59:49,388 INFO org.apache.hadoop.yarn.server.resourcemanager.scheduler.capacity.ParentQueue: Re-sorting completed queue: root.default stats: default: capacity=1.0, absoluteCapacity=1.0, usedResources=<memory:7168, vCores:6>, usedCapacity=0.875, absoluteUsedCapacity=0.875, numApps=1, numContainers=6
2015-01-14 19:59:49,404 INFO org.apache.hadoop.yarn.server.resourcemanager.scheduler.capacity.CapacityScheduler: Application attempt appattempt_1421286406893_0001_000001 released container container_1421286406893_0001_01_000024 on node: host: barbie:45258 #containers=6 available=1024 used=7168 with event: FINISHED
2015-01-14 19:59:49,405 INFO org.apache.hadoop.yarn.server.resourcemanager.rmcontainer.RMContainerImpl: container_1421286406893_0001_01_000025 Container Transitioned from RUNNING to COMPLETED
2015-01-14 19:59:49,405 INFO org.apache.hadoop.yarn.server.resourcemanager.scheduler.common.fica.FiCaSchedulerApp: Completed container: container_1421286406893_0001_01_000025 in state: COMPLETED event:FINISHED
2015-01-14 19:59:49,413 INFO org.apache.hadoop.yarn.server.resourcemanager.RMAuditLogger: USER=doopy	OPERATION=AM Released Container	TARGET=SchedulerApp	RESULT=SUCCESS	APPID=application_1421286406893_0001	CONTAINERID=container_1421286406893_0001_01_000025
2015-01-14 19:59:49,413 INFO org.apache.hadoop.yarn.server.resourcemanager.scheduler.SchedulerNode: Released container container_1421286406893_0001_01_000025 of capacity <memory:1024, vCores:1> on host barbie:45258, which currently has 5 containers, <memory:6144, vCores:5> used and <memory:2048, vCores:3> available, release resources=true
2015-01-14 19:59:49,414 INFO org.apache.hadoop.yarn.server.resourcemanager.scheduler.capacity.LeafQueue: default used=<memory:6144, vCores:5> numContainers=5 user=doopy user-resources=<memory:6144, vCores:5>
2015-01-14 19:59:49,438 INFO org.apache.hadoop.yarn.server.resourcemanager.scheduler.capacity.LeafQueue: completedContainer container=Container: [ContainerId: container_1421286406893_0001_01_000025, NodeId: barbie:45258, NodeHttpAddress: barbie:8042, Resource: <memory:1024, vCores:1>, Priority: 20, Token: Token { kind: ContainerToken, service: 127.0.1.1:45258 }, ] queue=default: capacity=1.0, absoluteCapacity=1.0, usedResources=<memory:6144, vCores:5>, usedCapacity=0.75, absoluteUsedCapacity=0.75, numApps=1, numContainers=5 cluster=<memory:8192, vCores:8>
2015-01-14 19:59:49,438 INFO org.apache.hadoop.yarn.server.resourcemanager.scheduler.capacity.ParentQueue: completedContainer queue=root usedCapacity=0.75 absoluteUsedCapacity=0.75 used=<memory:6144, vCores:5> cluster=<memory:8192, vCores:8>
2015-01-14 19:59:49,438 INFO org.apache.hadoop.yarn.server.resourcemanager.scheduler.capacity.ParentQueue: Re-sorting completed queue: root.default stats: default: capacity=1.0, absoluteCapacity=1.0, usedResources=<memory:6144, vCores:5>, usedCapacity=0.75, absoluteUsedCapacity=0.75, numApps=1, numContainers=5
2015-01-14 19:59:49,438 INFO org.apache.hadoop.yarn.server.resourcemanager.scheduler.capacity.CapacityScheduler: Application attempt appattempt_1421286406893_0001_000001 released container container_1421286406893_0001_01_000025 on node: host: barbie:45258 #containers=5 available=2048 used=6144 with event: FINISHED
2015-01-14 19:59:49,439 INFO org.apache.hadoop.yarn.server.resourcemanager.rmcontainer.RMContainerImpl: container_1421286406893_0001_01_000026 Container Transitioned from RUNNING to COMPLETED
2015-01-14 19:59:49,439 INFO org.apache.hadoop.yarn.server.resourcemanager.scheduler.common.fica.FiCaSchedulerApp: Completed container: container_1421286406893_0001_01_000026 in state: COMPLETED event:FINISHED
2015-01-14 19:59:49,454 INFO org.apache.hadoop.yarn.server.resourcemanager.RMAuditLogger: USER=doopy	OPERATION=AM Released Container	TARGET=SchedulerApp	RESULT=SUCCESS	APPID=application_1421286406893_0001	CONTAINERID=container_1421286406893_0001_01_000026
2015-01-14 19:59:49,454 INFO org.apache.hadoop.yarn.server.resourcemanager.scheduler.SchedulerNode: Released container container_1421286406893_0001_01_000026 of capacity <memory:1024, vCores:1> on host barbie:45258, which currently has 4 containers, <memory:5120, vCores:4> used and <memory:3072, vCores:4> available, release resources=true
2015-01-14 19:59:49,454 INFO org.apache.hadoop.yarn.server.resourcemanager.scheduler.capacity.LeafQueue: default used=<memory:5120, vCores:4> numContainers=4 user=doopy user-resources=<memory:5120, vCores:4>
2015-01-14 19:59:49,477 INFO org.apache.hadoop.yarn.server.resourcemanager.scheduler.capacity.LeafQueue: completedContainer container=Container: [ContainerId: container_1421286406893_0001_01_000026, NodeId: barbie:45258, NodeHttpAddress: barbie:8042, Resource: <memory:1024, vCores:1>, Priority: 20, Token: Token { kind: ContainerToken, service: 127.0.1.1:45258 }, ] queue=default: capacity=1.0, absoluteCapacity=1.0, usedResources=<memory:5120, vCores:4>, usedCapacity=0.625, absoluteUsedCapacity=0.625, numApps=1, numContainers=4 cluster=<memory:8192, vCores:8>
2015-01-14 19:59:49,477 INFO org.apache.hadoop.yarn.server.resourcemanager.scheduler.capacity.ParentQueue: completedContainer queue=root usedCapacity=0.625 absoluteUsedCapacity=0.625 used=<memory:5120, vCores:4> cluster=<memory:8192, vCores:8>
2015-01-14 19:59:49,477 INFO org.apache.hadoop.yarn.server.resourcemanager.scheduler.capacity.ParentQueue: Re-sorting completed queue: root.default stats: default: capacity=1.0, absoluteCapacity=1.0, usedResources=<memory:5120, vCores:4>, usedCapacity=0.625, absoluteUsedCapacity=0.625, numApps=1, numContainers=4
2015-01-14 19:59:49,477 INFO org.apache.hadoop.yarn.server.resourcemanager.scheduler.capacity.CapacityScheduler: Application attempt appattempt_1421286406893_0001_000001 released container container_1421286406893_0001_01_000026 on node: host: barbie:45258 #containers=4 available=3072 used=5120 with event: FINISHED
2015-01-14 19:59:49,478 INFO org.apache.hadoop.yarn.server.resourcemanager.rmcontainer.RMContainerImpl: container_1421286406893_0001_01_000027 Container Transitioned from RUNNING to COMPLETED
2015-01-14 19:59:49,478 INFO org.apache.hadoop.yarn.server.resourcemanager.scheduler.common.fica.FiCaSchedulerApp: Completed container: container_1421286406893_0001_01_000027 in state: COMPLETED event:FINISHED
2015-01-14 19:59:49,478 INFO org.apache.hadoop.yarn.server.resourcemanager.RMAuditLogger: USER=doopy	OPERATION=AM Released Container	TARGET=SchedulerApp	RESULT=SUCCESS	APPID=application_1421286406893_0001	CONTAINERID=container_1421286406893_0001_01_000027
2015-01-14 19:59:49,488 INFO org.apache.hadoop.yarn.server.resourcemanager.scheduler.SchedulerNode: Released container container_1421286406893_0001_01_000027 of capacity <memory:1024, vCores:1> on host barbie:45258, which currently has 3 containers, <memory:4096, vCores:3> used and <memory:4096, vCores:5> available, release resources=true
2015-01-14 19:59:49,489 INFO org.apache.hadoop.yarn.server.resourcemanager.scheduler.capacity.LeafQueue: default used=<memory:4096, vCores:3> numContainers=3 user=doopy user-resources=<memory:4096, vCores:3>
2015-01-14 19:59:49,489 INFO org.apache.hadoop.yarn.server.resourcemanager.scheduler.capacity.LeafQueue: completedContainer container=Container: [ContainerId: container_1421286406893_0001_01_000027, NodeId: barbie:45258, NodeHttpAddress: barbie:8042, Resource: <memory:1024, vCores:1>, Priority: 20, Token: Token { kind: ContainerToken, service: 127.0.1.1:45258 }, ] queue=default: capacity=1.0, absoluteCapacity=1.0, usedResources=<memory:4096, vCores:3>, usedCapacity=0.5, absoluteUsedCapacity=0.5, numApps=1, numContainers=3 cluster=<memory:8192, vCores:8>
2015-01-14 19:59:49,489 INFO org.apache.hadoop.yarn.server.resourcemanager.scheduler.capacity.ParentQueue: completedContainer queue=root usedCapacity=0.5 absoluteUsedCapacity=0.5 used=<memory:4096, vCores:3> cluster=<memory:8192, vCores:8>
2015-01-14 19:59:49,489 INFO org.apache.hadoop.yarn.server.resourcemanager.scheduler.capacity.ParentQueue: Re-sorting completed queue: root.default stats: default: capacity=1.0, absoluteCapacity=1.0, usedResources=<memory:4096, vCores:3>, usedCapacity=0.5, absoluteUsedCapacity=0.5, numApps=1, numContainers=3
2015-01-14 19:59:49,490 INFO org.apache.hadoop.yarn.server.resourcemanager.scheduler.capacity.CapacityScheduler: Application attempt appattempt_1421286406893_0001_000001 released container container_1421286406893_0001_01_000027 on node: host: barbie:45258 #containers=3 available=4096 used=4096 with event: FINISHED
2015-01-14 19:59:49,490 INFO org.apache.hadoop.yarn.server.resourcemanager.rmcontainer.RMContainerImpl: container_1421286406893_0001_01_000028 Container Transitioned from RUNNING to COMPLETED
2015-01-14 19:59:49,490 INFO org.apache.hadoop.yarn.server.resourcemanager.scheduler.common.fica.FiCaSchedulerApp: Completed container: container_1421286406893_0001_01_000028 in state: COMPLETED event:FINISHED
2015-01-14 19:59:49,490 INFO org.apache.hadoop.yarn.server.resourcemanager.RMAuditLogger: USER=doopy	OPERATION=AM Released Container	TARGET=SchedulerApp	RESULT=SUCCESS	APPID=application_1421286406893_0001	CONTAINERID=container_1421286406893_0001_01_000028
2015-01-14 19:59:49,490 INFO org.apache.hadoop.yarn.server.resourcemanager.scheduler.SchedulerNode: Released container container_1421286406893_0001_01_000028 of capacity <memory:1024, vCores:1> on host barbie:45258, which currently has 2 containers, <memory:3072, vCores:2> used and <memory:5120, vCores:6> available, release resources=true
2015-01-14 19:59:49,490 INFO org.apache.hadoop.yarn.server.resourcemanager.scheduler.capacity.LeafQueue: default used=<memory:3072, vCores:2> numContainers=2 user=doopy user-resources=<memory:3072, vCores:2>
2015-01-14 19:59:49,500 INFO org.apache.hadoop.yarn.server.resourcemanager.scheduler.capacity.LeafQueue: completedContainer container=Container: [ContainerId: container_1421286406893_0001_01_000028, NodeId: barbie:45258, NodeHttpAddress: barbie:8042, Resource: <memory:1024, vCores:1>, Priority: 20, Token: Token { kind: ContainerToken, service: 127.0.1.1:45258 }, ] queue=default: capacity=1.0, absoluteCapacity=1.0, usedResources=<memory:3072, vCores:2>, usedCapacity=0.375, absoluteUsedCapacity=0.375, numApps=1, numContainers=2 cluster=<memory:8192, vCores:8>
2015-01-14 19:59:49,510 INFO org.apache.hadoop.yarn.server.resourcemanager.scheduler.capacity.ParentQueue: completedContainer queue=root usedCapacity=0.375 absoluteUsedCapacity=0.375 used=<memory:3072, vCores:2> cluster=<memory:8192, vCores:8>
2015-01-14 19:59:49,510 INFO org.apache.hadoop.yarn.server.resourcemanager.scheduler.capacity.ParentQueue: Re-sorting completed queue: root.default stats: default: capacity=1.0, absoluteCapacity=1.0, usedResources=<memory:3072, vCores:2>, usedCapacity=0.375, absoluteUsedCapacity=0.375, numApps=1, numContainers=2
2015-01-14 19:59:49,510 INFO org.apache.hadoop.yarn.server.resourcemanager.scheduler.capacity.CapacityScheduler: Application attempt appattempt_1421286406893_0001_000001 released container container_1421286406893_0001_01_000028 on node: host: barbie:45258 #containers=2 available=5120 used=3072 with event: FINISHED
2015-01-14 19:59:49,547 INFO org.apache.hadoop.yarn.server.resourcemanager.rmcontainer.RMContainerImpl: container_1421286406893_0001_01_000029 Container Transitioned from NEW to ALLOCATED
2015-01-14 19:59:49,547 INFO org.apache.hadoop.yarn.server.resourcemanager.RMAuditLogger: USER=doopy	OPERATION=AM Allocated Container	TARGET=SchedulerApp	RESULT=SUCCESS	APPID=application_1421286406893_0001	CONTAINERID=container_1421286406893_0001_01_000029
2015-01-14 19:59:49,547 INFO org.apache.hadoop.yarn.server.resourcemanager.scheduler.SchedulerNode: Assigned container container_1421286406893_0001_01_000029 of capacity <memory:1024, vCores:1> on host barbie:45258, which has 3 containers, <memory:4096, vCores:3> used and <memory:4096, vCores:5> available after allocation
2015-01-14 19:59:49,547 INFO org.apache.hadoop.yarn.server.resourcemanager.scheduler.capacity.LeafQueue: assignedContainer application attempt=appattempt_1421286406893_0001_000001 container=Container: [ContainerId: container_1421286406893_0001_01_000029, NodeId: barbie:45258, NodeHttpAddress: barbie:8042, Resource: <memory:1024, vCores:1>, Priority: 20, Token: null, ] queue=default: capacity=1.0, absoluteCapacity=1.0, usedResources=<memory:3072, vCores:2>, usedCapacity=0.375, absoluteUsedCapacity=0.375, numApps=1, numContainers=2 clusterResource=<memory:8192, vCores:8>
2015-01-14 19:59:49,548 INFO org.apache.hadoop.yarn.server.resourcemanager.scheduler.capacity.ParentQueue: Re-sorting assigned queue: root.default stats: default: capacity=1.0, absoluteCapacity=1.0, usedResources=<memory:4096, vCores:3>, usedCapacity=0.5, absoluteUsedCapacity=0.5, numApps=1, numContainers=3
2015-01-14 19:59:49,548 INFO org.apache.hadoop.yarn.server.resourcemanager.scheduler.capacity.ParentQueue: assignedContainer queue=root usedCapacity=0.5 absoluteUsedCapacity=0.5 used=<memory:4096, vCores:3> cluster=<memory:8192, vCores:8>
2015-01-14 19:59:49,575 INFO org.apache.hadoop.yarn.server.resourcemanager.rmcontainer.RMContainerImpl: container_1421286406893_0001_01_000030 Container Transitioned from NEW to ALLOCATED
2015-01-14 19:59:49,575 INFO org.apache.hadoop.yarn.server.resourcemanager.RMAuditLogger: USER=doopy	OPERATION=AM Allocated Container	TARGET=SchedulerApp	RESULT=SUCCESS	APPID=application_1421286406893_0001	CONTAINERID=container_1421286406893_0001_01_000030
2015-01-14 19:59:49,576 INFO org.apache.hadoop.yarn.server.resourcemanager.scheduler.SchedulerNode: Assigned container container_1421286406893_0001_01_000030 of capacity <memory:1024, vCores:1> on host barbie:45258, which has 4 containers, <memory:5120, vCores:4> used and <memory:3072, vCores:4> available after allocation
2015-01-14 19:59:49,583 INFO org.apache.hadoop.yarn.server.resourcemanager.scheduler.capacity.LeafQueue: assignedContainer application attempt=appattempt_1421286406893_0001_000001 container=Container: [ContainerId: container_1421286406893_0001_01_000030, NodeId: barbie:45258, NodeHttpAddress: barbie:8042, Resource: <memory:1024, vCores:1>, Priority: 20, Token: null, ] queue=default: capacity=1.0, absoluteCapacity=1.0, usedResources=<memory:4096, vCores:3>, usedCapacity=0.5, absoluteUsedCapacity=0.5, numApps=1, numContainers=3 clusterResource=<memory:8192, vCores:8>
2015-01-14 19:59:49,587 INFO org.apache.hadoop.yarn.server.resourcemanager.scheduler.capacity.ParentQueue: Re-sorting assigned queue: root.default stats: default: capacity=1.0, absoluteCapacity=1.0, usedResources=<memory:5120, vCores:4>, usedCapacity=0.625, absoluteUsedCapacity=0.625, numApps=1, numContainers=4
2015-01-14 19:59:49,587 INFO org.apache.hadoop.yarn.server.resourcemanager.scheduler.capacity.ParentQueue: assignedContainer queue=root usedCapacity=0.625 absoluteUsedCapacity=0.625 used=<memory:5120, vCores:4> cluster=<memory:8192, vCores:8>
2015-01-14 19:59:49,590 INFO org.apache.hadoop.yarn.server.resourcemanager.rmcontainer.RMContainerImpl: container_1421286406893_0001_01_000031 Container Transitioned from NEW to ALLOCATED
2015-01-14 19:59:49,590 INFO org.apache.hadoop.yarn.server.resourcemanager.RMAuditLogger: USER=doopy	OPERATION=AM Allocated Container	TARGET=SchedulerApp	RESULT=SUCCESS	APPID=application_1421286406893_0001	CONTAINERID=container_1421286406893_0001_01_000031
2015-01-14 19:59:49,590 INFO org.apache.hadoop.yarn.server.resourcemanager.scheduler.SchedulerNode: Assigned container container_1421286406893_0001_01_000031 of capacity <memory:1024, vCores:1> on host barbie:45258, which has 5 containers, <memory:6144, vCores:5> used and <memory:2048, vCores:3> available after allocation
2015-01-14 19:59:49,590 INFO org.apache.hadoop.yarn.server.resourcemanager.scheduler.capacity.LeafQueue: assignedContainer application attempt=appattempt_1421286406893_0001_000001 container=Container: [ContainerId: container_1421286406893_0001_01_000031, NodeId: barbie:45258, NodeHttpAddress: barbie:8042, Resource: <memory:1024, vCores:1>, Priority: 20, Token: null, ] queue=default: capacity=1.0, absoluteCapacity=1.0, usedResources=<memory:5120, vCores:4>, usedCapacity=0.625, absoluteUsedCapacity=0.625, numApps=1, numContainers=4 clusterResource=<memory:8192, vCores:8>
2015-01-14 19:59:49,591 INFO org.apache.hadoop.yarn.server.resourcemanager.scheduler.capacity.ParentQueue: Re-sorting assigned queue: root.default stats: default: capacity=1.0, absoluteCapacity=1.0, usedResources=<memory:6144, vCores:5>, usedCapacity=0.75, absoluteUsedCapacity=0.75, numApps=1, numContainers=5
2015-01-14 19:59:49,591 INFO org.apache.hadoop.yarn.server.resourcemanager.scheduler.capacity.ParentQueue: assignedContainer queue=root usedCapacity=0.75 absoluteUsedCapacity=0.75 used=<memory:6144, vCores:5> cluster=<memory:8192, vCores:8>
2015-01-14 19:59:50,158 INFO org.apache.hadoop.yarn.server.resourcemanager.scheduler.capacity.CapacityScheduler: Null container completed...
2015-01-14 19:59:50,158 INFO org.apache.hadoop.yarn.server.resourcemanager.scheduler.capacity.CapacityScheduler: Null container completed...
2015-01-14 19:59:50,158 INFO org.apache.hadoop.yarn.server.resourcemanager.scheduler.capacity.CapacityScheduler: Null container completed...
2015-01-14 19:59:50,158 INFO org.apache.hadoop.yarn.server.resourcemanager.scheduler.capacity.CapacityScheduler: Null container completed...
2015-01-14 19:59:50,158 INFO org.apache.hadoop.yarn.server.resourcemanager.scheduler.capacity.CapacityScheduler: Null container completed...
2015-01-14 19:59:50,695 INFO org.apache.hadoop.yarn.server.resourcemanager.rmcontainer.RMContainerImpl: container_1421286406893_0001_01_000029 Container Transitioned from ALLOCATED to ACQUIRED
2015-01-14 19:59:50,698 INFO org.apache.hadoop.yarn.server.resourcemanager.rmcontainer.RMContainerImpl: container_1421286406893_0001_01_000030 Container Transitioned from ALLOCATED to ACQUIRED
2015-01-14 19:59:50,712 INFO org.apache.hadoop.yarn.server.resourcemanager.rmcontainer.RMContainerImpl: container_1421286406893_0001_01_000031 Container Transitioned from ALLOCATED to ACQUIRED
2015-01-14 19:59:51,395 INFO org.apache.hadoop.yarn.server.resourcemanager.rmcontainer.RMContainerImpl: container_1421286406893_0001_01_000029 Container Transitioned from ACQUIRED to RUNNING
2015-01-14 19:59:51,396 INFO org.apache.hadoop.yarn.server.resourcemanager.rmcontainer.RMContainerImpl: container_1421286406893_0001_01_000030 Container Transitioned from ACQUIRED to RUNNING
2015-01-14 19:59:51,396 INFO org.apache.hadoop.yarn.server.resourcemanager.rmcontainer.RMContainerImpl: container_1421286406893_0001_01_000031 Container Transitioned from ACQUIRED to RUNNING
2015-01-14 19:59:51,396 INFO org.apache.hadoop.yarn.server.resourcemanager.scheduler.capacity.CapacityScheduler: Null container completed...
2015-01-14 19:59:51,396 INFO org.apache.hadoop.yarn.server.resourcemanager.scheduler.capacity.CapacityScheduler: Null container completed...
2015-01-14 19:59:51,396 INFO org.apache.hadoop.yarn.server.resourcemanager.scheduler.capacity.CapacityScheduler: Null container completed...
2015-01-14 19:59:51,396 INFO org.apache.hadoop.yarn.server.resourcemanager.scheduler.capacity.CapacityScheduler: Null container completed...
2015-01-14 19:59:51,396 INFO org.apache.hadoop.yarn.server.resourcemanager.scheduler.capacity.CapacityScheduler: Null container completed...
2015-01-14 19:59:51,790 INFO org.apache.hadoop.yarn.server.resourcemanager.scheduler.AppSchedulingInfo: checking for deactivate... 
2015-01-14 19:59:52,568 INFO org.apache.hadoop.yarn.server.resourcemanager.scheduler.capacity.CapacityScheduler: Null container completed...
2015-01-14 19:59:52,568 INFO org.apache.hadoop.yarn.server.resourcemanager.scheduler.capacity.CapacityScheduler: Null container completed...
2015-01-14 20:00:03,514 INFO org.apache.hadoop.yarn.server.resourcemanager.rmcontainer.RMContainerImpl: container_1421286406893_0001_01_000032 Container Transitioned from NEW to ALLOCATED
2015-01-14 20:00:03,514 INFO org.apache.hadoop.yarn.server.resourcemanager.RMAuditLogger: USER=doopy	OPERATION=AM Allocated Container	TARGET=SchedulerApp	RESULT=SUCCESS	APPID=application_1421286406893_0001	CONTAINERID=container_1421286406893_0001_01_000032
2015-01-14 20:00:03,514 INFO org.apache.hadoop.yarn.server.resourcemanager.scheduler.SchedulerNode: Assigned container container_1421286406893_0001_01_000032 of capacity <memory:1024, vCores:1> on host barbie:45258, which has 6 containers, <memory:7168, vCores:6> used and <memory:1024, vCores:2> available after allocation
2015-01-14 20:00:03,515 INFO org.apache.hadoop.yarn.server.resourcemanager.scheduler.capacity.LeafQueue: assignedContainer application attempt=appattempt_1421286406893_0001_000001 container=Container: [ContainerId: container_1421286406893_0001_01_000032, NodeId: barbie:45258, NodeHttpAddress: barbie:8042, Resource: <memory:1024, vCores:1>, Priority: 20, Token: null, ] queue=default: capacity=1.0, absoluteCapacity=1.0, usedResources=<memory:6144, vCores:5>, usedCapacity=0.75, absoluteUsedCapacity=0.75, numApps=1, numContainers=5 clusterResource=<memory:8192, vCores:8>
2015-01-14 20:00:03,515 INFO org.apache.hadoop.yarn.server.resourcemanager.scheduler.capacity.ParentQueue: Re-sorting assigned queue: root.default stats: default: capacity=1.0, absoluteCapacity=1.0, usedResources=<memory:7168, vCores:6>, usedCapacity=0.875, absoluteUsedCapacity=0.875, numApps=1, numContainers=6
2015-01-14 20:00:03,515 INFO org.apache.hadoop.yarn.server.resourcemanager.scheduler.capacity.ParentQueue: assignedContainer queue=root usedCapacity=0.875 absoluteUsedCapacity=0.875 used=<memory:7168, vCores:6> cluster=<memory:8192, vCores:8>
2015-01-14 20:00:04,534 INFO org.apache.hadoop.yarn.server.resourcemanager.rmcontainer.RMContainerImpl: container_1421286406893_0001_01_000032 Container Transitioned from ALLOCATED to ACQUIRED
2015-01-14 20:00:05,537 INFO org.apache.hadoop.yarn.server.resourcemanager.rmcontainer.RMContainerImpl: container_1421286406893_0001_01_000032 Container Transitioned from ACQUIRED to RUNNING
2015-01-14 20:00:05,709 INFO org.apache.hadoop.yarn.server.resourcemanager.scheduler.AppSchedulingInfo: checking for deactivate... 
2015-01-14 20:00:18,632 INFO org.apache.hadoop.yarn.server.resourcemanager.rmcontainer.RMContainerImpl: container_1421286406893_0001_01_000033 Container Transitioned from NEW to ALLOCATED
2015-01-14 20:00:18,633 INFO org.apache.hadoop.yarn.server.resourcemanager.RMAuditLogger: USER=doopy	OPERATION=AM Allocated Container	TARGET=SchedulerApp	RESULT=SUCCESS	APPID=application_1421286406893_0001	CONTAINERID=container_1421286406893_0001_01_000033
2015-01-14 20:00:18,633 INFO org.apache.hadoop.yarn.server.resourcemanager.scheduler.SchedulerNode: Assigned container container_1421286406893_0001_01_000033 of capacity <memory:1024, vCores:1> on host barbie:45258, which has 7 containers, <memory:8192, vCores:7> used and <memory:0, vCores:1> available after allocation
2015-01-14 20:00:18,633 INFO org.apache.hadoop.yarn.server.resourcemanager.scheduler.capacity.LeafQueue: assignedContainer application attempt=appattempt_1421286406893_0001_000001 container=Container: [ContainerId: container_1421286406893_0001_01_000033, NodeId: barbie:45258, NodeHttpAddress: barbie:8042, Resource: <memory:1024, vCores:1>, Priority: 20, Token: null, ] queue=default: capacity=1.0, absoluteCapacity=1.0, usedResources=<memory:7168, vCores:6>, usedCapacity=0.875, absoluteUsedCapacity=0.875, numApps=1, numContainers=6 clusterResource=<memory:8192, vCores:8>
2015-01-14 20:00:18,643 INFO org.apache.hadoop.yarn.server.resourcemanager.scheduler.capacity.ParentQueue: Re-sorting assigned queue: root.default stats: default: capacity=1.0, absoluteCapacity=1.0, usedResources=<memory:8192, vCores:7>, usedCapacity=1.0, absoluteUsedCapacity=1.0, numApps=1, numContainers=7
2015-01-14 20:00:18,651 INFO org.apache.hadoop.yarn.server.resourcemanager.scheduler.capacity.ParentQueue: assignedContainer queue=root usedCapacity=1.0 absoluteUsedCapacity=1.0 used=<memory:8192, vCores:7> cluster=<memory:8192, vCores:8>
2015-01-14 20:00:19,212 INFO org.apache.hadoop.yarn.server.resourcemanager.rmcontainer.RMContainerImpl: container_1421286406893_0001_01_000033 Container Transitioned from ALLOCATED to ACQUIRED
2015-01-14 20:00:20,290 INFO org.apache.hadoop.yarn.server.resourcemanager.scheduler.AppSchedulingInfo: checking for deactivate... 
2015-01-14 20:00:20,851 INFO org.apache.hadoop.yarn.server.resourcemanager.rmcontainer.RMContainerImpl: container_1421286406893_0001_01_000033 Container Transitioned from ACQUIRED to RUNNING
2015-01-14 20:01:41,833 INFO SecurityLogger.org.apache.hadoop.ipc.Server: Auth successful for appattempt_1421286406893_0001_000001 (auth:SIMPLE)
2015-01-14 20:02:33,522 INFO org.apache.hadoop.yarn.server.resourcemanager.scheduler.AppSchedulingInfo: checking for deactivate... 
2015-01-14 20:02:41,771 INFO org.apache.hadoop.yarn.server.resourcemanager.rmcontainer.RMContainerImpl: container_1421286406893_0001_01_000029 Container Transitioned from RUNNING to COMPLETED
2015-01-14 20:02:41,771 INFO org.apache.hadoop.yarn.server.resourcemanager.scheduler.common.fica.FiCaSchedulerApp: Completed container: container_1421286406893_0001_01_000029 in state: COMPLETED event:FINISHED
2015-01-14 20:02:41,816 INFO org.apache.hadoop.yarn.server.resourcemanager.RMAuditLogger: USER=doopy	OPERATION=AM Released Container	TARGET=SchedulerApp	RESULT=SUCCESS	APPID=application_1421286406893_0001	CONTAINERID=container_1421286406893_0001_01_000029
2015-01-14 20:02:41,817 INFO org.apache.hadoop.yarn.server.resourcemanager.scheduler.SchedulerNode: Released container container_1421286406893_0001_01_000029 of capacity <memory:1024, vCores:1> on host barbie:45258, which currently has 6 containers, <memory:7168, vCores:6> used and <memory:1024, vCores:2> available, release resources=true
2015-01-14 20:02:41,817 INFO org.apache.hadoop.yarn.server.resourcemanager.scheduler.capacity.LeafQueue: default used=<memory:7168, vCores:6> numContainers=6 user=doopy user-resources=<memory:7168, vCores:6>
2015-01-14 20:02:41,947 INFO org.apache.hadoop.yarn.server.resourcemanager.scheduler.capacity.LeafQueue: completedContainer container=Container: [ContainerId: container_1421286406893_0001_01_000029, NodeId: barbie:45258, NodeHttpAddress: barbie:8042, Resource: <memory:1024, vCores:1>, Priority: 20, Token: Token { kind: ContainerToken, service: 127.0.1.1:45258 }, ] queue=default: capacity=1.0, absoluteCapacity=1.0, usedResources=<memory:7168, vCores:6>, usedCapacity=0.875, absoluteUsedCapacity=0.875, numApps=1, numContainers=6 cluster=<memory:8192, vCores:8>
2015-01-14 20:02:41,988 INFO org.apache.hadoop.yarn.server.resourcemanager.scheduler.capacity.ParentQueue: completedContainer queue=root usedCapacity=0.875 absoluteUsedCapacity=0.875 used=<memory:7168, vCores:6> cluster=<memory:8192, vCores:8>
2015-01-14 20:02:42,009 INFO org.apache.hadoop.yarn.server.resourcemanager.scheduler.capacity.ParentQueue: Re-sorting completed queue: root.default stats: default: capacity=1.0, absoluteCapacity=1.0, usedResources=<memory:7168, vCores:6>, usedCapacity=0.875, absoluteUsedCapacity=0.875, numApps=1, numContainers=6
2015-01-14 20:02:42,029 INFO org.apache.hadoop.yarn.server.resourcemanager.scheduler.capacity.CapacityScheduler: Application attempt appattempt_1421286406893_0001_000001 released container container_1421286406893_0001_01_000029 on node: host: barbie:45258 #containers=6 available=1024 used=7168 with event: FINISHED
2015-01-14 20:02:42,030 INFO org.apache.hadoop.yarn.server.resourcemanager.rmcontainer.RMContainerImpl: container_1421286406893_0001_01_000030 Container Transitioned from RUNNING to COMPLETED
2015-01-14 20:02:42,046 INFO org.apache.hadoop.yarn.server.resourcemanager.scheduler.common.fica.FiCaSchedulerApp: Completed container: container_1421286406893_0001_01_000030 in state: COMPLETED event:FINISHED
2015-01-14 20:02:42,046 INFO org.apache.hadoop.yarn.server.resourcemanager.RMAuditLogger: USER=doopy	OPERATION=AM Released Container	TARGET=SchedulerApp	RESULT=SUCCESS	APPID=application_1421286406893_0001	CONTAINERID=container_1421286406893_0001_01_000030
2015-01-14 20:02:42,046 INFO org.apache.hadoop.yarn.server.resourcemanager.scheduler.SchedulerNode: Released container container_1421286406893_0001_01_000030 of capacity <memory:1024, vCores:1> on host barbie:45258, which currently has 5 containers, <memory:6144, vCores:5> used and <memory:2048, vCores:3> available, release resources=true
2015-01-14 20:02:42,076 INFO org.apache.hadoop.yarn.server.resourcemanager.scheduler.capacity.LeafQueue: default used=<memory:6144, vCores:5> numContainers=5 user=doopy user-resources=<memory:6144, vCores:5>
2015-01-14 20:02:42,137 INFO org.apache.hadoop.yarn.server.resourcemanager.scheduler.capacity.LeafQueue: completedContainer container=Container: [ContainerId: container_1421286406893_0001_01_000030, NodeId: barbie:45258, NodeHttpAddress: barbie:8042, Resource: <memory:1024, vCores:1>, Priority: 20, Token: Token { kind: ContainerToken, service: 127.0.1.1:45258 }, ] queue=default: capacity=1.0, absoluteCapacity=1.0, usedResources=<memory:6144, vCores:5>, usedCapacity=0.75, absoluteUsedCapacity=0.75, numApps=1, numContainers=5 cluster=<memory:8192, vCores:8>
2015-01-14 20:02:42,137 INFO org.apache.hadoop.yarn.server.resourcemanager.scheduler.capacity.ParentQueue: completedContainer queue=root usedCapacity=0.75 absoluteUsedCapacity=0.75 used=<memory:6144, vCores:5> cluster=<memory:8192, vCores:8>
2015-01-14 20:02:42,137 INFO org.apache.hadoop.yarn.server.resourcemanager.scheduler.capacity.ParentQueue: Re-sorting completed queue: root.default stats: default: capacity=1.0, absoluteCapacity=1.0, usedResources=<memory:6144, vCores:5>, usedCapacity=0.75, absoluteUsedCapacity=0.75, numApps=1, numContainers=5
2015-01-14 20:02:42,162 INFO org.apache.hadoop.yarn.server.resourcemanager.scheduler.capacity.CapacityScheduler: Application attempt appattempt_1421286406893_0001_000001 released container container_1421286406893_0001_01_000030 on node: host: barbie:45258 #containers=5 available=2048 used=6144 with event: FINISHED
2015-01-14 20:02:42,162 INFO org.apache.hadoop.yarn.server.resourcemanager.rmcontainer.RMContainerImpl: container_1421286406893_0001_01_000031 Container Transitioned from RUNNING to COMPLETED
2015-01-14 20:02:42,162 INFO org.apache.hadoop.yarn.server.resourcemanager.scheduler.common.fica.FiCaSchedulerApp: Completed container: container_1421286406893_0001_01_000031 in state: COMPLETED event:FINISHED
2015-01-14 20:02:42,162 INFO org.apache.hadoop.yarn.server.resourcemanager.RMAuditLogger: USER=doopy	OPERATION=AM Released Container	TARGET=SchedulerApp	RESULT=SUCCESS	APPID=application_1421286406893_0001	CONTAINERID=container_1421286406893_0001_01_000031
2015-01-14 20:02:42,162 INFO org.apache.hadoop.yarn.server.resourcemanager.scheduler.SchedulerNode: Released container container_1421286406893_0001_01_000031 of capacity <memory:1024, vCores:1> on host barbie:45258, which currently has 4 containers, <memory:5120, vCores:4> used and <memory:3072, vCores:4> available, release resources=true
2015-01-14 20:02:42,162 INFO org.apache.hadoop.yarn.server.resourcemanager.scheduler.capacity.LeafQueue: default used=<memory:5120, vCores:4> numContainers=4 user=doopy user-resources=<memory:5120, vCores:4>
2015-01-14 20:02:42,163 INFO org.apache.hadoop.yarn.server.resourcemanager.scheduler.capacity.LeafQueue: completedContainer container=Container: [ContainerId: container_1421286406893_0001_01_000031, NodeId: barbie:45258, NodeHttpAddress: barbie:8042, Resource: <memory:1024, vCores:1>, Priority: 20, Token: Token { kind: ContainerToken, service: 127.0.1.1:45258 }, ] queue=default: capacity=1.0, absoluteCapacity=1.0, usedResources=<memory:5120, vCores:4>, usedCapacity=0.625, absoluteUsedCapacity=0.625, numApps=1, numContainers=4 cluster=<memory:8192, vCores:8>
2015-01-14 20:02:42,183 INFO org.apache.hadoop.yarn.server.resourcemanager.scheduler.capacity.ParentQueue: completedContainer queue=root usedCapacity=0.625 absoluteUsedCapacity=0.625 used=<memory:5120, vCores:4> cluster=<memory:8192, vCores:8>
2015-01-14 20:02:42,183 INFO org.apache.hadoop.yarn.server.resourcemanager.scheduler.capacity.ParentQueue: Re-sorting completed queue: root.default stats: default: capacity=1.0, absoluteCapacity=1.0, usedResources=<memory:5120, vCores:4>, usedCapacity=0.625, absoluteUsedCapacity=0.625, numApps=1, numContainers=4
2015-01-14 20:02:42,183 INFO org.apache.hadoop.yarn.server.resourcemanager.scheduler.capacity.CapacityScheduler: Application attempt appattempt_1421286406893_0001_000001 released container container_1421286406893_0001_01_000031 on node: host: barbie:45258 #containers=4 available=3072 used=5120 with event: FINISHED
2015-01-14 20:02:42,183 INFO org.apache.hadoop.yarn.server.resourcemanager.rmcontainer.RMContainerImpl: container_1421286406893_0001_01_000032 Container Transitioned from RUNNING to COMPLETED
2015-01-14 20:02:42,183 INFO org.apache.hadoop.yarn.server.resourcemanager.scheduler.common.fica.FiCaSchedulerApp: Completed container: container_1421286406893_0001_01_000032 in state: COMPLETED event:FINISHED
2015-01-14 20:02:42,184 INFO org.apache.hadoop.yarn.server.resourcemanager.RMAuditLogger: USER=doopy	OPERATION=AM Released Container	TARGET=SchedulerApp	RESULT=SUCCESS	APPID=application_1421286406893_0001	CONTAINERID=container_1421286406893_0001_01_000032
2015-01-14 20:02:42,214 INFO org.apache.hadoop.yarn.server.resourcemanager.scheduler.SchedulerNode: Released container container_1421286406893_0001_01_000032 of capacity <memory:1024, vCores:1> on host barbie:45258, which currently has 3 containers, <memory:4096, vCores:3> used and <memory:4096, vCores:5> available, release resources=true
2015-01-14 20:02:42,214 INFO org.apache.hadoop.yarn.server.resourcemanager.scheduler.capacity.LeafQueue: default used=<memory:4096, vCores:3> numContainers=3 user=doopy user-resources=<memory:4096, vCores:3>
2015-01-14 20:02:42,239 INFO org.apache.hadoop.yarn.server.resourcemanager.scheduler.capacity.LeafQueue: completedContainer container=Container: [ContainerId: container_1421286406893_0001_01_000032, NodeId: barbie:45258, NodeHttpAddress: barbie:8042, Resource: <memory:1024, vCores:1>, Priority: 20, Token: Token { kind: ContainerToken, service: 127.0.1.1:45258 }, ] queue=default: capacity=1.0, absoluteCapacity=1.0, usedResources=<memory:4096, vCores:3>, usedCapacity=0.5, absoluteUsedCapacity=0.5, numApps=1, numContainers=3 cluster=<memory:8192, vCores:8>
2015-01-14 20:02:42,240 INFO org.apache.hadoop.yarn.server.resourcemanager.scheduler.capacity.ParentQueue: completedContainer queue=root usedCapacity=0.5 absoluteUsedCapacity=0.5 used=<memory:4096, vCores:3> cluster=<memory:8192, vCores:8>
2015-01-14 20:02:42,240 INFO org.apache.hadoop.yarn.server.resourcemanager.scheduler.capacity.ParentQueue: Re-sorting completed queue: root.default stats: default: capacity=1.0, absoluteCapacity=1.0, usedResources=<memory:4096, vCores:3>, usedCapacity=0.5, absoluteUsedCapacity=0.5, numApps=1, numContainers=3
2015-01-14 20:02:42,240 INFO org.apache.hadoop.yarn.server.resourcemanager.scheduler.capacity.CapacityScheduler: Application attempt appattempt_1421286406893_0001_000001 released container container_1421286406893_0001_01_000032 on node: host: barbie:45258 #containers=3 available=4096 used=4096 with event: FINISHED
2015-01-14 20:02:42,240 INFO org.apache.hadoop.yarn.server.resourcemanager.rmcontainer.RMContainerImpl: container_1421286406893_0001_01_000033 Container Transitioned from RUNNING to COMPLETED
2015-01-14 20:02:42,240 INFO org.apache.hadoop.yarn.server.resourcemanager.scheduler.common.fica.FiCaSchedulerApp: Completed container: container_1421286406893_0001_01_000033 in state: COMPLETED event:FINISHED
2015-01-14 20:02:42,240 INFO org.apache.hadoop.yarn.server.resourcemanager.RMAuditLogger: USER=doopy	OPERATION=AM Released Container	TARGET=SchedulerApp	RESULT=SUCCESS	APPID=application_1421286406893_0001	CONTAINERID=container_1421286406893_0001_01_000033
2015-01-14 20:02:42,241 INFO org.apache.hadoop.yarn.server.resourcemanager.scheduler.SchedulerNode: Released container container_1421286406893_0001_01_000033 of capacity <memory:1024, vCores:1> on host barbie:45258, which currently has 2 containers, <memory:3072, vCores:2> used and <memory:5120, vCores:6> available, release resources=true
2015-01-14 20:02:42,241 INFO org.apache.hadoop.yarn.server.resourcemanager.scheduler.capacity.LeafQueue: default used=<memory:3072, vCores:2> numContainers=2 user=doopy user-resources=<memory:3072, vCores:2>
2015-01-14 20:02:42,286 INFO org.apache.hadoop.yarn.server.resourcemanager.scheduler.capacity.LeafQueue: completedContainer container=Container: [ContainerId: container_1421286406893_0001_01_000033, NodeId: barbie:45258, NodeHttpAddress: barbie:8042, Resource: <memory:1024, vCores:1>, Priority: 20, Token: Token { kind: ContainerToken, service: 127.0.1.1:45258 }, ] queue=default: capacity=1.0, absoluteCapacity=1.0, usedResources=<memory:3072, vCores:2>, usedCapacity=0.375, absoluteUsedCapacity=0.375, numApps=1, numContainers=2 cluster=<memory:8192, vCores:8>
2015-01-14 20:02:42,286 INFO org.apache.hadoop.yarn.server.resourcemanager.scheduler.capacity.ParentQueue: completedContainer queue=root usedCapacity=0.375 absoluteUsedCapacity=0.375 used=<memory:3072, vCores:2> cluster=<memory:8192, vCores:8>
2015-01-14 20:02:42,286 INFO org.apache.hadoop.yarn.server.resourcemanager.scheduler.capacity.ParentQueue: Re-sorting completed queue: root.default stats: default: capacity=1.0, absoluteCapacity=1.0, usedResources=<memory:3072, vCores:2>, usedCapacity=0.375, absoluteUsedCapacity=0.375, numApps=1, numContainers=2
2015-01-14 20:02:42,286 INFO org.apache.hadoop.yarn.server.resourcemanager.scheduler.capacity.CapacityScheduler: Application attempt appattempt_1421286406893_0001_000001 released container container_1421286406893_0001_01_000033 on node: host: barbie:45258 #containers=2 available=5120 used=3072 with event: FINISHED
2015-01-14 20:02:42,664 INFO org.apache.hadoop.yarn.server.resourcemanager.scheduler.capacity.CapacityScheduler: Null container completed...
2015-01-14 20:02:42,664 INFO org.apache.hadoop.yarn.server.resourcemanager.scheduler.capacity.CapacityScheduler: Null container completed...
2015-01-14 20:02:42,664 INFO org.apache.hadoop.yarn.server.resourcemanager.scheduler.capacity.CapacityScheduler: Null container completed...
2015-01-14 20:02:42,664 INFO org.apache.hadoop.yarn.server.resourcemanager.scheduler.capacity.CapacityScheduler: Null container completed...
2015-01-14 20:02:42,664 INFO org.apache.hadoop.yarn.server.resourcemanager.scheduler.capacity.CapacityScheduler: Null container completed...
2015-01-14 20:02:43,682 INFO org.apache.hadoop.yarn.server.resourcemanager.scheduler.capacity.CapacityScheduler: Null container completed...
2015-01-14 20:02:43,682 INFO org.apache.hadoop.yarn.server.resourcemanager.scheduler.capacity.CapacityScheduler: Null container completed...
2015-01-14 20:02:43,682 INFO org.apache.hadoop.yarn.server.resourcemanager.scheduler.capacity.CapacityScheduler: Null container completed...
2015-01-14 20:02:43,682 INFO org.apache.hadoop.yarn.server.resourcemanager.scheduler.capacity.CapacityScheduler: Null container completed...
2015-01-14 20:02:43,682 INFO org.apache.hadoop.yarn.server.resourcemanager.scheduler.capacity.CapacityScheduler: Null container completed...
2015-01-14 20:02:44,695 INFO org.apache.hadoop.yarn.server.resourcemanager.scheduler.capacity.CapacityScheduler: Null container completed...
2015-01-14 20:02:44,695 INFO org.apache.hadoop.yarn.server.resourcemanager.scheduler.capacity.CapacityScheduler: Null container completed...
2015-01-14 20:02:44,695 INFO org.apache.hadoop.yarn.server.resourcemanager.scheduler.capacity.CapacityScheduler: Null container completed...
2015-01-14 20:02:51,669 INFO org.apache.hadoop.yarn.server.resourcemanager.rmcontainer.RMContainerImpl: container_1421286406893_0001_01_000008 Container Transitioned from RUNNING to COMPLETED
2015-01-14 20:02:51,669 INFO org.apache.hadoop.yarn.server.resourcemanager.scheduler.common.fica.FiCaSchedulerApp: Completed container: container_1421286406893_0001_01_000008 in state: COMPLETED event:FINISHED
2015-01-14 20:02:51,669 INFO org.apache.hadoop.yarn.server.resourcemanager.RMAuditLogger: USER=doopy	OPERATION=AM Released Container	TARGET=SchedulerApp	RESULT=SUCCESS	APPID=application_1421286406893_0001	CONTAINERID=container_1421286406893_0001_01_000008
2015-01-14 20:02:51,669 INFO org.apache.hadoop.yarn.server.resourcemanager.scheduler.SchedulerNode: Released container container_1421286406893_0001_01_000008 of capacity <memory:1024, vCores:1> on host barbie:45258, which currently has 1 containers, <memory:2048, vCores:1> used and <memory:6144, vCores:7> available, release resources=true
2015-01-14 20:02:51,670 INFO org.apache.hadoop.yarn.server.resourcemanager.scheduler.capacity.LeafQueue: default used=<memory:2048, vCores:1> numContainers=1 user=doopy user-resources=<memory:2048, vCores:1>
2015-01-14 20:02:51,670 INFO org.apache.hadoop.yarn.server.resourcemanager.scheduler.capacity.LeafQueue: completedContainer container=Container: [ContainerId: container_1421286406893_0001_01_000008, NodeId: barbie:45258, NodeHttpAddress: barbie:8042, Resource: <memory:1024, vCores:1>, Priority: 10, Token: Token { kind: ContainerToken, service: 127.0.1.1:45258 }, ] queue=default: capacity=1.0, absoluteCapacity=1.0, usedResources=<memory:2048, vCores:1>, usedCapacity=0.25, absoluteUsedCapacity=0.25, numApps=1, numContainers=1 cluster=<memory:8192, vCores:8>
2015-01-14 20:02:51,706 INFO org.apache.hadoop.yarn.server.resourcemanager.scheduler.capacity.ParentQueue: completedContainer queue=root usedCapacity=0.25 absoluteUsedCapacity=0.25 used=<memory:2048, vCores:1> cluster=<memory:8192, vCores:8>
2015-01-14 20:02:51,706 INFO org.apache.hadoop.yarn.server.resourcemanager.scheduler.capacity.ParentQueue: Re-sorting completed queue: root.default stats: default: capacity=1.0, absoluteCapacity=1.0, usedResources=<memory:2048, vCores:1>, usedCapacity=0.25, absoluteUsedCapacity=0.25, numApps=1, numContainers=1
2015-01-14 20:02:51,706 INFO org.apache.hadoop.yarn.server.resourcemanager.scheduler.capacity.CapacityScheduler: Application attempt appattempt_1421286406893_0001_000001 released container container_1421286406893_0001_01_000008 on node: host: barbie:45258 #containers=1 available=6144 used=2048 with event: FINISHED
2015-01-14 20:02:52,674 INFO org.apache.hadoop.yarn.server.resourcemanager.scheduler.capacity.CapacityScheduler: Null container completed...
2015-01-14 20:02:57,318 INFO org.apache.hadoop.yarn.server.resourcemanager.scheduler.capacity.CapacityScheduler: Null container completed...
2015-01-14 20:02:57,478 INFO org.apache.hadoop.yarn.server.resourcemanager.rmapp.attempt.RMAppAttemptImpl: Updating application attempt appattempt_1421286406893_0001_000001 with final state: FINISHING, and exit status: -1000
2015-01-14 20:02:57,488 INFO org.apache.hadoop.yarn.server.resourcemanager.rmapp.attempt.RMAppAttemptImpl: appattempt_1421286406893_0001_000001 State change from RUNNING to FINAL_SAVING
2015-01-14 20:02:57,488 INFO org.apache.hadoop.yarn.server.resourcemanager.rmapp.RMAppImpl: Updating application application_1421286406893_0001 with final state: FINISHING
2015-01-14 20:02:57,527 INFO org.apache.hadoop.yarn.server.resourcemanager.recovery.RMStateStore: Updating info for app: application_1421286406893_0001
2015-01-14 20:02:57,527 INFO org.apache.hadoop.yarn.server.resourcemanager.rmapp.RMAppImpl: application_1421286406893_0001 State change from RUNNING to FINAL_SAVING
2015-01-14 20:02:57,549 INFO org.apache.hadoop.yarn.server.resourcemanager.rmapp.attempt.RMAppAttemptImpl: appattempt_1421286406893_0001_000001 State change from FINAL_SAVING to FINISHING
2015-01-14 20:02:57,550 INFO org.apache.hadoop.yarn.server.resourcemanager.rmapp.RMAppImpl: application_1421286406893_0001 State change from FINAL_SAVING to FINISHING
2015-01-14 20:02:58,321 INFO org.apache.hadoop.yarn.server.resourcemanager.scheduler.capacity.CapacityScheduler: Null container completed...
2015-01-14 20:02:58,620 INFO org.apache.hadoop.yarn.server.resourcemanager.ApplicationMasterService: application_1421286406893_0001 unregistered successfully. 
2015-01-14 20:02:59,325 INFO org.apache.hadoop.yarn.server.resourcemanager.scheduler.capacity.CapacityScheduler: Null container completed...
2015-01-14 20:03:00,327 INFO org.apache.hadoop.yarn.server.resourcemanager.scheduler.capacity.CapacityScheduler: Null container completed...
2015-01-14 20:03:01,330 INFO org.apache.hadoop.yarn.server.resourcemanager.scheduler.capacity.CapacityScheduler: Null container completed...
2015-01-14 20:03:02,333 INFO org.apache.hadoop.yarn.server.resourcemanager.scheduler.capacity.CapacityScheduler: Null container completed...
2015-01-14 20:03:03,336 INFO org.apache.hadoop.yarn.server.resourcemanager.scheduler.capacity.CapacityScheduler: Null container completed...
2015-01-14 20:03:04,338 INFO org.apache.hadoop.yarn.server.resourcemanager.scheduler.capacity.CapacityScheduler: Null container completed...
2015-01-14 20:03:05,341 INFO org.apache.hadoop.yarn.server.resourcemanager.scheduler.capacity.CapacityScheduler: Null container completed...
2015-01-14 20:03:05,439 INFO org.apache.hadoop.yarn.server.resourcemanager.ClientRMService: Allocated new applicationId: 2
2015-01-14 20:03:06,344 INFO org.apache.hadoop.yarn.server.resourcemanager.scheduler.capacity.CapacityScheduler: Null container completed...
2015-01-14 20:03:06,734 INFO org.apache.hadoop.yarn.server.resourcemanager.rmapp.RMAppImpl: Storing application with id application_1421286406893_0002
2015-01-14 20:03:06,735 INFO org.apache.hadoop.yarn.server.resourcemanager.rmapp.RMAppImpl: application_1421286406893_0002 State change from NEW to NEW_SAVING
2015-01-14 20:03:06,735 INFO org.apache.hadoop.yarn.server.resourcemanager.recovery.RMStateStore: Storing info for app: application_1421286406893_0002
2015-01-14 20:03:06,735 INFO org.apache.hadoop.yarn.server.resourcemanager.rmapp.RMAppImpl: application_1421286406893_0002 State change from NEW_SAVING to SUBMITTED
2015-01-14 20:03:06,735 INFO org.apache.hadoop.yarn.server.resourcemanager.scheduler.capacity.ParentQueue: Application added - appId: application_1421286406893_0002 user: doopy leaf-queue of parent: root #applications: 2
2015-01-14 20:03:06,735 INFO org.apache.hadoop.yarn.server.resourcemanager.scheduler.capacity.CapacityScheduler: Accepted application application_1421286406893_0002 from user: doopy, in queue: default
2015-01-14 20:03:06,736 INFO org.apache.hadoop.yarn.server.resourcemanager.rmapp.RMAppImpl: application_1421286406893_0002 State change from SUBMITTED to ACCEPTED
2015-01-14 20:03:06,736 INFO org.apache.hadoop.yarn.server.resourcemanager.ApplicationMasterService: Registering app attempt : appattempt_1421286406893_0002_000001
2015-01-14 20:03:06,736 INFO org.apache.hadoop.yarn.server.resourcemanager.rmapp.attempt.RMAppAttemptImpl: appattempt_1421286406893_0002_000001 State change from NEW to SUBMITTED
2015-01-14 20:03:06,736 INFO org.apache.hadoop.yarn.server.resourcemanager.ClientRMService: Application with id 2 submitted by user doopy
2015-01-14 20:03:06,736 INFO org.apache.hadoop.yarn.server.resourcemanager.RMAuditLogger: USER=doopy	IP=127.0.0.1	OPERATION=Submit Application Request	TARGET=ClientRMService	RESULT=SUCCESS	APPID=application_1421286406893_0002
2015-01-14 20:03:06,738 INFO org.apache.hadoop.yarn.server.resourcemanager.scheduler.capacity.LeafQueue: Application added - appId: application_1421286406893_0002 user: org.apache.hadoop.yarn.server.resourcemanager.scheduler.capacity.LeafQueue$User@4d2ceb, leaf-queue: default #user-pending-applications: 1 #user-active-applications: 1 #queue-pending-applications: 1 #queue-active-applications: 1
2015-01-14 20:03:06,739 INFO org.apache.hadoop.yarn.server.resourcemanager.scheduler.capacity.CapacityScheduler: Added Application Attempt appattempt_1421286406893_0002_000001 to scheduler from user doopy in queue default
2015-01-14 20:03:06,740 INFO org.apache.hadoop.yarn.server.resourcemanager.rmapp.attempt.RMAppAttemptImpl: appattempt_1421286406893_0002_000001 State change from SUBMITTED to SCHEDULED
2015-01-14 20:03:07,347 INFO org.apache.hadoop.yarn.server.resourcemanager.scheduler.capacity.CapacityScheduler: Null container completed...
2015-01-14 20:03:08,350 INFO org.apache.hadoop.yarn.server.resourcemanager.scheduler.capacity.CapacityScheduler: Null container completed...
2015-01-14 20:03:09,352 INFO org.apache.hadoop.yarn.server.resourcemanager.scheduler.capacity.CapacityScheduler: Null container completed...
2015-01-14 20:03:10,355 INFO org.apache.hadoop.yarn.server.resourcemanager.scheduler.capacity.CapacityScheduler: Null container completed...
2015-01-14 20:03:11,359 INFO org.apache.hadoop.yarn.server.resourcemanager.scheduler.capacity.CapacityScheduler: Null container completed...
2015-01-14 20:03:12,361 INFO org.apache.hadoop.yarn.server.resourcemanager.scheduler.capacity.CapacityScheduler: Null container completed...
2015-01-14 20:03:13,365 INFO org.apache.hadoop.yarn.server.resourcemanager.scheduler.capacity.CapacityScheduler: Null container completed...
2015-01-14 20:03:14,367 INFO org.apache.hadoop.yarn.server.resourcemanager.scheduler.capacity.CapacityScheduler: Null container completed...
2015-01-14 20:03:15,370 INFO org.apache.hadoop.yarn.server.resourcemanager.scheduler.capacity.CapacityScheduler: Null container completed...
2015-01-14 20:03:16,373 INFO org.apache.hadoop.yarn.server.resourcemanager.scheduler.capacity.CapacityScheduler: Null container completed...
2015-01-14 20:03:17,376 INFO org.apache.hadoop.yarn.server.resourcemanager.scheduler.capacity.CapacityScheduler: Null container completed...
2015-01-14 20:03:18,384 INFO org.apache.hadoop.yarn.server.resourcemanager.scheduler.capacity.CapacityScheduler: Null container completed...
2015-01-14 20:03:19,403 INFO org.apache.hadoop.yarn.server.resourcemanager.scheduler.capacity.CapacityScheduler: Null container completed...
2015-01-14 20:03:20,406 INFO org.apache.hadoop.yarn.server.resourcemanager.scheduler.capacity.CapacityScheduler: Null container completed...
2015-01-14 20:03:21,408 INFO org.apache.hadoop.yarn.server.resourcemanager.scheduler.capacity.CapacityScheduler: Null container completed...
2015-01-14 20:03:22,411 INFO org.apache.hadoop.yarn.server.resourcemanager.scheduler.capacity.CapacityScheduler: Null container completed...
2015-01-14 20:03:23,414 INFO org.apache.hadoop.yarn.server.resourcemanager.scheduler.capacity.CapacityScheduler: Null container completed...
2015-01-14 20:03:24,417 INFO org.apache.hadoop.yarn.server.resourcemanager.scheduler.capacity.CapacityScheduler: Null container completed...
2015-01-14 20:03:25,423 INFO org.apache.hadoop.yarn.server.resourcemanager.scheduler.capacity.CapacityScheduler: Null container completed...
2015-01-14 20:03:26,426 INFO org.apache.hadoop.yarn.server.resourcemanager.scheduler.capacity.CapacityScheduler: Null container completed...
2015-01-14 20:03:27,429 INFO org.apache.hadoop.yarn.server.resourcemanager.scheduler.capacity.CapacityScheduler: Null container completed...
2015-01-14 20:03:28,432 INFO org.apache.hadoop.yarn.server.resourcemanager.scheduler.capacity.CapacityScheduler: Null container completed...
2015-01-14 20:03:29,435 INFO org.apache.hadoop.yarn.server.resourcemanager.scheduler.capacity.CapacityScheduler: Null container completed...
2015-01-14 20:03:30,437 INFO org.apache.hadoop.yarn.server.resourcemanager.scheduler.capacity.CapacityScheduler: Null container completed...
2015-01-14 20:03:31,439 INFO org.apache.hadoop.yarn.server.resourcemanager.scheduler.capacity.CapacityScheduler: Null container completed...
2015-01-14 20:03:32,459 INFO org.apache.hadoop.yarn.server.resourcemanager.scheduler.capacity.CapacityScheduler: Null container completed...
2015-01-14 20:03:33,461 INFO org.apache.hadoop.yarn.server.resourcemanager.scheduler.capacity.CapacityScheduler: Null container completed...
2015-01-14 20:03:34,466 INFO org.apache.hadoop.yarn.server.resourcemanager.scheduler.capacity.CapacityScheduler: Null container completed...
2015-01-14 20:03:35,470 INFO org.apache.hadoop.yarn.server.resourcemanager.scheduler.capacity.CapacityScheduler: Null container completed...
2015-01-14 20:03:36,487 INFO org.apache.hadoop.yarn.server.resourcemanager.scheduler.capacity.CapacityScheduler: Null container completed...
2015-01-14 20:03:37,489 INFO org.apache.hadoop.yarn.server.resourcemanager.scheduler.capacity.CapacityScheduler: Null container completed...
2015-01-14 20:03:38,529 INFO org.apache.hadoop.yarn.server.resourcemanager.scheduler.capacity.CapacityScheduler: Null container completed...
2015-01-14 20:03:39,532 INFO org.apache.hadoop.yarn.server.resourcemanager.scheduler.capacity.CapacityScheduler: Null container completed...
2015-01-14 20:03:40,535 INFO org.apache.hadoop.yarn.server.resourcemanager.scheduler.capacity.CapacityScheduler: Null container completed...
2015-01-14 20:03:41,537 INFO org.apache.hadoop.yarn.server.resourcemanager.scheduler.capacity.CapacityScheduler: Null container completed...
2015-01-14 20:03:42,577 INFO org.apache.hadoop.yarn.server.resourcemanager.scheduler.capacity.CapacityScheduler: Null container completed...
2015-01-14 20:03:43,580 INFO org.apache.hadoop.yarn.server.resourcemanager.scheduler.capacity.CapacityScheduler: Null container completed...
2015-01-14 20:03:44,587 INFO org.apache.hadoop.yarn.server.resourcemanager.scheduler.capacity.CapacityScheduler: Null container completed...
2015-01-14 20:03:45,591 INFO org.apache.hadoop.yarn.server.resourcemanager.scheduler.capacity.CapacityScheduler: Null container completed...
2015-01-14 20:03:46,593 INFO org.apache.hadoop.yarn.server.resourcemanager.scheduler.capacity.CapacityScheduler: Null container completed...
2015-01-14 20:03:47,596 INFO org.apache.hadoop.yarn.server.resourcemanager.scheduler.capacity.CapacityScheduler: Null container completed...
2015-01-14 20:03:48,599 INFO org.apache.hadoop.yarn.server.resourcemanager.scheduler.capacity.CapacityScheduler: Null container completed...
2015-01-14 20:03:49,602 INFO org.apache.hadoop.yarn.server.resourcemanager.scheduler.capacity.CapacityScheduler: Null container completed...
2015-01-14 20:03:50,631 INFO org.apache.hadoop.yarn.server.resourcemanager.scheduler.capacity.CapacityScheduler: Null container completed...
2015-01-14 20:03:51,634 INFO org.apache.hadoop.yarn.server.resourcemanager.scheduler.capacity.CapacityScheduler: Null container completed...
2015-01-14 20:03:52,637 INFO org.apache.hadoop.yarn.server.resourcemanager.scheduler.capacity.CapacityScheduler: Null container completed...
2015-01-14 20:03:53,639 INFO org.apache.hadoop.yarn.server.resourcemanager.scheduler.capacity.CapacityScheduler: Null container completed...
2015-01-14 20:03:54,643 INFO org.apache.hadoop.yarn.server.resourcemanager.scheduler.capacity.CapacityScheduler: Null container completed...
2015-01-14 20:03:55,654 INFO org.apache.hadoop.yarn.server.resourcemanager.scheduler.capacity.CapacityScheduler: Null container completed...
2015-01-14 20:03:56,662 INFO org.apache.hadoop.yarn.server.resourcemanager.scheduler.capacity.CapacityScheduler: Null container completed...
2015-01-14 20:03:57,665 INFO org.apache.hadoop.yarn.server.resourcemanager.scheduler.capacity.CapacityScheduler: Null container completed...
2015-01-14 20:03:58,668 INFO org.apache.hadoop.yarn.server.resourcemanager.scheduler.capacity.CapacityScheduler: Null container completed...
2015-01-14 20:03:59,671 INFO org.apache.hadoop.yarn.server.resourcemanager.scheduler.capacity.CapacityScheduler: Null container completed...
2015-01-14 20:04:00,673 INFO org.apache.hadoop.yarn.server.resourcemanager.scheduler.capacity.CapacityScheduler: Null container completed...
2015-01-14 20:04:01,676 INFO org.apache.hadoop.yarn.server.resourcemanager.scheduler.capacity.CapacityScheduler: Null container completed...
2015-01-14 20:04:02,679 INFO org.apache.hadoop.yarn.server.resourcemanager.scheduler.capacity.CapacityScheduler: Null container completed...
2015-01-14 20:04:03,682 INFO org.apache.hadoop.yarn.server.resourcemanager.scheduler.capacity.CapacityScheduler: Null container completed...
2015-01-14 20:04:04,684 INFO org.apache.hadoop.yarn.server.resourcemanager.scheduler.capacity.CapacityScheduler: Null container completed...
2015-01-14 20:04:05,687 INFO org.apache.hadoop.yarn.server.resourcemanager.scheduler.capacity.CapacityScheduler: Null container completed...
2015-01-14 20:04:06,690 INFO org.apache.hadoop.yarn.server.resourcemanager.scheduler.capacity.CapacityScheduler: Null container completed...
2015-01-14 20:04:07,698 INFO org.apache.hadoop.yarn.server.resourcemanager.scheduler.capacity.CapacityScheduler: Null container completed...
2015-01-14 20:04:08,701 INFO org.apache.hadoop.yarn.server.resourcemanager.scheduler.capacity.CapacityScheduler: Null container completed...
2015-01-14 20:04:09,703 INFO org.apache.hadoop.yarn.server.resourcemanager.scheduler.capacity.CapacityScheduler: Null container completed...
2015-01-14 20:04:10,706 INFO org.apache.hadoop.yarn.server.resourcemanager.scheduler.capacity.CapacityScheduler: Null container completed...
2015-01-14 20:04:11,708 INFO org.apache.hadoop.yarn.server.resourcemanager.scheduler.capacity.CapacityScheduler: Null container completed...
2015-01-14 20:04:12,711 INFO org.apache.hadoop.yarn.server.resourcemanager.scheduler.capacity.CapacityScheduler: Null container completed...
2015-01-14 20:04:13,714 INFO org.apache.hadoop.yarn.server.resourcemanager.scheduler.capacity.CapacityScheduler: Null container completed...
2015-01-14 20:04:14,717 INFO org.apache.hadoop.yarn.server.resourcemanager.scheduler.capacity.CapacityScheduler: Null container completed...
2015-01-14 20:04:15,719 INFO org.apache.hadoop.yarn.server.resourcemanager.scheduler.capacity.CapacityScheduler: Null container completed...
2015-01-14 20:04:16,722 INFO org.apache.hadoop.yarn.server.resourcemanager.scheduler.capacity.CapacityScheduler: Null container completed...
2015-01-14 20:04:17,725 INFO org.apache.hadoop.yarn.server.resourcemanager.scheduler.capacity.CapacityScheduler: Null container completed...
2015-01-14 20:04:18,727 INFO org.apache.hadoop.yarn.server.resourcemanager.scheduler.capacity.CapacityScheduler: Null container completed...
2015-01-14 20:04:19,730 INFO org.apache.hadoop.yarn.server.resourcemanager.scheduler.capacity.CapacityScheduler: Null container completed...
2015-01-14 20:04:20,733 INFO org.apache.hadoop.yarn.server.resourcemanager.scheduler.capacity.CapacityScheduler: Null container completed...
2015-01-14 20:04:21,735 INFO org.apache.hadoop.yarn.server.resourcemanager.scheduler.capacity.CapacityScheduler: Null container completed...
2015-01-14 20:04:22,738 INFO org.apache.hadoop.yarn.server.resourcemanager.scheduler.capacity.CapacityScheduler: Null container completed...
2015-01-14 20:04:23,741 INFO org.apache.hadoop.yarn.server.resourcemanager.scheduler.capacity.CapacityScheduler: Null container completed...
2015-01-14 20:04:24,743 INFO org.apache.hadoop.yarn.server.resourcemanager.scheduler.capacity.CapacityScheduler: Null container completed...
2015-01-14 20:04:25,746 INFO org.apache.hadoop.yarn.server.resourcemanager.scheduler.capacity.CapacityScheduler: Null container completed...
2015-01-14 20:04:26,748 INFO org.apache.hadoop.yarn.server.resourcemanager.scheduler.capacity.CapacityScheduler: Null container completed...
2015-01-14 20:04:27,751 INFO org.apache.hadoop.yarn.server.resourcemanager.scheduler.capacity.CapacityScheduler: Null container completed...
2015-01-14 20:04:28,754 INFO org.apache.hadoop.yarn.server.resourcemanager.scheduler.capacity.CapacityScheduler: Null container completed...
2015-01-14 20:04:29,756 INFO org.apache.hadoop.yarn.server.resourcemanager.scheduler.capacity.CapacityScheduler: Null container completed...
2015-01-14 20:04:30,759 INFO org.apache.hadoop.yarn.server.resourcemanager.scheduler.capacity.CapacityScheduler: Null container completed...
2015-01-14 20:04:31,762 INFO org.apache.hadoop.yarn.server.resourcemanager.scheduler.capacity.CapacityScheduler: Null container completed...
2015-01-14 20:04:32,764 INFO org.apache.hadoop.yarn.server.resourcemanager.scheduler.capacity.CapacityScheduler: Null container completed...
2015-01-14 20:04:33,767 INFO org.apache.hadoop.yarn.server.resourcemanager.scheduler.capacity.CapacityScheduler: Null container completed...
2015-01-14 20:04:34,770 INFO org.apache.hadoop.yarn.server.resourcemanager.scheduler.capacity.CapacityScheduler: Null container completed...
2015-01-14 20:04:35,773 INFO org.apache.hadoop.yarn.server.resourcemanager.scheduler.capacity.CapacityScheduler: Null container completed...
2015-01-14 20:04:36,776 INFO org.apache.hadoop.yarn.server.resourcemanager.scheduler.capacity.CapacityScheduler: Null container completed...
2015-01-14 20:04:37,778 INFO org.apache.hadoop.yarn.server.resourcemanager.scheduler.capacity.CapacityScheduler: Null container completed...
2015-01-14 20:04:38,782 INFO org.apache.hadoop.yarn.server.resourcemanager.scheduler.capacity.CapacityScheduler: Null container completed...
2015-01-14 20:04:39,785 INFO org.apache.hadoop.yarn.server.resourcemanager.scheduler.capacity.CapacityScheduler: Null container completed...
2015-01-14 20:04:40,788 INFO org.apache.hadoop.yarn.server.resourcemanager.scheduler.capacity.CapacityScheduler: Null container completed...
2015-01-14 20:04:41,790 INFO org.apache.hadoop.yarn.server.resourcemanager.scheduler.capacity.CapacityScheduler: Null container completed...
2015-01-14 20:04:42,793 INFO org.apache.hadoop.yarn.server.resourcemanager.scheduler.capacity.CapacityScheduler: Null container completed...
2015-01-14 20:04:43,797 INFO org.apache.hadoop.yarn.server.resourcemanager.scheduler.capacity.CapacityScheduler: Null container completed...
2015-01-14 20:04:44,801 INFO org.apache.hadoop.yarn.server.resourcemanager.scheduler.capacity.CapacityScheduler: Null container completed...
2015-01-14 20:04:45,804 INFO org.apache.hadoop.yarn.server.resourcemanager.scheduler.capacity.CapacityScheduler: Null container completed...
2015-01-14 20:04:46,806 INFO org.apache.hadoop.yarn.server.resourcemanager.scheduler.capacity.CapacityScheduler: Null container completed...
2015-01-14 20:04:47,810 INFO org.apache.hadoop.yarn.server.resourcemanager.scheduler.capacity.CapacityScheduler: Null container completed...
2015-01-14 20:04:48,812 INFO org.apache.hadoop.yarn.server.resourcemanager.scheduler.capacity.CapacityScheduler: Null container completed...
2015-01-14 20:04:49,815 INFO org.apache.hadoop.yarn.server.resourcemanager.scheduler.capacity.CapacityScheduler: Null container completed...
2015-01-14 20:04:50,819 INFO org.apache.hadoop.yarn.server.resourcemanager.scheduler.capacity.CapacityScheduler: Null container completed...
2015-01-14 20:04:51,821 INFO org.apache.hadoop.yarn.server.resourcemanager.scheduler.capacity.CapacityScheduler: Null container completed...
2015-01-14 20:04:52,823 INFO org.apache.hadoop.yarn.server.resourcemanager.scheduler.capacity.CapacityScheduler: Null container completed...
2015-01-14 20:04:53,828 INFO org.apache.hadoop.yarn.server.resourcemanager.scheduler.capacity.CapacityScheduler: Null container completed...
2015-01-14 20:04:54,830 INFO org.apache.hadoop.yarn.server.resourcemanager.scheduler.capacity.CapacityScheduler: Null container completed...
2015-01-14 20:04:55,832 INFO org.apache.hadoop.yarn.server.resourcemanager.scheduler.capacity.CapacityScheduler: Null container completed...
2015-01-14 20:04:56,836 INFO org.apache.hadoop.yarn.server.resourcemanager.scheduler.capacity.CapacityScheduler: Null container completed...
2015-01-14 20:04:57,839 INFO org.apache.hadoop.yarn.server.resourcemanager.scheduler.capacity.CapacityScheduler: Null container completed...
2015-01-14 20:04:58,842 INFO org.apache.hadoop.yarn.server.resourcemanager.scheduler.capacity.CapacityScheduler: Null container completed...
2015-01-14 20:04:59,846 INFO org.apache.hadoop.yarn.server.resourcemanager.scheduler.capacity.CapacityScheduler: Null container completed...
2015-01-14 20:05:00,848 INFO org.apache.hadoop.yarn.server.resourcemanager.scheduler.capacity.CapacityScheduler: Null container completed...
2015-01-14 20:05:01,850 INFO org.apache.hadoop.yarn.server.resourcemanager.scheduler.capacity.CapacityScheduler: Null container completed...
2015-01-14 20:05:02,855 INFO org.apache.hadoop.yarn.server.resourcemanager.scheduler.capacity.CapacityScheduler: Null container completed...
2015-01-14 20:05:03,858 INFO org.apache.hadoop.yarn.server.resourcemanager.scheduler.capacity.CapacityScheduler: Null container completed...
2015-01-14 20:05:04,860 INFO org.apache.hadoop.yarn.server.resourcemanager.scheduler.capacity.CapacityScheduler: Null container completed...
2015-01-14 20:05:05,864 INFO org.apache.hadoop.yarn.server.resourcemanager.scheduler.capacity.CapacityScheduler: Null container completed...
2015-01-14 20:05:06,866 INFO org.apache.hadoop.yarn.server.resourcemanager.scheduler.capacity.CapacityScheduler: Null container completed...
2015-01-14 20:05:07,870 INFO org.apache.hadoop.yarn.server.resourcemanager.scheduler.capacity.CapacityScheduler: Null container completed...
2015-01-14 20:05:08,874 INFO org.apache.hadoop.yarn.server.resourcemanager.scheduler.capacity.CapacityScheduler: Null container completed...
2015-01-14 20:05:09,893 INFO org.apache.hadoop.yarn.server.resourcemanager.scheduler.capacity.CapacityScheduler: Null container completed...
2015-01-14 20:05:10,895 INFO org.apache.hadoop.yarn.server.resourcemanager.scheduler.capacity.CapacityScheduler: Null container completed...
2015-01-14 20:05:11,899 INFO org.apache.hadoop.yarn.server.resourcemanager.scheduler.capacity.CapacityScheduler: Null container completed...
2015-01-14 20:05:12,901 INFO org.apache.hadoop.yarn.server.resourcemanager.scheduler.capacity.CapacityScheduler: Null container completed...
2015-01-14 20:05:13,904 INFO org.apache.hadoop.yarn.server.resourcemanager.scheduler.capacity.CapacityScheduler: Null container completed...
2015-01-14 20:05:14,907 INFO org.apache.hadoop.yarn.server.resourcemanager.scheduler.capacity.CapacityScheduler: Null container completed...
2015-01-14 20:05:15,909 INFO org.apache.hadoop.yarn.server.resourcemanager.scheduler.capacity.CapacityScheduler: Null container completed...
2015-01-14 20:05:16,912 INFO org.apache.hadoop.yarn.server.resourcemanager.scheduler.capacity.CapacityScheduler: Null container completed...
2015-01-14 20:05:17,915 INFO org.apache.hadoop.yarn.server.resourcemanager.scheduler.capacity.CapacityScheduler: Null container completed...
2015-01-14 20:05:18,917 INFO org.apache.hadoop.yarn.server.resourcemanager.scheduler.capacity.CapacityScheduler: Null container completed...
2015-01-14 20:05:19,920 INFO org.apache.hadoop.yarn.server.resourcemanager.scheduler.capacity.CapacityScheduler: Null container completed...
2015-01-14 20:05:20,923 INFO org.apache.hadoop.yarn.server.resourcemanager.scheduler.capacity.CapacityScheduler: Null container completed...
2015-01-14 20:05:21,925 INFO org.apache.hadoop.yarn.server.resourcemanager.scheduler.capacity.CapacityScheduler: Null container completed...
2015-01-14 20:05:22,927 INFO org.apache.hadoop.yarn.server.resourcemanager.scheduler.capacity.CapacityScheduler: Null container completed...
2015-01-14 20:05:23,930 INFO org.apache.hadoop.yarn.server.resourcemanager.scheduler.capacity.CapacityScheduler: Null container completed...
2015-01-14 20:05:24,934 INFO org.apache.hadoop.yarn.server.resourcemanager.scheduler.capacity.CapacityScheduler: Null container completed...
2015-01-14 20:05:25,937 INFO org.apache.hadoop.yarn.server.resourcemanager.scheduler.capacity.CapacityScheduler: Null container completed...
2015-01-14 20:05:26,939 INFO org.apache.hadoop.yarn.server.resourcemanager.scheduler.capacity.CapacityScheduler: Null container completed...
2015-01-14 20:05:27,942 INFO org.apache.hadoop.yarn.server.resourcemanager.scheduler.capacity.CapacityScheduler: Null container completed...
2015-01-14 20:05:28,945 INFO org.apache.hadoop.yarn.server.resourcemanager.scheduler.capacity.CapacityScheduler: Null container completed...
2015-01-14 20:05:29,947 INFO org.apache.hadoop.yarn.server.resourcemanager.scheduler.capacity.CapacityScheduler: Null container completed...
2015-01-14 20:05:30,951 INFO org.apache.hadoop.yarn.server.resourcemanager.scheduler.capacity.CapacityScheduler: Null container completed...
2015-01-14 20:05:31,952 INFO org.apache.hadoop.yarn.server.resourcemanager.scheduler.capacity.CapacityScheduler: Null container completed...
2015-01-14 20:05:32,955 INFO org.apache.hadoop.yarn.server.resourcemanager.scheduler.capacity.CapacityScheduler: Null container completed...
2015-01-14 20:05:33,959 INFO org.apache.hadoop.yarn.server.resourcemanager.scheduler.capacity.CapacityScheduler: Null container completed...
2015-01-14 20:05:34,961 INFO org.apache.hadoop.yarn.server.resourcemanager.scheduler.capacity.CapacityScheduler: Null container completed...
2015-01-14 20:05:35,964 INFO org.apache.hadoop.yarn.server.resourcemanager.scheduler.capacity.CapacityScheduler: Null container completed...
2015-01-14 20:05:36,968 INFO org.apache.hadoop.yarn.server.resourcemanager.scheduler.capacity.CapacityScheduler: Null container completed...
2015-01-14 20:05:37,970 INFO org.apache.hadoop.yarn.server.resourcemanager.scheduler.capacity.CapacityScheduler: Null container completed...
2015-01-14 20:05:38,974 INFO org.apache.hadoop.yarn.server.resourcemanager.scheduler.capacity.CapacityScheduler: Null container completed...
2015-01-14 20:05:39,976 INFO org.apache.hadoop.yarn.server.resourcemanager.scheduler.capacity.CapacityScheduler: Null container completed...
2015-01-14 20:05:40,978 INFO org.apache.hadoop.yarn.server.resourcemanager.scheduler.capacity.CapacityScheduler: Null container completed...
2015-01-14 20:05:41,982 INFO org.apache.hadoop.yarn.server.resourcemanager.scheduler.capacity.CapacityScheduler: Null container completed...
2015-01-14 20:05:42,986 INFO org.apache.hadoop.yarn.server.resourcemanager.scheduler.capacity.CapacityScheduler: Null container completed...
2015-01-14 20:05:43,988 INFO org.apache.hadoop.yarn.server.resourcemanager.scheduler.capacity.CapacityScheduler: Null container completed...
2015-01-14 20:05:44,992 INFO org.apache.hadoop.yarn.server.resourcemanager.scheduler.capacity.CapacityScheduler: Null container completed...
2015-01-14 20:05:45,995 INFO org.apache.hadoop.yarn.server.resourcemanager.scheduler.capacity.CapacityScheduler: Null container completed...
2015-01-14 20:05:46,997 INFO org.apache.hadoop.yarn.server.resourcemanager.scheduler.capacity.CapacityScheduler: Null container completed...
2015-01-14 20:05:48,001 INFO org.apache.hadoop.yarn.server.resourcemanager.scheduler.capacity.CapacityScheduler: Null container completed...
2015-01-14 20:05:49,004 INFO org.apache.hadoop.yarn.server.resourcemanager.scheduler.capacity.CapacityScheduler: Null container completed...
2015-01-14 20:05:50,007 INFO org.apache.hadoop.yarn.server.resourcemanager.scheduler.capacity.CapacityScheduler: Null container completed...
2015-01-14 20:05:51,010 INFO org.apache.hadoop.yarn.server.resourcemanager.scheduler.capacity.CapacityScheduler: Null container completed...
2015-01-14 20:05:52,012 INFO org.apache.hadoop.yarn.server.resourcemanager.scheduler.capacity.CapacityScheduler: Null container completed...
2015-01-14 20:05:53,016 INFO org.apache.hadoop.yarn.server.resourcemanager.scheduler.capacity.CapacityScheduler: Null container completed...
2015-01-14 20:05:54,019 INFO org.apache.hadoop.yarn.server.resourcemanager.scheduler.capacity.CapacityScheduler: Null container completed...
2015-01-14 20:05:54,215 INFO org.apache.hadoop.yarn.server.resourcemanager.ClientRMService: Allocated new applicationId: 3
2015-01-14 20:05:55,021 INFO org.apache.hadoop.yarn.server.resourcemanager.scheduler.capacity.CapacityScheduler: Null container completed...
2015-01-14 20:05:56,024 INFO org.apache.hadoop.yarn.server.resourcemanager.scheduler.capacity.CapacityScheduler: Null container completed...
2015-01-14 20:05:56,460 INFO org.apache.hadoop.yarn.server.resourcemanager.ClientRMService: Application with id 3 submitted by user doopy
2015-01-14 20:05:56,461 INFO org.apache.hadoop.yarn.server.resourcemanager.RMAuditLogger: USER=doopy	IP=127.0.0.1	OPERATION=Submit Application Request	TARGET=ClientRMService	RESULT=SUCCESS	APPID=application_1421286406893_0003
2015-01-14 20:05:56,461 INFO org.apache.hadoop.yarn.server.resourcemanager.rmapp.RMAppImpl: Storing application with id application_1421286406893_0003
2015-01-14 20:05:56,461 INFO org.apache.hadoop.yarn.server.resourcemanager.rmapp.RMAppImpl: application_1421286406893_0003 State change from NEW to NEW_SAVING
2015-01-14 20:05:56,461 INFO org.apache.hadoop.yarn.server.resourcemanager.recovery.RMStateStore: Storing info for app: application_1421286406893_0003
2015-01-14 20:05:56,461 INFO org.apache.hadoop.yarn.server.resourcemanager.rmapp.RMAppImpl: application_1421286406893_0003 State change from NEW_SAVING to SUBMITTED
2015-01-14 20:05:56,461 INFO org.apache.hadoop.yarn.server.resourcemanager.scheduler.capacity.ParentQueue: Application added - appId: application_1421286406893_0003 user: doopy leaf-queue of parent: root #applications: 3
2015-01-14 20:05:56,461 INFO org.apache.hadoop.yarn.server.resourcemanager.scheduler.capacity.CapacityScheduler: Accepted application application_1421286406893_0003 from user: doopy, in queue: default
2015-01-14 20:05:56,463 INFO org.apache.hadoop.yarn.server.resourcemanager.rmapp.RMAppImpl: application_1421286406893_0003 State change from SUBMITTED to ACCEPTED
2015-01-14 20:05:56,464 INFO org.apache.hadoop.yarn.server.resourcemanager.ApplicationMasterService: Registering app attempt : appattempt_1421286406893_0003_000001
2015-01-14 20:05:56,465 INFO org.apache.hadoop.yarn.server.resourcemanager.rmapp.attempt.RMAppAttemptImpl: appattempt_1421286406893_0003_000001 State change from NEW to SUBMITTED
2015-01-14 20:05:56,465 INFO org.apache.hadoop.yarn.server.resourcemanager.scheduler.capacity.LeafQueue: Application added - appId: application_1421286406893_0003 user: org.apache.hadoop.yarn.server.resourcemanager.scheduler.capacity.LeafQueue$User@4d2ceb, leaf-queue: default #user-pending-applications: 2 #user-active-applications: 1 #queue-pending-applications: 2 #queue-active-applications: 1
2015-01-14 20:05:56,465 INFO org.apache.hadoop.yarn.server.resourcemanager.scheduler.capacity.CapacityScheduler: Added Application Attempt appattempt_1421286406893_0003_000001 to scheduler from user doopy in queue default
2015-01-14 20:05:56,466 INFO org.apache.hadoop.yarn.server.resourcemanager.rmapp.attempt.RMAppAttemptImpl: appattempt_1421286406893_0003_000001 State change from SUBMITTED to SCHEDULED
2015-01-14 20:05:57,026 INFO org.apache.hadoop.yarn.server.resourcemanager.scheduler.capacity.CapacityScheduler: Null container completed...
2015-01-14 20:05:58,029 INFO org.apache.hadoop.yarn.server.resourcemanager.scheduler.capacity.CapacityScheduler: Null container completed...
2015-01-14 20:05:59,032 INFO org.apache.hadoop.yarn.server.resourcemanager.scheduler.capacity.CapacityScheduler: Null container completed...
2015-01-14 20:06:00,034 INFO org.apache.hadoop.yarn.server.resourcemanager.scheduler.capacity.CapacityScheduler: Null container completed...
2015-01-14 20:06:01,037 INFO org.apache.hadoop.yarn.server.resourcemanager.scheduler.capacity.CapacityScheduler: Null container completed...
2015-01-14 20:06:02,040 INFO org.apache.hadoop.yarn.server.resourcemanager.scheduler.capacity.CapacityScheduler: Null container completed...
2015-01-14 20:06:03,042 INFO org.apache.hadoop.yarn.server.resourcemanager.scheduler.capacity.CapacityScheduler: Null container completed...
2015-01-14 20:06:04,045 INFO org.apache.hadoop.yarn.server.resourcemanager.scheduler.capacity.CapacityScheduler: Null container completed...
2015-01-14 20:06:05,047 INFO org.apache.hadoop.yarn.server.resourcemanager.scheduler.capacity.CapacityScheduler: Null container completed...
2015-01-14 20:06:06,050 INFO org.apache.hadoop.yarn.server.resourcemanager.scheduler.capacity.CapacityScheduler: Null container completed...
2015-01-14 20:06:07,052 INFO org.apache.hadoop.yarn.server.resourcemanager.scheduler.capacity.CapacityScheduler: Null container completed...
2015-01-14 20:06:08,055 INFO org.apache.hadoop.yarn.server.resourcemanager.scheduler.capacity.CapacityScheduler: Null container completed...
2015-01-14 20:06:09,058 INFO org.apache.hadoop.yarn.server.resourcemanager.scheduler.capacity.CapacityScheduler: Null container completed...
2015-01-14 20:06:10,060 INFO org.apache.hadoop.yarn.server.resourcemanager.scheduler.capacity.CapacityScheduler: Null container completed...
2015-01-14 20:06:11,064 INFO org.apache.hadoop.yarn.server.resourcemanager.scheduler.capacity.CapacityScheduler: Null container completed...
2015-01-14 20:06:12,068 INFO org.apache.hadoop.yarn.server.resourcemanager.scheduler.capacity.CapacityScheduler: Null container completed...
2015-01-14 20:06:13,070 INFO org.apache.hadoop.yarn.server.resourcemanager.scheduler.capacity.CapacityScheduler: Null container completed...
2015-01-14 20:06:14,072 INFO org.apache.hadoop.yarn.server.resourcemanager.scheduler.capacity.CapacityScheduler: Null container completed...
2015-01-14 20:06:15,077 INFO org.apache.hadoop.yarn.server.resourcemanager.scheduler.capacity.CapacityScheduler: Null container completed...
2015-01-14 20:06:16,080 INFO org.apache.hadoop.yarn.server.resourcemanager.scheduler.capacity.CapacityScheduler: Null container completed...
2015-01-14 20:06:17,082 INFO org.apache.hadoop.yarn.server.resourcemanager.scheduler.capacity.CapacityScheduler: Null container completed...
2015-01-14 20:06:17,270 INFO org.apache.hadoop.yarn.server.resourcemanager.ClientRMService: Allocated new applicationId: 4
2015-01-14 20:06:18,085 INFO org.apache.hadoop.yarn.server.resourcemanager.scheduler.capacity.CapacityScheduler: Null container completed...
2015-01-14 20:06:18,976 INFO org.apache.hadoop.yarn.server.resourcemanager.ClientRMService: Application with id 4 submitted by user doopy
2015-01-14 20:06:18,976 INFO org.apache.hadoop.yarn.server.resourcemanager.RMAuditLogger: USER=doopy	IP=127.0.0.1	OPERATION=Submit Application Request	TARGET=ClientRMService	RESULT=SUCCESS	APPID=application_1421286406893_0004
2015-01-14 20:06:18,977 INFO org.apache.hadoop.yarn.server.resourcemanager.rmapp.RMAppImpl: Storing application with id application_1421286406893_0004
2015-01-14 20:06:18,977 INFO org.apache.hadoop.yarn.server.resourcemanager.rmapp.RMAppImpl: application_1421286406893_0004 State change from NEW to NEW_SAVING
2015-01-14 20:06:18,977 INFO org.apache.hadoop.yarn.server.resourcemanager.recovery.RMStateStore: Storing info for app: application_1421286406893_0004
2015-01-14 20:06:18,977 INFO org.apache.hadoop.yarn.server.resourcemanager.rmapp.RMAppImpl: application_1421286406893_0004 State change from NEW_SAVING to SUBMITTED
2015-01-14 20:06:18,977 INFO org.apache.hadoop.yarn.server.resourcemanager.scheduler.capacity.ParentQueue: Application added - appId: application_1421286406893_0004 user: doopy leaf-queue of parent: root #applications: 4
2015-01-14 20:06:18,977 INFO org.apache.hadoop.yarn.server.resourcemanager.scheduler.capacity.CapacityScheduler: Accepted application application_1421286406893_0004 from user: doopy, in queue: default
2015-01-14 20:06:18,978 INFO org.apache.hadoop.yarn.server.resourcemanager.rmapp.RMAppImpl: application_1421286406893_0004 State change from SUBMITTED to ACCEPTED
2015-01-14 20:06:18,978 INFO org.apache.hadoop.yarn.server.resourcemanager.ApplicationMasterService: Registering app attempt : appattempt_1421286406893_0004_000001
2015-01-14 20:06:18,978 INFO org.apache.hadoop.yarn.server.resourcemanager.rmapp.attempt.RMAppAttemptImpl: appattempt_1421286406893_0004_000001 State change from NEW to SUBMITTED
2015-01-14 20:06:18,979 INFO org.apache.hadoop.yarn.server.resourcemanager.scheduler.capacity.LeafQueue: Application added - appId: application_1421286406893_0004 user: org.apache.hadoop.yarn.server.resourcemanager.scheduler.capacity.LeafQueue$User@4d2ceb, leaf-queue: default #user-pending-applications: 3 #user-active-applications: 1 #queue-pending-applications: 3 #queue-active-applications: 1
2015-01-14 20:06:18,979 INFO org.apache.hadoop.yarn.server.resourcemanager.scheduler.capacity.CapacityScheduler: Added Application Attempt appattempt_1421286406893_0004_000001 to scheduler from user doopy in queue default
2015-01-14 20:06:18,980 INFO org.apache.hadoop.yarn.server.resourcemanager.rmapp.attempt.RMAppAttemptImpl: appattempt_1421286406893_0004_000001 State change from SUBMITTED to SCHEDULED
2015-01-14 20:06:19,088 INFO org.apache.hadoop.yarn.server.resourcemanager.scheduler.capacity.CapacityScheduler: Null container completed...
2015-01-14 20:06:20,090 INFO org.apache.hadoop.yarn.server.resourcemanager.scheduler.capacity.CapacityScheduler: Null container completed...
2015-01-14 20:06:21,093 INFO org.apache.hadoop.yarn.server.resourcemanager.scheduler.capacity.CapacityScheduler: Null container completed...
2015-01-14 20:06:22,096 INFO org.apache.hadoop.yarn.server.resourcemanager.scheduler.capacity.CapacityScheduler: Null container completed...
2015-01-14 20:06:23,098 INFO org.apache.hadoop.yarn.server.resourcemanager.scheduler.capacity.CapacityScheduler: Null container completed...
2015-01-14 20:06:24,102 INFO org.apache.hadoop.yarn.server.resourcemanager.scheduler.capacity.CapacityScheduler: Null container completed...
2015-01-14 20:06:25,105 INFO org.apache.hadoop.yarn.server.resourcemanager.scheduler.capacity.CapacityScheduler: Null container completed...
2015-01-14 20:06:26,107 INFO org.apache.hadoop.yarn.server.resourcemanager.scheduler.capacity.CapacityScheduler: Null container completed...
2015-01-14 20:06:27,110 INFO org.apache.hadoop.yarn.server.resourcemanager.scheduler.capacity.CapacityScheduler: Null container completed...
2015-01-14 20:06:28,113 INFO org.apache.hadoop.yarn.server.resourcemanager.scheduler.capacity.CapacityScheduler: Null container completed...
2015-01-14 20:06:29,116 INFO org.apache.hadoop.yarn.server.resourcemanager.scheduler.capacity.CapacityScheduler: Null container completed...
2015-01-14 20:06:30,118 INFO org.apache.hadoop.yarn.server.resourcemanager.scheduler.capacity.CapacityScheduler: Null container completed...
2015-01-14 20:06:31,121 INFO org.apache.hadoop.yarn.server.resourcemanager.scheduler.capacity.CapacityScheduler: Null container completed...
2015-01-14 20:06:32,123 INFO org.apache.hadoop.yarn.server.resourcemanager.scheduler.capacity.CapacityScheduler: Null container completed...
2015-01-14 20:06:33,127 INFO org.apache.hadoop.yarn.server.resourcemanager.scheduler.capacity.CapacityScheduler: Null container completed...
2015-01-14 20:06:34,130 INFO org.apache.hadoop.yarn.server.resourcemanager.scheduler.capacity.CapacityScheduler: Null container completed...
2015-01-14 20:06:35,132 INFO org.apache.hadoop.yarn.server.resourcemanager.scheduler.capacity.CapacityScheduler: Null container completed...
2015-01-14 20:06:36,135 INFO org.apache.hadoop.yarn.server.resourcemanager.scheduler.capacity.CapacityScheduler: Null container completed...
2015-01-14 20:06:37,137 INFO org.apache.hadoop.yarn.server.resourcemanager.scheduler.capacity.CapacityScheduler: Null container completed...
2015-01-14 20:06:38,141 INFO org.apache.hadoop.yarn.server.resourcemanager.scheduler.capacity.CapacityScheduler: Null container completed...
2015-01-14 20:06:39,144 INFO org.apache.hadoop.yarn.server.resourcemanager.scheduler.capacity.CapacityScheduler: Null container completed...
2015-01-14 20:06:40,147 INFO org.apache.hadoop.yarn.server.resourcemanager.scheduler.capacity.CapacityScheduler: Null container completed...
2015-01-14 20:06:41,149 INFO org.apache.hadoop.yarn.server.resourcemanager.scheduler.capacity.CapacityScheduler: Null container completed...
2015-01-14 20:06:42,153 INFO org.apache.hadoop.yarn.server.resourcemanager.scheduler.capacity.CapacityScheduler: Null container completed...
2015-01-14 20:06:43,155 INFO org.apache.hadoop.yarn.server.resourcemanager.scheduler.capacity.CapacityScheduler: Null container completed...
2015-01-14 20:06:44,158 INFO org.apache.hadoop.yarn.server.resourcemanager.scheduler.capacity.CapacityScheduler: Null container completed...
2015-01-14 20:06:45,162 INFO org.apache.hadoop.yarn.server.resourcemanager.scheduler.capacity.CapacityScheduler: Null container completed...
2015-01-14 20:06:46,164 INFO org.apache.hadoop.yarn.server.resourcemanager.scheduler.capacity.CapacityScheduler: Null container completed...
2015-01-14 20:06:47,166 INFO org.apache.hadoop.yarn.server.resourcemanager.scheduler.capacity.CapacityScheduler: Null container completed...
2015-01-14 20:06:48,170 INFO org.apache.hadoop.yarn.server.resourcemanager.scheduler.capacity.CapacityScheduler: Null container completed...
2015-01-14 20:06:49,172 INFO org.apache.hadoop.yarn.server.resourcemanager.scheduler.capacity.CapacityScheduler: Null container completed...
2015-01-14 20:06:50,175 INFO org.apache.hadoop.yarn.server.resourcemanager.scheduler.capacity.CapacityScheduler: Null container completed...
2015-01-14 20:06:51,179 INFO org.apache.hadoop.yarn.server.resourcemanager.scheduler.capacity.CapacityScheduler: Null container completed...
2015-01-14 20:06:52,182 INFO org.apache.hadoop.yarn.server.resourcemanager.scheduler.capacity.CapacityScheduler: Null container completed...
2015-01-14 20:06:53,184 INFO org.apache.hadoop.yarn.server.resourcemanager.scheduler.capacity.CapacityScheduler: Null container completed...
2015-01-14 20:06:54,187 INFO org.apache.hadoop.yarn.server.resourcemanager.scheduler.capacity.CapacityScheduler: Null container completed...
2015-01-14 20:06:55,190 INFO org.apache.hadoop.yarn.server.resourcemanager.scheduler.capacity.CapacityScheduler: Null container completed...
2015-01-14 20:06:56,192 INFO org.apache.hadoop.yarn.server.resourcemanager.scheduler.capacity.CapacityScheduler: Null container completed...
2015-01-14 20:06:57,195 INFO org.apache.hadoop.yarn.server.resourcemanager.scheduler.capacity.CapacityScheduler: Null container completed...
2015-01-14 20:06:58,198 INFO org.apache.hadoop.yarn.server.resourcemanager.scheduler.capacity.CapacityScheduler: Null container completed...
2015-01-14 20:06:59,201 INFO org.apache.hadoop.yarn.server.resourcemanager.scheduler.capacity.CapacityScheduler: Null container completed...
2015-01-14 20:07:00,205 INFO org.apache.hadoop.yarn.server.resourcemanager.scheduler.capacity.CapacityScheduler: Null container completed...
2015-01-14 20:07:01,208 INFO org.apache.hadoop.yarn.server.resourcemanager.scheduler.capacity.CapacityScheduler: Null container completed...
2015-01-14 20:07:02,210 INFO org.apache.hadoop.yarn.server.resourcemanager.scheduler.capacity.CapacityScheduler: Null container completed...
2015-01-14 20:07:03,213 INFO org.apache.hadoop.yarn.server.resourcemanager.scheduler.capacity.CapacityScheduler: Null container completed...
2015-01-14 20:07:04,216 INFO org.apache.hadoop.yarn.server.resourcemanager.scheduler.capacity.CapacityScheduler: Null container completed...
2015-01-14 20:07:05,218 INFO org.apache.hadoop.yarn.server.resourcemanager.scheduler.capacity.CapacityScheduler: Null container completed...
2015-01-14 20:07:06,221 INFO org.apache.hadoop.yarn.server.resourcemanager.scheduler.capacity.CapacityScheduler: Null container completed...
2015-01-14 20:07:07,224 INFO org.apache.hadoop.yarn.server.resourcemanager.scheduler.capacity.CapacityScheduler: Null container completed...
2015-01-14 20:07:08,227 INFO org.apache.hadoop.yarn.server.resourcemanager.scheduler.capacity.CapacityScheduler: Null container completed...
2015-01-14 20:07:09,230 INFO org.apache.hadoop.yarn.server.resourcemanager.scheduler.capacity.CapacityScheduler: Null container completed...
2015-01-14 20:07:10,233 INFO org.apache.hadoop.yarn.server.resourcemanager.scheduler.capacity.CapacityScheduler: Null container completed...
2015-01-14 20:07:11,235 INFO org.apache.hadoop.yarn.server.resourcemanager.scheduler.capacity.CapacityScheduler: Null container completed...
2015-01-14 20:07:12,240 INFO org.apache.hadoop.yarn.server.resourcemanager.scheduler.capacity.CapacityScheduler: Null container completed...
2015-01-14 20:07:13,241 INFO org.apache.hadoop.yarn.server.resourcemanager.scheduler.capacity.CapacityScheduler: Null container completed...
2015-01-14 20:07:14,243 INFO org.apache.hadoop.yarn.server.resourcemanager.scheduler.capacity.CapacityScheduler: Null container completed...
2015-01-14 20:07:15,247 INFO org.apache.hadoop.yarn.server.resourcemanager.scheduler.capacity.CapacityScheduler: Null container completed...
2015-01-14 20:07:16,250 INFO org.apache.hadoop.yarn.server.resourcemanager.scheduler.capacity.CapacityScheduler: Null container completed...
2015-01-14 20:07:17,253 INFO org.apache.hadoop.yarn.server.resourcemanager.scheduler.capacity.CapacityScheduler: Null container completed...
2015-01-14 20:07:18,255 INFO org.apache.hadoop.yarn.server.resourcemanager.scheduler.capacity.CapacityScheduler: Null container completed...
2015-01-14 20:07:19,257 INFO org.apache.hadoop.yarn.server.resourcemanager.scheduler.capacity.CapacityScheduler: Null container completed...
2015-01-14 20:07:20,260 INFO org.apache.hadoop.yarn.server.resourcemanager.scheduler.capacity.CapacityScheduler: Null container completed...
2015-01-14 20:07:21,264 INFO org.apache.hadoop.yarn.server.resourcemanager.scheduler.capacity.CapacityScheduler: Null container completed...
2015-01-14 20:07:22,267 INFO org.apache.hadoop.yarn.server.resourcemanager.scheduler.capacity.CapacityScheduler: Null container completed...
2015-01-14 20:07:23,269 INFO org.apache.hadoop.yarn.server.resourcemanager.scheduler.capacity.CapacityScheduler: Null container completed...
2015-01-14 20:07:24,272 INFO org.apache.hadoop.yarn.server.resourcemanager.scheduler.capacity.CapacityScheduler: Null container completed...
2015-01-14 20:07:25,275 INFO org.apache.hadoop.yarn.server.resourcemanager.scheduler.capacity.CapacityScheduler: Null container completed...
2015-01-14 20:07:26,278 INFO org.apache.hadoop.yarn.server.resourcemanager.scheduler.capacity.CapacityScheduler: Null container completed...
2015-01-14 20:07:27,281 INFO org.apache.hadoop.yarn.server.resourcemanager.scheduler.capacity.CapacityScheduler: Null container completed...
2015-01-14 20:07:28,313 INFO org.apache.hadoop.yarn.server.resourcemanager.scheduler.capacity.CapacityScheduler: Null container completed...
2015-01-14 20:07:29,317 INFO org.apache.hadoop.yarn.server.resourcemanager.scheduler.capacity.CapacityScheduler: Null container completed...
2015-01-14 20:07:30,320 INFO org.apache.hadoop.yarn.server.resourcemanager.scheduler.capacity.CapacityScheduler: Null container completed...
2015-01-14 20:07:31,323 INFO org.apache.hadoop.yarn.server.resourcemanager.scheduler.capacity.CapacityScheduler: Null container completed...
2015-01-14 20:07:32,325 INFO org.apache.hadoop.yarn.server.resourcemanager.scheduler.capacity.CapacityScheduler: Null container completed...
2015-01-14 20:07:33,328 INFO org.apache.hadoop.yarn.server.resourcemanager.scheduler.capacity.CapacityScheduler: Null container completed...
2015-01-14 20:07:34,331 INFO org.apache.hadoop.yarn.server.resourcemanager.scheduler.capacity.CapacityScheduler: Null container completed...
2015-01-14 20:07:35,333 INFO org.apache.hadoop.yarn.server.resourcemanager.scheduler.capacity.CapacityScheduler: Null container completed...
2015-01-14 20:07:36,336 INFO org.apache.hadoop.yarn.server.resourcemanager.scheduler.capacity.CapacityScheduler: Null container completed...
2015-01-14 20:07:37,339 INFO org.apache.hadoop.yarn.server.resourcemanager.scheduler.capacity.CapacityScheduler: Null container completed...
2015-01-14 20:07:38,344 INFO org.apache.hadoop.yarn.server.resourcemanager.scheduler.capacity.CapacityScheduler: Null container completed...
2015-01-14 20:07:39,348 INFO org.apache.hadoop.yarn.server.resourcemanager.scheduler.capacity.CapacityScheduler: Null container completed...
2015-01-14 20:07:40,351 INFO org.apache.hadoop.yarn.server.resourcemanager.scheduler.capacity.CapacityScheduler: Null container completed...
2015-01-14 20:07:41,353 INFO org.apache.hadoop.yarn.server.resourcemanager.scheduler.capacity.CapacityScheduler: Null container completed...
2015-01-14 20:07:42,357 INFO org.apache.hadoop.yarn.server.resourcemanager.scheduler.capacity.CapacityScheduler: Null container completed...
2015-01-14 20:07:43,360 INFO org.apache.hadoop.yarn.server.resourcemanager.scheduler.capacity.CapacityScheduler: Null container completed...
2015-01-14 20:07:44,362 INFO org.apache.hadoop.yarn.server.resourcemanager.scheduler.capacity.CapacityScheduler: Null container completed...
2015-01-14 20:07:45,365 INFO org.apache.hadoop.yarn.server.resourcemanager.scheduler.capacity.CapacityScheduler: Null container completed...
2015-01-14 20:07:46,368 INFO org.apache.hadoop.yarn.server.resourcemanager.scheduler.capacity.CapacityScheduler: Null container completed...
2015-01-14 20:07:47,370 INFO org.apache.hadoop.yarn.server.resourcemanager.scheduler.capacity.CapacityScheduler: Null container completed...
2015-01-14 20:07:48,374 INFO org.apache.hadoop.yarn.server.resourcemanager.scheduler.capacity.CapacityScheduler: Null container completed...
2015-01-14 20:07:49,376 INFO org.apache.hadoop.yarn.server.resourcemanager.scheduler.capacity.CapacityScheduler: Null container completed...
2015-01-14 20:07:50,379 INFO org.apache.hadoop.yarn.server.resourcemanager.scheduler.capacity.CapacityScheduler: Null container completed...
2015-01-14 20:07:51,382 INFO org.apache.hadoop.yarn.server.resourcemanager.scheduler.capacity.CapacityScheduler: Null container completed...
2015-01-14 20:07:52,385 INFO org.apache.hadoop.yarn.server.resourcemanager.scheduler.capacity.CapacityScheduler: Null container completed...
2015-01-14 20:07:53,387 INFO org.apache.hadoop.yarn.server.resourcemanager.scheduler.capacity.CapacityScheduler: Null container completed...
2015-01-14 20:07:54,391 INFO org.apache.hadoop.yarn.server.resourcemanager.scheduler.capacity.CapacityScheduler: Null container completed...
2015-01-14 20:07:55,392 INFO org.apache.hadoop.yarn.server.resourcemanager.scheduler.capacity.CapacityScheduler: Null container completed...
2015-01-14 20:07:56,396 INFO org.apache.hadoop.yarn.server.resourcemanager.scheduler.capacity.CapacityScheduler: Null container completed...
2015-01-14 20:07:57,398 INFO org.apache.hadoop.yarn.server.resourcemanager.scheduler.capacity.CapacityScheduler: Null container completed...
2015-01-14 20:07:58,401 INFO org.apache.hadoop.yarn.server.resourcemanager.scheduler.capacity.CapacityScheduler: Null container completed...
2015-01-14 20:07:59,403 INFO org.apache.hadoop.yarn.server.resourcemanager.scheduler.capacity.CapacityScheduler: Null container completed...
2015-01-14 20:08:00,407 INFO org.apache.hadoop.yarn.server.resourcemanager.scheduler.capacity.CapacityScheduler: Null container completed...
2015-01-14 20:08:01,410 INFO org.apache.hadoop.yarn.server.resourcemanager.scheduler.capacity.CapacityScheduler: Null container completed...
2015-01-14 20:08:02,411 INFO org.apache.hadoop.yarn.server.resourcemanager.scheduler.capacity.CapacityScheduler: Null container completed...
2015-01-14 20:08:03,415 INFO org.apache.hadoop.yarn.server.resourcemanager.scheduler.capacity.CapacityScheduler: Null container completed...
2015-01-14 20:08:04,418 INFO org.apache.hadoop.yarn.server.resourcemanager.scheduler.capacity.CapacityScheduler: Null container completed...
2015-01-14 20:08:05,420 INFO org.apache.hadoop.yarn.server.resourcemanager.scheduler.capacity.CapacityScheduler: Null container completed...
2015-01-14 20:08:06,424 INFO org.apache.hadoop.yarn.server.resourcemanager.scheduler.capacity.CapacityScheduler: Null container completed...
2015-01-14 20:08:07,426 INFO org.apache.hadoop.yarn.server.resourcemanager.scheduler.capacity.CapacityScheduler: Null container completed...
2015-01-14 20:08:08,428 INFO org.apache.hadoop.yarn.server.resourcemanager.scheduler.capacity.CapacityScheduler: Null container completed...
2015-01-14 20:08:09,432 INFO org.apache.hadoop.yarn.server.resourcemanager.scheduler.capacity.CapacityScheduler: Null container completed...
2015-01-14 20:08:10,435 INFO org.apache.hadoop.yarn.server.resourcemanager.scheduler.capacity.CapacityScheduler: Null container completed...
2015-01-14 20:08:11,437 INFO org.apache.hadoop.yarn.server.resourcemanager.scheduler.capacity.CapacityScheduler: Null container completed...
2015-01-14 20:08:12,440 INFO org.apache.hadoop.yarn.server.resourcemanager.scheduler.capacity.CapacityScheduler: Null container completed...
2015-01-14 20:08:13,442 INFO org.apache.hadoop.yarn.server.resourcemanager.scheduler.capacity.CapacityScheduler: Null container completed...
2015-01-14 20:08:14,445 INFO org.apache.hadoop.yarn.server.resourcemanager.scheduler.capacity.CapacityScheduler: Null container completed...
2015-01-14 20:08:15,449 INFO org.apache.hadoop.yarn.server.resourcemanager.scheduler.capacity.CapacityScheduler: Null container completed...
2015-01-14 20:08:16,451 INFO org.apache.hadoop.yarn.server.resourcemanager.scheduler.capacity.CapacityScheduler: Null container completed...
2015-01-14 20:08:17,453 INFO org.apache.hadoop.yarn.server.resourcemanager.scheduler.capacity.CapacityScheduler: Null container completed...
2015-01-14 20:08:18,457 INFO org.apache.hadoop.yarn.server.resourcemanager.scheduler.capacity.CapacityScheduler: Null container completed...
2015-01-14 20:08:19,460 INFO org.apache.hadoop.yarn.server.resourcemanager.scheduler.capacity.CapacityScheduler: Null container completed...
2015-01-14 20:08:20,462 INFO org.apache.hadoop.yarn.server.resourcemanager.scheduler.capacity.CapacityScheduler: Null container completed...
2015-01-14 20:08:21,465 INFO org.apache.hadoop.yarn.server.resourcemanager.scheduler.capacity.CapacityScheduler: Null container completed...
2015-01-14 20:08:22,468 INFO org.apache.hadoop.yarn.server.resourcemanager.scheduler.capacity.CapacityScheduler: Null container completed...
2015-01-14 20:08:23,470 INFO org.apache.hadoop.yarn.server.resourcemanager.scheduler.capacity.CapacityScheduler: Null container completed...
2015-01-14 20:08:24,474 INFO org.apache.hadoop.yarn.server.resourcemanager.scheduler.capacity.CapacityScheduler: Null container completed...
2015-01-14 20:08:25,476 INFO org.apache.hadoop.yarn.server.resourcemanager.scheduler.capacity.CapacityScheduler: Null container completed...
2015-01-14 20:08:26,478 INFO org.apache.hadoop.yarn.server.resourcemanager.scheduler.capacity.CapacityScheduler: Null container completed...
2015-01-14 20:08:27,482 INFO org.apache.hadoop.yarn.server.resourcemanager.scheduler.capacity.CapacityScheduler: Null container completed...
2015-01-14 20:08:28,486 INFO org.apache.hadoop.yarn.server.resourcemanager.scheduler.capacity.CapacityScheduler: Null container completed...
2015-01-14 20:08:29,489 INFO org.apache.hadoop.yarn.server.resourcemanager.scheduler.capacity.CapacityScheduler: Null container completed...
2015-01-14 20:08:30,492 INFO org.apache.hadoop.yarn.server.resourcemanager.scheduler.capacity.CapacityScheduler: Null container completed...
2015-01-14 20:08:31,495 INFO org.apache.hadoop.yarn.server.resourcemanager.scheduler.capacity.CapacityScheduler: Null container completed...
2015-01-14 20:08:32,497 INFO org.apache.hadoop.yarn.server.resourcemanager.scheduler.capacity.CapacityScheduler: Null container completed...
2015-01-14 20:08:33,500 INFO org.apache.hadoop.yarn.server.resourcemanager.scheduler.capacity.CapacityScheduler: Null container completed...
2015-01-14 20:08:34,503 INFO org.apache.hadoop.yarn.server.resourcemanager.scheduler.capacity.CapacityScheduler: Null container completed...
2015-01-14 20:08:35,505 INFO org.apache.hadoop.yarn.server.resourcemanager.scheduler.capacity.CapacityScheduler: Null container completed...
2015-01-14 20:08:36,508 INFO org.apache.hadoop.yarn.server.resourcemanager.scheduler.capacity.CapacityScheduler: Null container completed...
2015-01-14 20:08:37,512 INFO org.apache.hadoop.yarn.server.resourcemanager.scheduler.capacity.CapacityScheduler: Null container completed...
2015-01-14 20:08:38,514 INFO org.apache.hadoop.yarn.server.resourcemanager.scheduler.capacity.CapacityScheduler: Null container completed...
2015-01-14 20:08:39,518 INFO org.apache.hadoop.yarn.server.resourcemanager.scheduler.capacity.CapacityScheduler: Null container completed...
2015-01-14 20:08:40,520 INFO org.apache.hadoop.yarn.server.resourcemanager.scheduler.capacity.CapacityScheduler: Null container completed...
2015-01-14 20:08:41,522 INFO org.apache.hadoop.yarn.server.resourcemanager.scheduler.capacity.CapacityScheduler: Null container completed...
2015-01-14 20:08:42,528 INFO org.apache.hadoop.yarn.server.resourcemanager.scheduler.capacity.CapacityScheduler: Null container completed...
2015-01-14 20:08:43,531 INFO org.apache.hadoop.yarn.server.resourcemanager.scheduler.capacity.CapacityScheduler: Null container completed...
2015-01-14 20:08:44,533 INFO org.apache.hadoop.yarn.server.resourcemanager.scheduler.capacity.CapacityScheduler: Null container completed...
2015-01-14 20:08:45,537 INFO org.apache.hadoop.yarn.server.resourcemanager.scheduler.capacity.CapacityScheduler: Null container completed...
2015-01-14 20:08:46,539 INFO org.apache.hadoop.yarn.server.resourcemanager.scheduler.capacity.CapacityScheduler: Null container completed...
2015-01-14 20:08:47,542 INFO org.apache.hadoop.yarn.server.resourcemanager.scheduler.capacity.CapacityScheduler: Null container completed...
2015-01-14 20:08:48,545 INFO org.apache.hadoop.yarn.server.resourcemanager.scheduler.capacity.CapacityScheduler: Null container completed...
2015-01-14 20:08:49,548 INFO org.apache.hadoop.yarn.server.resourcemanager.scheduler.capacity.CapacityScheduler: Null container completed...
2015-01-14 20:08:50,550 INFO org.apache.hadoop.yarn.server.resourcemanager.scheduler.capacity.CapacityScheduler: Null container completed...
2015-01-14 20:08:51,553 INFO org.apache.hadoop.yarn.server.resourcemanager.scheduler.capacity.CapacityScheduler: Null container completed...
2015-01-14 20:08:52,556 INFO org.apache.hadoop.yarn.server.resourcemanager.scheduler.capacity.CapacityScheduler: Null container completed...
2015-01-14 20:08:53,557 INFO org.apache.hadoop.yarn.server.resourcemanager.scheduler.capacity.CapacityScheduler: Null container completed...
2015-01-14 20:08:54,561 INFO org.apache.hadoop.yarn.server.resourcemanager.scheduler.capacity.CapacityScheduler: Null container completed...
2015-01-14 20:08:55,564 INFO org.apache.hadoop.yarn.server.resourcemanager.scheduler.capacity.CapacityScheduler: Null container completed...
2015-01-14 20:08:56,566 INFO org.apache.hadoop.yarn.server.resourcemanager.scheduler.capacity.CapacityScheduler: Null container completed...
2015-01-14 20:08:57,570 INFO org.apache.hadoop.yarn.server.resourcemanager.scheduler.capacity.CapacityScheduler: Null container completed...
2015-01-14 20:08:58,572 INFO org.apache.hadoop.yarn.server.resourcemanager.scheduler.capacity.CapacityScheduler: Null container completed...
2015-01-14 20:08:59,576 INFO org.apache.hadoop.yarn.server.resourcemanager.scheduler.capacity.CapacityScheduler: Null container completed...
2015-01-14 20:09:00,579 INFO org.apache.hadoop.yarn.server.resourcemanager.scheduler.capacity.CapacityScheduler: Null container completed...
2015-01-14 20:09:01,581 INFO org.apache.hadoop.yarn.server.resourcemanager.scheduler.capacity.CapacityScheduler: Null container completed...
2015-01-14 20:09:02,584 INFO org.apache.hadoop.yarn.server.resourcemanager.scheduler.capacity.CapacityScheduler: Null container completed...
2015-01-14 20:09:03,586 INFO org.apache.hadoop.yarn.server.resourcemanager.scheduler.capacity.CapacityScheduler: Null container completed...
2015-01-14 20:09:04,589 INFO org.apache.hadoop.yarn.server.resourcemanager.scheduler.capacity.CapacityScheduler: Null container completed...
2015-01-14 20:09:05,591 INFO org.apache.hadoop.yarn.server.resourcemanager.scheduler.capacity.CapacityScheduler: Null container completed...
2015-01-14 20:09:06,594 INFO org.apache.hadoop.yarn.server.resourcemanager.scheduler.capacity.CapacityScheduler: Null container completed...
2015-01-14 20:09:07,597 INFO org.apache.hadoop.yarn.server.resourcemanager.scheduler.capacity.CapacityScheduler: Null container completed...
2015-01-14 20:09:08,599 INFO org.apache.hadoop.yarn.server.resourcemanager.scheduler.capacity.CapacityScheduler: Null container completed...
2015-01-14 20:09:09,603 INFO org.apache.hadoop.yarn.server.resourcemanager.scheduler.capacity.CapacityScheduler: Null container completed...
2015-01-14 20:09:10,605 INFO org.apache.hadoop.yarn.server.resourcemanager.scheduler.capacity.CapacityScheduler: Null container completed...
2015-01-14 20:09:11,608 INFO org.apache.hadoop.yarn.server.resourcemanager.scheduler.capacity.CapacityScheduler: Null container completed...
2015-01-14 20:09:12,610 INFO org.apache.hadoop.yarn.server.resourcemanager.scheduler.capacity.CapacityScheduler: Null container completed...
2015-01-14 20:09:13,613 INFO org.apache.hadoop.yarn.server.resourcemanager.scheduler.capacity.CapacityScheduler: Null container completed...
2015-01-14 20:09:14,615 INFO org.apache.hadoop.yarn.server.resourcemanager.scheduler.capacity.CapacityScheduler: Null container completed...
2015-01-14 20:09:15,618 INFO org.apache.hadoop.yarn.server.resourcemanager.scheduler.capacity.CapacityScheduler: Null container completed...
2015-01-14 20:09:16,621 INFO org.apache.hadoop.yarn.server.resourcemanager.scheduler.capacity.CapacityScheduler: Null container completed...
2015-01-14 20:09:17,623 INFO org.apache.hadoop.yarn.server.resourcemanager.scheduler.capacity.CapacityScheduler: Null container completed...
2015-01-14 20:09:18,626 INFO org.apache.hadoop.yarn.server.resourcemanager.scheduler.capacity.CapacityScheduler: Null container completed...
2015-01-14 20:09:19,628 INFO org.apache.hadoop.yarn.server.resourcemanager.scheduler.capacity.CapacityScheduler: Null container completed...
2015-01-14 20:09:20,631 INFO org.apache.hadoop.yarn.server.resourcemanager.scheduler.capacity.CapacityScheduler: Null container completed...
2015-01-14 20:09:21,633 INFO org.apache.hadoop.yarn.server.resourcemanager.scheduler.capacity.CapacityScheduler: Null container completed...
2015-01-14 20:09:22,636 INFO org.apache.hadoop.yarn.server.resourcemanager.scheduler.capacity.CapacityScheduler: Null container completed...
2015-01-14 20:09:23,639 INFO org.apache.hadoop.yarn.server.resourcemanager.scheduler.capacity.CapacityScheduler: Null container completed...
2015-01-14 20:09:24,641 INFO org.apache.hadoop.yarn.server.resourcemanager.scheduler.capacity.CapacityScheduler: Null container completed...
2015-01-14 20:09:25,644 INFO org.apache.hadoop.yarn.server.resourcemanager.scheduler.capacity.CapacityScheduler: Null container completed...
2015-01-14 20:09:26,647 INFO org.apache.hadoop.yarn.server.resourcemanager.scheduler.capacity.CapacityScheduler: Null container completed...
2015-01-14 20:09:27,649 INFO org.apache.hadoop.yarn.server.resourcemanager.scheduler.capacity.CapacityScheduler: Null container completed...
2015-01-14 20:09:28,652 INFO org.apache.hadoop.yarn.server.resourcemanager.scheduler.capacity.CapacityScheduler: Null container completed...
2015-01-14 20:09:29,656 INFO org.apache.hadoop.yarn.server.resourcemanager.scheduler.capacity.CapacityScheduler: Null container completed...
2015-01-14 20:09:30,658 INFO org.apache.hadoop.yarn.server.resourcemanager.scheduler.capacity.CapacityScheduler: Null container completed...
2015-01-14 20:09:31,661 INFO org.apache.hadoop.yarn.server.resourcemanager.scheduler.capacity.CapacityScheduler: Null container completed...
2015-01-14 20:09:32,663 INFO org.apache.hadoop.yarn.server.resourcemanager.scheduler.capacity.CapacityScheduler: Null container completed...
2015-01-14 20:09:33,666 INFO org.apache.hadoop.yarn.server.resourcemanager.scheduler.capacity.CapacityScheduler: Null container completed...
2015-01-14 20:09:34,668 INFO org.apache.hadoop.yarn.server.resourcemanager.scheduler.capacity.CapacityScheduler: Null container completed...
2015-01-14 20:09:35,671 INFO org.apache.hadoop.yarn.server.resourcemanager.scheduler.capacity.CapacityScheduler: Null container completed...
2015-01-14 20:09:36,673 INFO org.apache.hadoop.yarn.server.resourcemanager.scheduler.capacity.CapacityScheduler: Null container completed...
2015-01-14 20:09:37,676 INFO org.apache.hadoop.yarn.server.resourcemanager.scheduler.capacity.CapacityScheduler: Null container completed...
2015-01-14 20:09:38,679 INFO org.apache.hadoop.yarn.server.resourcemanager.scheduler.capacity.CapacityScheduler: Null container completed...
2015-01-14 20:09:39,681 INFO org.apache.hadoop.yarn.server.resourcemanager.scheduler.capacity.CapacityScheduler: Null container completed...
2015-01-14 20:09:40,683 INFO org.apache.hadoop.yarn.server.resourcemanager.scheduler.capacity.CapacityScheduler: Null container completed...
2015-01-14 20:09:41,687 INFO org.apache.hadoop.yarn.server.resourcemanager.scheduler.capacity.CapacityScheduler: Null container completed...
2015-01-14 20:09:42,690 INFO org.apache.hadoop.yarn.server.resourcemanager.scheduler.capacity.CapacityScheduler: Null container completed...
2015-01-14 20:09:43,692 INFO org.apache.hadoop.yarn.server.resourcemanager.scheduler.capacity.CapacityScheduler: Null container completed...
2015-01-14 20:09:44,695 INFO org.apache.hadoop.yarn.server.resourcemanager.scheduler.capacity.CapacityScheduler: Null container completed...
2015-01-14 20:09:45,697 INFO org.apache.hadoop.yarn.server.resourcemanager.scheduler.capacity.CapacityScheduler: Null container completed...
2015-01-14 20:09:46,700 INFO org.apache.hadoop.yarn.server.resourcemanager.scheduler.capacity.CapacityScheduler: Null container completed...
2015-01-14 20:09:47,704 INFO org.apache.hadoop.yarn.server.resourcemanager.scheduler.capacity.CapacityScheduler: Null container completed...
2015-01-14 20:09:48,705 INFO org.apache.hadoop.yarn.server.resourcemanager.scheduler.capacity.CapacityScheduler: Null container completed...
2015-01-14 20:09:49,732 INFO org.apache.hadoop.yarn.server.resourcemanager.scheduler.capacity.CapacityScheduler: Null container completed...
2015-01-14 20:09:50,735 INFO org.apache.hadoop.yarn.server.resourcemanager.scheduler.capacity.CapacityScheduler: Null container completed...
2015-01-14 20:09:51,738 INFO org.apache.hadoop.yarn.server.resourcemanager.scheduler.capacity.CapacityScheduler: Null container completed...
2015-01-14 20:09:52,740 INFO org.apache.hadoop.yarn.server.resourcemanager.scheduler.capacity.CapacityScheduler: Null container completed...
2015-01-14 20:09:53,743 INFO org.apache.hadoop.yarn.server.resourcemanager.scheduler.capacity.CapacityScheduler: Null container completed...
2015-01-14 20:09:54,745 INFO org.apache.hadoop.yarn.server.resourcemanager.scheduler.capacity.CapacityScheduler: Null container completed...
2015-01-14 20:09:55,748 INFO org.apache.hadoop.yarn.server.resourcemanager.scheduler.capacity.CapacityScheduler: Null container completed...
2015-01-14 20:09:56,750 INFO org.apache.hadoop.yarn.server.resourcemanager.scheduler.capacity.CapacityScheduler: Null container completed...
2015-01-14 20:09:57,753 INFO org.apache.hadoop.yarn.server.resourcemanager.scheduler.capacity.CapacityScheduler: Null container completed...
2015-01-14 20:09:58,756 INFO org.apache.hadoop.yarn.server.resourcemanager.scheduler.capacity.CapacityScheduler: Null container completed...
2015-01-14 20:09:59,758 INFO org.apache.hadoop.yarn.server.resourcemanager.scheduler.capacity.CapacityScheduler: Null container completed...
2015-01-14 20:10:00,761 INFO org.apache.hadoop.yarn.server.resourcemanager.scheduler.capacity.CapacityScheduler: Null container completed...
2015-01-14 20:10:01,763 INFO org.apache.hadoop.yarn.server.resourcemanager.scheduler.capacity.CapacityScheduler: Null container completed...
2015-01-14 20:10:02,766 INFO org.apache.hadoop.yarn.server.resourcemanager.scheduler.capacity.CapacityScheduler: Null container completed...
2015-01-14 20:10:03,768 INFO org.apache.hadoop.yarn.server.resourcemanager.scheduler.capacity.CapacityScheduler: Null container completed...
2015-01-14 20:10:04,771 INFO org.apache.hadoop.yarn.server.resourcemanager.scheduler.capacity.CapacityScheduler: Null container completed...
2015-01-14 20:10:05,774 INFO org.apache.hadoop.yarn.server.resourcemanager.scheduler.capacity.CapacityScheduler: Null container completed...
2015-01-14 20:10:06,776 INFO org.apache.hadoop.yarn.server.resourcemanager.scheduler.capacity.CapacityScheduler: Null container completed...
2015-01-14 20:10:07,779 INFO org.apache.hadoop.yarn.server.resourcemanager.scheduler.capacity.CapacityScheduler: Null container completed...
2015-01-14 20:10:08,781 INFO org.apache.hadoop.yarn.server.resourcemanager.scheduler.capacity.CapacityScheduler: Null container completed...
2015-01-14 20:10:09,784 INFO org.apache.hadoop.yarn.server.resourcemanager.scheduler.capacity.CapacityScheduler: Null container completed...
2015-01-14 20:10:10,787 INFO org.apache.hadoop.yarn.server.resourcemanager.scheduler.capacity.CapacityScheduler: Null container completed...
2015-01-14 20:10:11,789 INFO org.apache.hadoop.yarn.server.resourcemanager.scheduler.capacity.CapacityScheduler: Null container completed...
2015-01-14 20:10:12,792 INFO org.apache.hadoop.yarn.server.resourcemanager.scheduler.capacity.CapacityScheduler: Null container completed...
2015-01-14 20:10:13,794 INFO org.apache.hadoop.yarn.server.resourcemanager.scheduler.capacity.CapacityScheduler: Null container completed...
2015-01-14 20:10:14,797 INFO org.apache.hadoop.yarn.server.resourcemanager.scheduler.capacity.CapacityScheduler: Null container completed...
2015-01-14 20:10:15,800 INFO org.apache.hadoop.yarn.server.resourcemanager.scheduler.capacity.CapacityScheduler: Null container completed...
2015-01-14 20:10:16,802 INFO org.apache.hadoop.yarn.server.resourcemanager.scheduler.capacity.CapacityScheduler: Null container completed...
2015-01-14 20:10:17,805 INFO org.apache.hadoop.yarn.server.resourcemanager.scheduler.capacity.CapacityScheduler: Null container completed...
2015-01-14 20:10:18,807 INFO org.apache.hadoop.yarn.server.resourcemanager.scheduler.capacity.CapacityScheduler: Null container completed...
2015-01-14 20:10:19,810 INFO org.apache.hadoop.yarn.server.resourcemanager.scheduler.capacity.CapacityScheduler: Null container completed...
2015-01-14 20:10:20,813 INFO org.apache.hadoop.yarn.server.resourcemanager.scheduler.capacity.CapacityScheduler: Null container completed...
2015-01-14 20:10:21,815 INFO org.apache.hadoop.yarn.server.resourcemanager.scheduler.capacity.CapacityScheduler: Null container completed...
2015-01-14 20:10:22,818 INFO org.apache.hadoop.yarn.server.resourcemanager.scheduler.capacity.CapacityScheduler: Null container completed...
2015-01-14 20:10:23,820 INFO org.apache.hadoop.yarn.server.resourcemanager.scheduler.capacity.CapacityScheduler: Null container completed...
2015-01-14 20:10:24,823 INFO org.apache.hadoop.yarn.server.resourcemanager.scheduler.capacity.CapacityScheduler: Null container completed...
2015-01-14 20:10:25,826 INFO org.apache.hadoop.yarn.server.resourcemanager.scheduler.capacity.CapacityScheduler: Null container completed...
2015-01-14 20:10:26,828 INFO org.apache.hadoop.yarn.server.resourcemanager.scheduler.capacity.CapacityScheduler: Null container completed...
2015-01-14 20:10:27,831 INFO org.apache.hadoop.yarn.server.resourcemanager.scheduler.capacity.CapacityScheduler: Null container completed...
2015-01-14 20:10:28,833 INFO org.apache.hadoop.yarn.server.resourcemanager.scheduler.capacity.CapacityScheduler: Null container completed...
2015-01-14 20:10:29,836 INFO org.apache.hadoop.yarn.server.resourcemanager.scheduler.capacity.CapacityScheduler: Null container completed...
2015-01-14 20:10:30,838 INFO org.apache.hadoop.yarn.server.resourcemanager.scheduler.capacity.CapacityScheduler: Null container completed...
2015-01-14 20:10:31,841 INFO org.apache.hadoop.yarn.server.resourcemanager.scheduler.capacity.CapacityScheduler: Null container completed...
2015-01-14 20:10:32,843 INFO org.apache.hadoop.yarn.server.resourcemanager.scheduler.capacity.CapacityScheduler: Null container completed...
2015-01-14 20:10:33,848 INFO org.apache.hadoop.yarn.server.resourcemanager.scheduler.capacity.CapacityScheduler: Null container completed...
2015-01-14 20:10:34,850 INFO org.apache.hadoop.yarn.server.resourcemanager.scheduler.capacity.CapacityScheduler: Null container completed...
2015-01-14 20:10:35,852 INFO org.apache.hadoop.yarn.server.resourcemanager.scheduler.capacity.CapacityScheduler: Null container completed...
2015-01-14 20:10:36,856 INFO org.apache.hadoop.yarn.server.resourcemanager.scheduler.capacity.CapacityScheduler: Null container completed...
2015-01-14 20:10:37,860 INFO org.apache.hadoop.yarn.server.resourcemanager.scheduler.capacity.CapacityScheduler: Null container completed...
2015-01-14 20:10:38,861 INFO org.apache.hadoop.yarn.server.resourcemanager.scheduler.capacity.CapacityScheduler: Null container completed...
2015-01-14 20:10:39,865 INFO org.apache.hadoop.yarn.server.resourcemanager.scheduler.capacity.CapacityScheduler: Null container completed...
2015-01-14 20:10:40,868 INFO org.apache.hadoop.yarn.server.resourcemanager.scheduler.capacity.CapacityScheduler: Null container completed...
2015-01-14 20:10:41,869 INFO org.apache.hadoop.yarn.server.resourcemanager.scheduler.capacity.CapacityScheduler: Null container completed...
2015-01-14 20:10:42,874 INFO org.apache.hadoop.yarn.server.resourcemanager.scheduler.capacity.CapacityScheduler: Null container completed...
2015-01-14 20:10:43,876 INFO org.apache.hadoop.yarn.server.resourcemanager.scheduler.capacity.CapacityScheduler: Null container completed...
2015-01-14 20:10:44,879 INFO org.apache.hadoop.yarn.server.resourcemanager.scheduler.capacity.CapacityScheduler: Null container completed...
2015-01-14 20:10:45,884 INFO org.apache.hadoop.yarn.server.resourcemanager.scheduler.capacity.CapacityScheduler: Null container completed...
2015-01-14 20:10:46,886 INFO org.apache.hadoop.yarn.server.resourcemanager.scheduler.capacity.CapacityScheduler: Null container completed...
2015-01-14 20:10:47,888 INFO org.apache.hadoop.yarn.server.resourcemanager.scheduler.capacity.CapacityScheduler: Null container completed...
2015-01-14 20:10:48,892 INFO org.apache.hadoop.yarn.server.resourcemanager.scheduler.capacity.CapacityScheduler: Null container completed...
2015-01-14 20:10:49,894 INFO org.apache.hadoop.yarn.server.resourcemanager.scheduler.capacity.CapacityScheduler: Null container completed...
2015-01-14 20:10:50,896 INFO org.apache.hadoop.yarn.server.resourcemanager.scheduler.capacity.CapacityScheduler: Null container completed...
2015-01-14 20:10:51,900 INFO org.apache.hadoop.yarn.server.resourcemanager.scheduler.capacity.CapacityScheduler: Null container completed...
2015-01-14 20:10:52,903 INFO org.apache.hadoop.yarn.server.resourcemanager.scheduler.capacity.CapacityScheduler: Null container completed...
2015-01-14 20:10:53,905 INFO org.apache.hadoop.yarn.server.resourcemanager.scheduler.capacity.CapacityScheduler: Null container completed...
2015-01-14 20:10:54,908 INFO org.apache.hadoop.yarn.server.resourcemanager.scheduler.capacity.CapacityScheduler: Null container completed...
2015-01-14 20:10:55,911 INFO org.apache.hadoop.yarn.server.resourcemanager.scheduler.capacity.CapacityScheduler: Null container completed...
2015-01-14 20:10:56,916 INFO org.apache.hadoop.yarn.server.resourcemanager.scheduler.capacity.CapacityScheduler: Null container completed...
2015-01-14 20:10:57,919 INFO org.apache.hadoop.yarn.server.resourcemanager.scheduler.capacity.CapacityScheduler: Null container completed...
2015-01-14 20:10:58,921 INFO org.apache.hadoop.yarn.server.resourcemanager.scheduler.capacity.CapacityScheduler: Null container completed...
2015-01-14 20:10:59,923 INFO org.apache.hadoop.yarn.server.resourcemanager.scheduler.capacity.CapacityScheduler: Null container completed...
2015-01-14 20:11:00,927 INFO org.apache.hadoop.yarn.server.resourcemanager.scheduler.capacity.CapacityScheduler: Null container completed...
2015-01-14 20:11:01,929 INFO org.apache.hadoop.yarn.server.resourcemanager.scheduler.capacity.CapacityScheduler: Null container completed...
2015-01-14 20:11:02,931 INFO org.apache.hadoop.yarn.server.resourcemanager.scheduler.capacity.CapacityScheduler: Null container completed...
2015-01-14 20:11:03,935 INFO org.apache.hadoop.yarn.server.resourcemanager.scheduler.capacity.CapacityScheduler: Null container completed...
2015-01-14 20:11:04,938 INFO org.apache.hadoop.yarn.server.resourcemanager.scheduler.capacity.CapacityScheduler: Null container completed...
2015-01-14 20:11:05,941 INFO org.apache.hadoop.yarn.server.resourcemanager.scheduler.capacity.CapacityScheduler: Null container completed...
2015-01-14 20:11:06,943 INFO org.apache.hadoop.yarn.server.resourcemanager.scheduler.capacity.CapacityScheduler: Null container completed...
2015-01-14 20:11:07,946 INFO org.apache.hadoop.yarn.server.resourcemanager.scheduler.capacity.CapacityScheduler: Null container completed...
2015-01-14 20:11:08,948 INFO org.apache.hadoop.yarn.server.resourcemanager.scheduler.capacity.CapacityScheduler: Null container completed...
2015-01-14 20:11:09,952 INFO org.apache.hadoop.yarn.server.resourcemanager.scheduler.capacity.CapacityScheduler: Null container completed...
2015-01-14 20:11:10,954 INFO org.apache.hadoop.yarn.server.resourcemanager.scheduler.capacity.CapacityScheduler: Null container completed...
2015-01-14 20:11:11,956 INFO org.apache.hadoop.yarn.server.resourcemanager.scheduler.capacity.CapacityScheduler: Null container completed...
2015-01-14 20:11:12,960 INFO org.apache.hadoop.yarn.server.resourcemanager.scheduler.capacity.CapacityScheduler: Null container completed...
2015-01-14 20:11:13,965 INFO org.apache.hadoop.yarn.server.resourcemanager.scheduler.capacity.CapacityScheduler: Null container completed...
2015-01-14 20:11:14,969 INFO org.apache.hadoop.yarn.server.resourcemanager.scheduler.capacity.CapacityScheduler: Null container completed...
2015-01-14 20:11:15,972 INFO org.apache.hadoop.yarn.server.resourcemanager.scheduler.capacity.CapacityScheduler: Null container completed...
2015-01-14 20:11:16,974 INFO org.apache.hadoop.yarn.server.resourcemanager.scheduler.capacity.CapacityScheduler: Null container completed...
2015-01-14 20:11:17,980 INFO org.apache.hadoop.yarn.server.resourcemanager.scheduler.capacity.CapacityScheduler: Null container completed...
2015-01-14 20:11:18,983 INFO org.apache.hadoop.yarn.server.resourcemanager.scheduler.capacity.CapacityScheduler: Null container completed...
2015-01-14 20:11:19,986 INFO org.apache.hadoop.yarn.server.resourcemanager.scheduler.capacity.CapacityScheduler: Null container completed...
2015-01-14 20:11:20,988 INFO org.apache.hadoop.yarn.server.resourcemanager.scheduler.capacity.CapacityScheduler: Null container completed...
2015-01-14 20:11:21,992 INFO org.apache.hadoop.yarn.server.resourcemanager.scheduler.capacity.CapacityScheduler: Null container completed...
2015-01-14 20:11:22,995 INFO org.apache.hadoop.yarn.server.resourcemanager.scheduler.capacity.CapacityScheduler: Null container completed...
2015-01-14 20:11:23,997 INFO org.apache.hadoop.yarn.server.resourcemanager.scheduler.capacity.CapacityScheduler: Null container completed...
2015-01-14 20:11:25,000 INFO org.apache.hadoop.yarn.server.resourcemanager.scheduler.capacity.CapacityScheduler: Null container completed...
2015-01-14 20:11:26,003 INFO org.apache.hadoop.yarn.server.resourcemanager.scheduler.capacity.CapacityScheduler: Null container completed...
2015-01-14 20:11:27,005 INFO org.apache.hadoop.yarn.server.resourcemanager.scheduler.capacity.CapacityScheduler: Null container completed...
2015-01-14 20:11:28,010 INFO org.apache.hadoop.yarn.server.resourcemanager.scheduler.capacity.CapacityScheduler: Null container completed...
2015-01-14 20:11:29,013 INFO org.apache.hadoop.yarn.server.resourcemanager.scheduler.capacity.CapacityScheduler: Null container completed...
2015-01-14 20:11:30,024 INFO org.apache.hadoop.yarn.server.resourcemanager.scheduler.capacity.CapacityScheduler: Null container completed...
2015-01-14 20:11:31,034 INFO org.apache.hadoop.yarn.server.resourcemanager.scheduler.capacity.CapacityScheduler: Null container completed...
2015-01-14 20:11:32,031 INFO org.apache.hadoop.yarn.server.resourcemanager.scheduler.capacity.CapacityScheduler: Null container completed...
2015-01-14 20:11:33,033 INFO org.apache.hadoop.yarn.server.resourcemanager.scheduler.capacity.CapacityScheduler: Null container completed...
2015-01-14 20:11:34,036 INFO org.apache.hadoop.yarn.server.resourcemanager.scheduler.capacity.CapacityScheduler: Null container completed...
2015-01-14 20:11:35,039 INFO org.apache.hadoop.yarn.server.resourcemanager.scheduler.capacity.CapacityScheduler: Null container completed...
2015-01-14 20:11:36,041 INFO org.apache.hadoop.yarn.server.resourcemanager.scheduler.capacity.CapacityScheduler: Null container completed...
2015-01-14 20:11:37,044 INFO org.apache.hadoop.yarn.server.resourcemanager.scheduler.capacity.CapacityScheduler: Null container completed...
2015-01-14 20:11:38,047 INFO org.apache.hadoop.yarn.server.resourcemanager.scheduler.capacity.CapacityScheduler: Null container completed...
2015-01-14 20:11:39,049 INFO org.apache.hadoop.yarn.server.resourcemanager.scheduler.capacity.CapacityScheduler: Null container completed...
2015-01-14 20:11:40,052 INFO org.apache.hadoop.yarn.server.resourcemanager.scheduler.capacity.CapacityScheduler: Null container completed...
2015-01-14 20:11:41,055 INFO org.apache.hadoop.yarn.server.resourcemanager.scheduler.capacity.CapacityScheduler: Null container completed...
2015-01-14 20:11:42,056 INFO org.apache.hadoop.yarn.server.resourcemanager.scheduler.capacity.CapacityScheduler: Null container completed...
2015-01-14 20:11:43,060 INFO org.apache.hadoop.yarn.server.resourcemanager.scheduler.capacity.CapacityScheduler: Null container completed...
2015-01-14 20:11:44,063 INFO org.apache.hadoop.yarn.server.resourcemanager.scheduler.capacity.CapacityScheduler: Null container completed...
2015-01-14 20:11:45,065 INFO org.apache.hadoop.yarn.server.resourcemanager.scheduler.capacity.CapacityScheduler: Null container completed...
2015-01-14 20:11:46,068 INFO org.apache.hadoop.yarn.server.resourcemanager.scheduler.capacity.CapacityScheduler: Null container completed...
2015-01-14 20:11:47,071 INFO org.apache.hadoop.yarn.server.resourcemanager.scheduler.capacity.CapacityScheduler: Null container completed...
2015-01-14 20:11:48,073 INFO org.apache.hadoop.yarn.server.resourcemanager.scheduler.capacity.CapacityScheduler: Null container completed...
2015-01-14 20:11:49,076 INFO org.apache.hadoop.yarn.server.resourcemanager.scheduler.capacity.CapacityScheduler: Null container completed...
2015-01-14 20:11:50,078 INFO org.apache.hadoop.yarn.server.resourcemanager.scheduler.capacity.CapacityScheduler: Null container completed...
2015-01-14 20:11:51,080 INFO org.apache.hadoop.yarn.server.resourcemanager.scheduler.capacity.CapacityScheduler: Null container completed...
2015-01-14 20:11:52,084 INFO org.apache.hadoop.yarn.server.resourcemanager.scheduler.capacity.CapacityScheduler: Null container completed...
2015-01-14 20:11:53,086 INFO org.apache.hadoop.yarn.server.resourcemanager.scheduler.capacity.CapacityScheduler: Null container completed...
2015-01-14 20:11:54,088 INFO org.apache.hadoop.yarn.server.resourcemanager.scheduler.capacity.CapacityScheduler: Null container completed...
2015-01-14 20:11:55,092 INFO org.apache.hadoop.yarn.server.resourcemanager.scheduler.capacity.CapacityScheduler: Null container completed...
2015-01-14 20:11:56,094 INFO org.apache.hadoop.yarn.server.resourcemanager.scheduler.capacity.CapacityScheduler: Null container completed...
2015-01-14 20:11:57,096 INFO org.apache.hadoop.yarn.server.resourcemanager.scheduler.capacity.CapacityScheduler: Null container completed...
2015-01-14 20:11:58,100 INFO org.apache.hadoop.yarn.server.resourcemanager.scheduler.capacity.CapacityScheduler: Null container completed...
2015-01-14 20:11:59,103 INFO org.apache.hadoop.yarn.server.resourcemanager.scheduler.capacity.CapacityScheduler: Null container completed...
2015-01-14 20:12:00,105 INFO org.apache.hadoop.yarn.server.resourcemanager.scheduler.capacity.CapacityScheduler: Null container completed...
2015-01-14 20:12:01,108 INFO org.apache.hadoop.yarn.server.resourcemanager.scheduler.capacity.CapacityScheduler: Null container completed...
2015-01-14 20:12:02,111 INFO org.apache.hadoop.yarn.server.resourcemanager.scheduler.capacity.CapacityScheduler: Null container completed...
2015-01-14 20:12:03,113 INFO org.apache.hadoop.yarn.server.resourcemanager.scheduler.capacity.CapacityScheduler: Null container completed...
2015-01-14 20:12:04,116 INFO org.apache.hadoop.yarn.server.resourcemanager.scheduler.capacity.CapacityScheduler: Null container completed...
2015-01-14 20:12:05,119 INFO org.apache.hadoop.yarn.server.resourcemanager.scheduler.capacity.CapacityScheduler: Null container completed...
2015-01-14 20:12:06,120 INFO org.apache.hadoop.yarn.server.resourcemanager.scheduler.capacity.CapacityScheduler: Null container completed...
2015-01-14 20:12:07,124 INFO org.apache.hadoop.yarn.server.resourcemanager.scheduler.capacity.CapacityScheduler: Null container completed...
2015-01-14 20:12:08,126 INFO org.apache.hadoop.yarn.server.resourcemanager.scheduler.capacity.CapacityScheduler: Null container completed...
2015-01-14 20:12:09,128 INFO org.apache.hadoop.yarn.server.resourcemanager.scheduler.capacity.CapacityScheduler: Null container completed...
2015-01-14 20:12:10,131 INFO org.apache.hadoop.yarn.server.resourcemanager.scheduler.capacity.CapacityScheduler: Null container completed...
2015-01-14 20:12:11,135 INFO org.apache.hadoop.yarn.server.resourcemanager.scheduler.capacity.CapacityScheduler: Null container completed...
2015-01-14 20:12:12,137 INFO org.apache.hadoop.yarn.server.resourcemanager.scheduler.capacity.CapacityScheduler: Null container completed...
2015-01-14 20:12:13,141 INFO org.apache.hadoop.yarn.server.resourcemanager.scheduler.capacity.CapacityScheduler: Null container completed...
2015-01-14 20:12:14,143 INFO org.apache.hadoop.yarn.server.resourcemanager.scheduler.capacity.CapacityScheduler: Null container completed...
2015-01-14 20:12:15,145 INFO org.apache.hadoop.yarn.server.resourcemanager.scheduler.capacity.CapacityScheduler: Null container completed...
2015-01-14 20:12:16,148 INFO org.apache.hadoop.yarn.server.resourcemanager.scheduler.capacity.CapacityScheduler: Null container completed...
2015-01-14 20:12:17,150 INFO org.apache.hadoop.yarn.server.resourcemanager.scheduler.capacity.CapacityScheduler: Null container completed...
2015-01-14 20:12:18,154 INFO org.apache.hadoop.yarn.server.resourcemanager.scheduler.capacity.CapacityScheduler: Null container completed...
2015-01-14 20:12:19,160 INFO org.apache.hadoop.yarn.server.resourcemanager.scheduler.capacity.CapacityScheduler: Null container completed...
2015-01-14 20:12:20,160 INFO org.apache.hadoop.yarn.server.resourcemanager.scheduler.capacity.CapacityScheduler: Null container completed...
2015-01-14 20:12:21,161 INFO org.apache.hadoop.yarn.server.resourcemanager.scheduler.capacity.CapacityScheduler: Null container completed...
2015-01-14 20:12:22,165 INFO org.apache.hadoop.yarn.server.resourcemanager.scheduler.capacity.CapacityScheduler: Null container completed...
2015-01-14 20:12:23,167 INFO org.apache.hadoop.yarn.server.resourcemanager.scheduler.capacity.CapacityScheduler: Null container completed...
2015-01-14 20:12:24,169 INFO org.apache.hadoop.yarn.server.resourcemanager.scheduler.capacity.CapacityScheduler: Null container completed...
2015-01-14 20:12:25,173 INFO org.apache.hadoop.yarn.server.resourcemanager.scheduler.capacity.CapacityScheduler: Null container completed...
2015-01-14 20:12:26,175 INFO org.apache.hadoop.yarn.server.resourcemanager.scheduler.capacity.CapacityScheduler: Null container completed...
2015-01-14 20:12:27,177 INFO org.apache.hadoop.yarn.server.resourcemanager.scheduler.capacity.CapacityScheduler: Null container completed...
2015-01-14 20:12:28,182 INFO org.apache.hadoop.yarn.server.resourcemanager.scheduler.capacity.CapacityScheduler: Null container completed...
2015-01-14 20:12:29,188 INFO org.apache.hadoop.yarn.server.resourcemanager.scheduler.capacity.CapacityScheduler: Null container completed...
2015-01-14 20:12:30,192 INFO org.apache.hadoop.yarn.server.resourcemanager.scheduler.capacity.CapacityScheduler: Null container completed...
2015-01-14 20:12:31,199 INFO org.apache.hadoop.yarn.server.resourcemanager.scheduler.capacity.CapacityScheduler: Null container completed...
2015-01-14 20:12:32,202 INFO org.apache.hadoop.yarn.server.resourcemanager.scheduler.capacity.CapacityScheduler: Null container completed...
2015-01-14 20:12:33,204 INFO org.apache.hadoop.yarn.server.resourcemanager.scheduler.capacity.CapacityScheduler: Null container completed...
2015-01-14 20:12:34,208 INFO org.apache.hadoop.yarn.server.resourcemanager.scheduler.capacity.CapacityScheduler: Null container completed...
2015-01-14 20:12:35,210 INFO org.apache.hadoop.yarn.server.resourcemanager.scheduler.capacity.CapacityScheduler: Null container completed...
2015-01-14 20:12:36,212 INFO org.apache.hadoop.yarn.server.resourcemanager.scheduler.capacity.CapacityScheduler: Null container completed...
2015-01-14 20:12:37,215 INFO org.apache.hadoop.yarn.server.resourcemanager.scheduler.capacity.CapacityScheduler: Null container completed...
2015-01-14 20:12:38,218 INFO org.apache.hadoop.yarn.server.resourcemanager.scheduler.capacity.CapacityScheduler: Null container completed...
2015-01-14 20:12:39,220 INFO org.apache.hadoop.yarn.server.resourcemanager.scheduler.capacity.CapacityScheduler: Null container completed...
2015-01-14 20:12:40,223 INFO org.apache.hadoop.yarn.server.resourcemanager.scheduler.capacity.CapacityScheduler: Null container completed...
2015-01-14 20:12:41,226 INFO org.apache.hadoop.yarn.server.resourcemanager.scheduler.capacity.CapacityScheduler: Null container completed...
2015-01-14 20:12:42,228 INFO org.apache.hadoop.yarn.server.resourcemanager.scheduler.capacity.CapacityScheduler: Null container completed...
2015-01-14 20:12:43,231 INFO org.apache.hadoop.yarn.server.resourcemanager.scheduler.capacity.CapacityScheduler: Null container completed...
2015-01-14 20:12:44,234 INFO org.apache.hadoop.yarn.server.resourcemanager.scheduler.capacity.CapacityScheduler: Null container completed...
2015-01-14 20:12:45,236 INFO org.apache.hadoop.yarn.server.resourcemanager.scheduler.capacity.CapacityScheduler: Null container completed...
2015-01-14 20:12:46,239 INFO org.apache.hadoop.yarn.server.resourcemanager.scheduler.capacity.CapacityScheduler: Null container completed...
2015-01-14 20:12:47,241 INFO org.apache.hadoop.yarn.server.resourcemanager.scheduler.capacity.CapacityScheduler: Null container completed...
2015-01-14 20:12:48,244 INFO org.apache.hadoop.yarn.server.resourcemanager.scheduler.capacity.CapacityScheduler: Null container completed...
2015-01-14 20:12:49,247 INFO org.apache.hadoop.yarn.server.resourcemanager.scheduler.capacity.CapacityScheduler: Null container completed...
2015-01-14 20:12:50,250 INFO org.apache.hadoop.yarn.server.resourcemanager.scheduler.capacity.CapacityScheduler: Null container completed...
2015-01-14 20:12:51,251 INFO org.apache.hadoop.yarn.server.resourcemanager.scheduler.capacity.CapacityScheduler: Null container completed...
2015-01-14 20:12:52,255 INFO org.apache.hadoop.yarn.server.resourcemanager.scheduler.capacity.CapacityScheduler: Null container completed...
2015-01-14 20:12:53,257 INFO org.apache.hadoop.yarn.server.resourcemanager.scheduler.capacity.CapacityScheduler: Null container completed...
2015-01-14 20:12:54,259 INFO org.apache.hadoop.yarn.server.resourcemanager.scheduler.capacity.CapacityScheduler: Null container completed...
2015-01-14 20:12:55,263 INFO org.apache.hadoop.yarn.server.resourcemanager.scheduler.capacity.CapacityScheduler: Null container completed...
2015-01-14 20:12:56,265 INFO org.apache.hadoop.yarn.server.resourcemanager.scheduler.capacity.CapacityScheduler: Null container completed...
2015-01-14 20:12:57,267 INFO org.apache.hadoop.yarn.server.resourcemanager.scheduler.capacity.CapacityScheduler: Null container completed...
2015-01-14 20:12:58,271 INFO org.apache.hadoop.yarn.server.resourcemanager.scheduler.capacity.CapacityScheduler: Null container completed...
2015-01-14 20:12:59,273 INFO org.apache.hadoop.yarn.server.resourcemanager.scheduler.capacity.CapacityScheduler: Null container completed...
2015-01-14 20:13:00,275 INFO org.apache.hadoop.yarn.server.resourcemanager.scheduler.capacity.CapacityScheduler: Null container completed...
2015-01-14 20:13:01,278 INFO org.apache.hadoop.yarn.server.resourcemanager.scheduler.capacity.CapacityScheduler: Null container completed...
2015-01-14 20:13:02,281 INFO org.apache.hadoop.yarn.server.resourcemanager.scheduler.capacity.CapacityScheduler: Null container completed...
2015-01-14 20:13:03,283 INFO org.apache.hadoop.yarn.server.resourcemanager.scheduler.capacity.CapacityScheduler: Null container completed...
2015-01-14 20:13:04,288 INFO org.apache.hadoop.yarn.server.resourcemanager.scheduler.capacity.CapacityScheduler: Null container completed...
2015-01-14 20:13:05,290 INFO org.apache.hadoop.yarn.server.resourcemanager.scheduler.capacity.CapacityScheduler: Null container completed...
2015-01-14 20:13:06,292 INFO org.apache.hadoop.yarn.server.resourcemanager.scheduler.capacity.CapacityScheduler: Null container completed...
2015-01-14 20:13:07,296 INFO org.apache.hadoop.yarn.server.resourcemanager.scheduler.capacity.CapacityScheduler: Null container completed...
2015-01-14 20:13:08,298 INFO org.apache.hadoop.yarn.server.resourcemanager.scheduler.capacity.CapacityScheduler: Null container completed...
2015-01-14 20:13:09,300 INFO org.apache.hadoop.yarn.server.resourcemanager.scheduler.capacity.CapacityScheduler: Null container completed...
2015-01-14 20:13:10,304 INFO org.apache.hadoop.yarn.server.resourcemanager.scheduler.capacity.CapacityScheduler: Null container completed...
2015-01-14 20:13:11,306 INFO org.apache.hadoop.yarn.server.resourcemanager.scheduler.capacity.CapacityScheduler: Null container completed...
2015-01-14 20:13:12,308 INFO org.apache.hadoop.yarn.server.resourcemanager.scheduler.capacity.CapacityScheduler: Null container completed...
2015-01-14 20:13:13,312 INFO org.apache.hadoop.yarn.server.resourcemanager.scheduler.capacity.CapacityScheduler: Null container completed...
2015-01-14 20:13:14,314 INFO org.apache.hadoop.yarn.server.resourcemanager.scheduler.capacity.CapacityScheduler: Null container completed...
2015-01-14 20:13:15,316 INFO org.apache.hadoop.yarn.server.resourcemanager.scheduler.capacity.CapacityScheduler: Null container completed...
2015-01-14 20:13:16,320 INFO org.apache.hadoop.yarn.server.resourcemanager.scheduler.capacity.CapacityScheduler: Null container completed...
2015-01-14 20:13:17,322 INFO org.apache.hadoop.yarn.server.resourcemanager.scheduler.capacity.CapacityScheduler: Null container completed...
2015-01-14 20:13:18,324 INFO org.apache.hadoop.yarn.server.resourcemanager.scheduler.capacity.CapacityScheduler: Null container completed...
2015-01-14 20:13:19,328 INFO org.apache.hadoop.yarn.server.resourcemanager.scheduler.capacity.CapacityScheduler: Null container completed...
2015-01-14 20:13:20,330 INFO org.apache.hadoop.yarn.server.resourcemanager.scheduler.capacity.CapacityScheduler: Null container completed...
2015-01-14 20:13:21,332 INFO org.apache.hadoop.yarn.server.resourcemanager.scheduler.capacity.CapacityScheduler: Null container completed...
2015-01-14 20:13:22,335 INFO org.apache.hadoop.yarn.server.resourcemanager.scheduler.capacity.CapacityScheduler: Null container completed...
2015-01-14 20:13:23,338 INFO org.apache.hadoop.yarn.server.resourcemanager.scheduler.capacity.CapacityScheduler: Null container completed...
2015-01-14 20:13:24,340 INFO org.apache.hadoop.yarn.server.resourcemanager.scheduler.capacity.CapacityScheduler: Null container completed...
2015-01-14 20:13:25,343 INFO org.apache.hadoop.yarn.server.resourcemanager.scheduler.capacity.CapacityScheduler: Null container completed...
2015-01-14 20:13:26,346 INFO org.apache.hadoop.yarn.server.resourcemanager.scheduler.capacity.CapacityScheduler: Null container completed...
2015-01-14 20:13:27,347 INFO org.apache.hadoop.yarn.server.resourcemanager.scheduler.capacity.CapacityScheduler: Null container completed...
2015-01-14 20:13:28,351 INFO org.apache.hadoop.yarn.server.resourcemanager.scheduler.capacity.CapacityScheduler: Null container completed...
2015-01-14 20:13:29,354 INFO org.apache.hadoop.yarn.server.resourcemanager.scheduler.capacity.CapacityScheduler: Null container completed...
2015-01-14 20:13:30,356 INFO org.apache.hadoop.yarn.server.resourcemanager.scheduler.capacity.CapacityScheduler: Null container completed...
2015-01-14 20:13:30,770 INFO org.apache.hadoop.yarn.util.AbstractLivelinessMonitor: Expired:appattempt_1421286406893_0001_000001 Timed out after 600 secs
2015-01-14 20:13:30,771 INFO org.apache.hadoop.yarn.server.resourcemanager.ApplicationMasterService: Unregistering app attempt : appattempt_1421286406893_0001_000001
2015-01-14 20:13:30,790 INFO org.apache.hadoop.yarn.server.resourcemanager.security.AMRMTokenSecretManager: Application finished, removing password for appattempt_1421286406893_0001_000001
2015-01-14 20:13:30,790 INFO org.apache.hadoop.yarn.server.resourcemanager.rmapp.attempt.RMAppAttemptImpl: appattempt_1421286406893_0001_000001 State change from FINISHING to FINISHED
2015-01-14 20:13:30,798 INFO org.apache.hadoop.yarn.server.resourcemanager.rmapp.RMAppImpl: application_1421286406893_0001 State change from FINISHING to FINISHED
2015-01-14 20:13:30,798 INFO org.apache.hadoop.yarn.server.resourcemanager.scheduler.capacity.CapacityScheduler: Application Attempt appattempt_1421286406893_0001_000001 is done. finalState=FINISHED
2015-01-14 20:13:30,823 INFO org.apache.hadoop.yarn.server.resourcemanager.amlauncher.AMLauncher: Cleaning master appattempt_1421286406893_0001_000001
2015-01-14 20:13:30,842 INFO org.apache.hadoop.yarn.server.resourcemanager.RMAuditLogger: USER=doopy	OPERATION=Application Finished - Succeeded	TARGET=RMAppManager	RESULT=SUCCESS	APPID=application_1421286406893_0001
2015-01-14 20:13:30,846 INFO org.apache.hadoop.yarn.server.resourcemanager.rmcontainer.RMContainerImpl: container_1421286406893_0001_01_000001 Container Transitioned from RUNNING to KILLED
2015-01-14 20:13:30,846 INFO org.apache.hadoop.yarn.server.resourcemanager.scheduler.common.fica.FiCaSchedulerApp: Completed container: container_1421286406893_0001_01_000001 in state: KILLED event:KILL
2015-01-14 20:13:30,846 INFO org.apache.hadoop.yarn.server.resourcemanager.RMAuditLogger: USER=doopy	OPERATION=AM Released Container	TARGET=SchedulerApp	RESULT=SUCCESS	APPID=application_1421286406893_0001	CONTAINERID=container_1421286406893_0001_01_000001
2015-01-14 20:13:30,846 INFO org.apache.hadoop.yarn.server.resourcemanager.scheduler.SchedulerNode: Released container container_1421286406893_0001_01_000001 of capacity <memory:2048, vCores:1> on host barbie:45258, which currently has 0 containers, <memory:0, vCores:0> used and <memory:8192, vCores:8> available, release resources=true
2015-01-14 20:13:30,847 INFO org.apache.hadoop.yarn.server.resourcemanager.scheduler.capacity.LeafQueue: default used=<memory:0, vCores:0> numContainers=0 user=doopy user-resources=<memory:0, vCores:0>
2015-01-14 20:13:30,847 INFO org.apache.hadoop.yarn.server.resourcemanager.scheduler.capacity.LeafQueue: completedContainer container=Container: [ContainerId: container_1421286406893_0001_01_000001, NodeId: barbie:45258, NodeHttpAddress: barbie:8042, Resource: <memory:2048, vCores:1>, Priority: 0, Token: Token { kind: ContainerToken, service: 127.0.1.1:45258 }, ] queue=default: capacity=1.0, absoluteCapacity=1.0, usedResources=<memory:0, vCores:0>, usedCapacity=0.0, absoluteUsedCapacity=0.0, numApps=4, numContainers=0 cluster=<memory:8192, vCores:8>
2015-01-14 20:13:30,847 INFO org.apache.hadoop.yarn.server.resourcemanager.scheduler.capacity.ParentQueue: completedContainer queue=root usedCapacity=0.0 absoluteUsedCapacity=0.0 used=<memory:0, vCores:0> cluster=<memory:8192, vCores:8>
2015-01-14 20:13:30,847 INFO org.apache.hadoop.yarn.server.resourcemanager.scheduler.capacity.ParentQueue: Re-sorting completed queue: root.default stats: default: capacity=1.0, absoluteCapacity=1.0, usedResources=<memory:0, vCores:0>, usedCapacity=0.0, absoluteUsedCapacity=0.0, numApps=4, numContainers=0
2015-01-14 20:13:30,847 INFO org.apache.hadoop.yarn.server.resourcemanager.scheduler.capacity.CapacityScheduler: Application attempt appattempt_1421286406893_0001_000001 released container container_1421286406893_0001_01_000001 on node: host: barbie:45258 #containers=0 available=8192 used=0 with event: KILL
2015-01-14 20:13:30,847 INFO org.apache.hadoop.yarn.server.resourcemanager.scheduler.AppSchedulingInfo: Application application_1421286406893_0001 requests cleared
2015-01-14 20:13:30,847 INFO org.apache.hadoop.yarn.server.resourcemanager.scheduler.capacity.LeafQueue: Application application_1421286406893_0002 from user: doopy activated in queue: default
2015-01-14 20:13:30,848 INFO org.apache.hadoop.yarn.server.resourcemanager.scheduler.capacity.LeafQueue: Application removed - appId: application_1421286406893_0001 user: doopy queue: default #user-pending-applications: 2 #user-active-applications: 1 #queue-pending-applications: 2 #queue-active-applications: 1
2015-01-14 20:13:30,848 INFO org.apache.hadoop.yarn.server.resourcemanager.scheduler.capacity.ParentQueue: Application removed - appId: application_1421286406893_0001 user: doopy leaf-queue of parent: root #applications: 3
2015-01-14 20:13:30,850 INFO org.apache.hadoop.yarn.server.resourcemanager.RMAppManager$ApplicationSummary: appId=application_1421286406893_0001,name=grep-search,user=doopy,queue=default,state=FINISHED,trackingUrl=http://barbie:8088/proxy/application_1421286406893_0001/jobhistory/job/job_1421286406893_0001,appMasterHost=barbie,startTime=1421286480841,finishTime=1421287377488,finalStatus=SUCCEEDED
2015-01-14 20:13:30,921 INFO org.apache.hadoop.yarn.server.resourcemanager.scheduler.capacity.CapacityScheduler: Null container completed...
2015-01-14 20:13:30,922 INFO org.apache.hadoop.yarn.server.resourcemanager.rmcontainer.RMContainerImpl: container_1421286406893_0002_01_000001 Container Transitioned from NEW to ALLOCATED
2015-01-14 20:13:30,922 INFO org.apache.hadoop.yarn.server.resourcemanager.RMAuditLogger: USER=doopy	OPERATION=AM Allocated Container	TARGET=SchedulerApp	RESULT=SUCCESS	APPID=application_1421286406893_0002	CONTAINERID=container_1421286406893_0002_01_000001
2015-01-14 20:13:30,922 INFO org.apache.hadoop.yarn.server.resourcemanager.scheduler.SchedulerNode: Assigned container container_1421286406893_0002_01_000001 of capacity <memory:2048, vCores:1> on host barbie:45258, which has 1 containers, <memory:2048, vCores:1> used and <memory:6144, vCores:7> available after allocation
2015-01-14 20:13:30,922 INFO org.apache.hadoop.yarn.server.resourcemanager.scheduler.capacity.LeafQueue: assignedContainer application attempt=appattempt_1421286406893_0002_000001 container=Container: [ContainerId: container_1421286406893_0002_01_000001, NodeId: barbie:45258, NodeHttpAddress: barbie:8042, Resource: <memory:2048, vCores:1>, Priority: 0, Token: null, ] queue=default: capacity=1.0, absoluteCapacity=1.0, usedResources=<memory:0, vCores:0>, usedCapacity=0.0, absoluteUsedCapacity=0.0, numApps=3, numContainers=0 clusterResource=<memory:8192, vCores:8>
2015-01-14 20:13:30,922 INFO org.apache.hadoop.yarn.server.resourcemanager.scheduler.capacity.ParentQueue: Re-sorting assigned queue: root.default stats: default: capacity=1.0, absoluteCapacity=1.0, usedResources=<memory:2048, vCores:1>, usedCapacity=0.25, absoluteUsedCapacity=0.25, numApps=3, numContainers=1
2015-01-14 20:13:30,922 INFO org.apache.hadoop.yarn.server.resourcemanager.scheduler.capacity.ParentQueue: assignedContainer queue=root usedCapacity=0.25 absoluteUsedCapacity=0.25 used=<memory:2048, vCores:1> cluster=<memory:8192, vCores:8>
2015-01-14 20:13:30,924 INFO org.apache.hadoop.yarn.server.resourcemanager.security.NMTokenSecretManagerInRM: Sending NMToken for nodeId : barbie:45258 for container : container_1421286406893_0002_01_000001
2015-01-14 20:13:30,926 INFO org.apache.hadoop.yarn.server.resourcemanager.rmcontainer.RMContainerImpl: container_1421286406893_0002_01_000001 Container Transitioned from ALLOCATED to ACQUIRED
2015-01-14 20:13:30,926 INFO org.apache.hadoop.yarn.server.resourcemanager.security.NMTokenSecretManagerInRM: Clear node set for appattempt_1421286406893_0002_000001
2015-01-14 20:13:30,926 INFO org.apache.hadoop.yarn.server.resourcemanager.rmapp.attempt.RMAppAttemptImpl: Storing attempt: AppId: application_1421286406893_0002 AttemptId: appattempt_1421286406893_0002_000001 MasterContainer: Container: [ContainerId: container_1421286406893_0002_01_000001, NodeId: barbie:45258, NodeHttpAddress: barbie:8042, Resource: <memory:2048, vCores:1>, Priority: 0, Token: Token { kind: ContainerToken, service: 127.0.1.1:45258 }, ]
2015-01-14 20:13:30,932 INFO org.apache.hadoop.yarn.server.resourcemanager.rmapp.attempt.RMAppAttemptImpl: appattempt_1421286406893_0002_000001 State change from SCHEDULED to ALLOCATED_SAVING
2015-01-14 20:13:30,932 INFO org.apache.hadoop.yarn.server.resourcemanager.rmapp.attempt.RMAppAttemptImpl: appattempt_1421286406893_0002_000001 State change from ALLOCATED_SAVING to ALLOCATED
2015-01-14 20:13:30,933 INFO org.apache.hadoop.yarn.server.resourcemanager.amlauncher.AMLauncher: Launching masterappattempt_1421286406893_0002_000001
2015-01-14 20:13:30,936 INFO org.apache.hadoop.yarn.server.resourcemanager.amlauncher.AMLauncher: Setting up container Container: [ContainerId: container_1421286406893_0002_01_000001, NodeId: barbie:45258, NodeHttpAddress: barbie:8042, Resource: <memory:2048, vCores:1>, Priority: 0, Token: Token { kind: ContainerToken, service: 127.0.1.1:45258 }, ] for AM appattempt_1421286406893_0002_000001
2015-01-14 20:13:30,937 INFO org.apache.hadoop.yarn.server.resourcemanager.amlauncher.AMLauncher: Command to launch container container_1421286406893_0002_01_000001 : $JAVA_HOME/bin/java -Dlog4j.configuration=container-log4j.properties -Dyarn.app.container.log.dir=<LOG_DIR> -Dyarn.app.container.log.filesize=0 -Dhadoop.root.logger=INFO,CLA  -Xmx1024m org.apache.hadoop.mapreduce.v2.app.MRAppMaster 1><LOG_DIR>/stdout 2><LOG_DIR>/stderr 
2015-01-14 20:13:30,937 INFO org.apache.hadoop.yarn.server.resourcemanager.security.AMRMTokenSecretManager: Create AMRMToken for ApplicationAttempt: appattempt_1421286406893_0002_000001
2015-01-14 20:13:30,937 INFO org.apache.hadoop.yarn.server.resourcemanager.security.AMRMTokenSecretManager: Creating password for appattempt_1421286406893_0002_000001
2015-01-14 20:13:31,045 INFO org.apache.hadoop.yarn.server.resourcemanager.amlauncher.AMLauncher: Done launching container Container: [ContainerId: container_1421286406893_0002_01_000001, NodeId: barbie:45258, NodeHttpAddress: barbie:8042, Resource: <memory:2048, vCores:1>, Priority: 0, Token: Token { kind: ContainerToken, service: 127.0.1.1:45258 }, ] for AM appattempt_1421286406893_0002_000001
2015-01-14 20:13:31,045 INFO org.apache.hadoop.yarn.server.resourcemanager.rmapp.attempt.RMAppAttemptImpl: appattempt_1421286406893_0002_000001 State change from ALLOCATED to LAUNCHED
2015-01-14 20:13:32,490 INFO org.apache.hadoop.yarn.server.resourcemanager.rmcontainer.RMContainerImpl: container_1421286406893_0002_01_000001 Container Transitioned from ACQUIRED to RUNNING
2015-01-14 20:13:32,490 INFO org.apache.hadoop.yarn.server.resourcemanager.scheduler.capacity.CapacityScheduler: Null container completed...
2015-01-14 20:13:32,491 INFO org.apache.hadoop.yarn.server.resourcemanager.scheduler.capacity.CapacityScheduler: Null container completed...
2015-01-14 20:13:40,983 INFO SecurityLogger.org.apache.hadoop.ipc.Server: Auth successful for appattempt_1421286406893_0002_000001 (auth:SIMPLE)
2015-01-14 20:13:40,989 INFO org.apache.hadoop.yarn.server.resourcemanager.ApplicationMasterService: AM registration appattempt_1421286406893_0002_000001
2015-01-14 20:13:40,989 INFO org.apache.hadoop.yarn.server.resourcemanager.RMAuditLogger: USER=doopy	IP=127.0.0.1	OPERATION=Register App Master	TARGET=ApplicationMasterService	RESULT=SUCCESS	APPID=application_1421286406893_0002	APPATTEMPTID=appattempt_1421286406893_0002_000001
2015-01-14 20:13:40,990 INFO org.apache.hadoop.yarn.server.resourcemanager.rmapp.attempt.RMAppAttemptImpl: appattempt_1421286406893_0002_000001 State change from LAUNCHED to RUNNING
2015-01-14 20:13:40,990 INFO org.apache.hadoop.yarn.server.resourcemanager.rmapp.RMAppImpl: application_1421286406893_0002 State change from ACCEPTED to RUNNING
2015-01-14 20:13:42,519 INFO org.apache.hadoop.yarn.server.resourcemanager.rmcontainer.RMContainerImpl: container_1421286406893_0002_01_000002 Container Transitioned from NEW to ALLOCATED
2015-01-14 20:13:42,519 INFO org.apache.hadoop.yarn.server.resourcemanager.RMAuditLogger: USER=doopy	OPERATION=AM Allocated Container	TARGET=SchedulerApp	RESULT=SUCCESS	APPID=application_1421286406893_0002	CONTAINERID=container_1421286406893_0002_01_000002
2015-01-14 20:13:42,519 INFO org.apache.hadoop.yarn.server.resourcemanager.scheduler.SchedulerNode: Assigned container container_1421286406893_0002_01_000002 of capacity <memory:1024, vCores:1> on host barbie:45258, which has 2 containers, <memory:3072, vCores:2> used and <memory:5120, vCores:6> available after allocation
2015-01-14 20:13:42,519 INFO org.apache.hadoop.yarn.server.resourcemanager.scheduler.capacity.LeafQueue: assignedContainer application attempt=appattempt_1421286406893_0002_000001 container=Container: [ContainerId: container_1421286406893_0002_01_000002, NodeId: barbie:45258, NodeHttpAddress: barbie:8042, Resource: <memory:1024, vCores:1>, Priority: 20, Token: null, ] queue=default: capacity=1.0, absoluteCapacity=1.0, usedResources=<memory:2048, vCores:1>, usedCapacity=0.25, absoluteUsedCapacity=0.25, numApps=3, numContainers=1 clusterResource=<memory:8192, vCores:8>
2015-01-14 20:13:42,520 INFO org.apache.hadoop.yarn.server.resourcemanager.scheduler.capacity.ParentQueue: Re-sorting assigned queue: root.default stats: default: capacity=1.0, absoluteCapacity=1.0, usedResources=<memory:3072, vCores:2>, usedCapacity=0.375, absoluteUsedCapacity=0.375, numApps=3, numContainers=2
2015-01-14 20:13:42,520 INFO org.apache.hadoop.yarn.server.resourcemanager.scheduler.capacity.ParentQueue: assignedContainer queue=root usedCapacity=0.375 absoluteUsedCapacity=0.375 used=<memory:3072, vCores:2> cluster=<memory:8192, vCores:8>
2015-01-14 20:13:43,119 INFO org.apache.hadoop.yarn.server.resourcemanager.security.NMTokenSecretManagerInRM: Sending NMToken for nodeId : barbie:45258 for container : container_1421286406893_0002_01_000002
2015-01-14 20:13:43,122 INFO org.apache.hadoop.yarn.server.resourcemanager.rmcontainer.RMContainerImpl: container_1421286406893_0002_01_000002 Container Transitioned from ALLOCATED to ACQUIRED
2015-01-14 20:13:43,526 INFO org.apache.hadoop.yarn.server.resourcemanager.rmcontainer.RMContainerImpl: container_1421286406893_0002_01_000002 Container Transitioned from ACQUIRED to RUNNING
2015-01-14 20:13:44,164 INFO org.apache.hadoop.yarn.server.resourcemanager.scheduler.AppSchedulingInfo: checking for deactivate... 
2015-01-14 20:13:50,250 INFO org.apache.hadoop.yarn.server.resourcemanager.rmcontainer.RMContainerImpl: container_1421286406893_0002_01_000002 Container Transitioned from RUNNING to COMPLETED
2015-01-14 20:13:50,251 INFO org.apache.hadoop.yarn.server.resourcemanager.scheduler.common.fica.FiCaSchedulerApp: Completed container: container_1421286406893_0002_01_000002 in state: COMPLETED event:FINISHED
2015-01-14 20:13:50,251 INFO org.apache.hadoop.yarn.server.resourcemanager.RMAuditLogger: USER=doopy	OPERATION=AM Released Container	TARGET=SchedulerApp	RESULT=SUCCESS	APPID=application_1421286406893_0002	CONTAINERID=container_1421286406893_0002_01_000002
2015-01-14 20:13:50,251 INFO org.apache.hadoop.yarn.server.resourcemanager.scheduler.SchedulerNode: Released container container_1421286406893_0002_01_000002 of capacity <memory:1024, vCores:1> on host barbie:45258, which currently has 1 containers, <memory:2048, vCores:1> used and <memory:6144, vCores:7> available, release resources=true
2015-01-14 20:13:50,251 INFO org.apache.hadoop.yarn.server.resourcemanager.scheduler.capacity.LeafQueue: default used=<memory:2048, vCores:1> numContainers=1 user=doopy user-resources=<memory:2048, vCores:1>
2015-01-14 20:13:50,252 INFO org.apache.hadoop.yarn.server.resourcemanager.scheduler.capacity.LeafQueue: completedContainer container=Container: [ContainerId: container_1421286406893_0002_01_000002, NodeId: barbie:45258, NodeHttpAddress: barbie:8042, Resource: <memory:1024, vCores:1>, Priority: 20, Token: Token { kind: ContainerToken, service: 127.0.1.1:45258 }, ] queue=default: capacity=1.0, absoluteCapacity=1.0, usedResources=<memory:2048, vCores:1>, usedCapacity=0.25, absoluteUsedCapacity=0.25, numApps=3, numContainers=1 cluster=<memory:8192, vCores:8>
2015-01-14 20:13:50,252 INFO org.apache.hadoop.yarn.server.resourcemanager.scheduler.capacity.ParentQueue: completedContainer queue=root usedCapacity=0.25 absoluteUsedCapacity=0.25 used=<memory:2048, vCores:1> cluster=<memory:8192, vCores:8>
2015-01-14 20:13:50,252 INFO org.apache.hadoop.yarn.server.resourcemanager.scheduler.capacity.ParentQueue: Re-sorting completed queue: root.default stats: default: capacity=1.0, absoluteCapacity=1.0, usedResources=<memory:2048, vCores:1>, usedCapacity=0.25, absoluteUsedCapacity=0.25, numApps=3, numContainers=1
2015-01-14 20:13:50,252 INFO org.apache.hadoop.yarn.server.resourcemanager.scheduler.capacity.CapacityScheduler: Application attempt appattempt_1421286406893_0002_000001 released container container_1421286406893_0002_01_000002 on node: host: barbie:45258 #containers=1 available=6144 used=2048 with event: FINISHED
2015-01-14 20:13:51,252 INFO org.apache.hadoop.yarn.server.resourcemanager.scheduler.capacity.CapacityScheduler: Null container completed...
2015-01-14 20:13:51,253 INFO org.apache.hadoop.yarn.server.resourcemanager.rmcontainer.RMContainerImpl: container_1421286406893_0002_01_000003 Container Transitioned from NEW to ALLOCATED
2015-01-14 20:13:51,254 INFO org.apache.hadoop.yarn.server.resourcemanager.RMAuditLogger: USER=doopy	OPERATION=AM Allocated Container	TARGET=SchedulerApp	RESULT=SUCCESS	APPID=application_1421286406893_0002	CONTAINERID=container_1421286406893_0002_01_000003
2015-01-14 20:13:51,254 INFO org.apache.hadoop.yarn.server.resourcemanager.scheduler.SchedulerNode: Assigned container container_1421286406893_0002_01_000003 of capacity <memory:1024, vCores:1> on host barbie:45258, which has 2 containers, <memory:3072, vCores:2> used and <memory:5120, vCores:6> available after allocation
2015-01-14 20:13:51,254 INFO org.apache.hadoop.yarn.server.resourcemanager.scheduler.capacity.LeafQueue: assignedContainer application attempt=appattempt_1421286406893_0002_000001 container=Container: [ContainerId: container_1421286406893_0002_01_000003, NodeId: barbie:45258, NodeHttpAddress: barbie:8042, Resource: <memory:1024, vCores:1>, Priority: 10, Token: null, ] queue=default: capacity=1.0, absoluteCapacity=1.0, usedResources=<memory:2048, vCores:1>, usedCapacity=0.25, absoluteUsedCapacity=0.25, numApps=3, numContainers=1 clusterResource=<memory:8192, vCores:8>
2015-01-14 20:13:51,254 INFO org.apache.hadoop.yarn.server.resourcemanager.scheduler.capacity.ParentQueue: Re-sorting assigned queue: root.default stats: default: capacity=1.0, absoluteCapacity=1.0, usedResources=<memory:3072, vCores:2>, usedCapacity=0.375, absoluteUsedCapacity=0.375, numApps=3, numContainers=2
2015-01-14 20:13:51,254 INFO org.apache.hadoop.yarn.server.resourcemanager.scheduler.capacity.ParentQueue: assignedContainer queue=root usedCapacity=0.375 absoluteUsedCapacity=0.375 used=<memory:3072, vCores:2> cluster=<memory:8192, vCores:8>
2015-01-14 20:13:52,229 INFO org.apache.hadoop.yarn.server.resourcemanager.rmcontainer.RMContainerImpl: container_1421286406893_0002_01_000003 Container Transitioned from ALLOCATED to ACQUIRED
2015-01-14 20:13:52,255 INFO org.apache.hadoop.yarn.server.resourcemanager.scheduler.capacity.CapacityScheduler: Null container completed...
2015-01-14 20:13:53,238 INFO org.apache.hadoop.yarn.server.resourcemanager.scheduler.AppSchedulingInfo: checking for deactivate... 
2015-01-14 20:13:53,258 INFO org.apache.hadoop.yarn.server.resourcemanager.rmcontainer.RMContainerImpl: container_1421286406893_0002_01_000003 Container Transitioned from ACQUIRED to RUNNING
2015-01-14 20:13:58,672 INFO org.apache.hadoop.yarn.server.resourcemanager.rmapp.attempt.RMAppAttemptImpl: Updating application attempt appattempt_1421286406893_0002_000001 with final state: FINISHING, and exit status: -1000
2015-01-14 20:13:58,672 INFO org.apache.hadoop.yarn.server.resourcemanager.rmapp.attempt.RMAppAttemptImpl: appattempt_1421286406893_0002_000001 State change from RUNNING to FINAL_SAVING
2015-01-14 20:13:58,672 INFO org.apache.hadoop.yarn.server.resourcemanager.rmapp.RMAppImpl: Updating application application_1421286406893_0002 with final state: FINISHING
2015-01-14 20:13:58,673 INFO org.apache.hadoop.yarn.server.resourcemanager.rmapp.RMAppImpl: application_1421286406893_0002 State change from RUNNING to FINAL_SAVING
2015-01-14 20:13:58,673 INFO org.apache.hadoop.yarn.server.resourcemanager.recovery.RMStateStore: Updating info for app: application_1421286406893_0002
2015-01-14 20:13:58,673 INFO org.apache.hadoop.yarn.server.resourcemanager.rmapp.attempt.RMAppAttemptImpl: appattempt_1421286406893_0002_000001 State change from FINAL_SAVING to FINISHING
2015-01-14 20:13:58,673 INFO org.apache.hadoop.yarn.server.resourcemanager.rmapp.RMAppImpl: application_1421286406893_0002 State change from FINAL_SAVING to FINISHING
2015-01-14 20:13:58,988 INFO org.apache.hadoop.yarn.server.resourcemanager.rmcontainer.RMContainerImpl: container_1421286406893_0002_01_000003 Container Transitioned from RUNNING to COMPLETED
2015-01-14 20:13:58,988 INFO org.apache.hadoop.yarn.server.resourcemanager.scheduler.common.fica.FiCaSchedulerApp: Completed container: container_1421286406893_0002_01_000003 in state: COMPLETED event:FINISHED
2015-01-14 20:13:58,988 INFO org.apache.hadoop.yarn.server.resourcemanager.RMAuditLogger: USER=doopy	OPERATION=AM Released Container	TARGET=SchedulerApp	RESULT=SUCCESS	APPID=application_1421286406893_0002	CONTAINERID=container_1421286406893_0002_01_000003
2015-01-14 20:13:58,988 INFO org.apache.hadoop.yarn.server.resourcemanager.scheduler.SchedulerNode: Released container container_1421286406893_0002_01_000003 of capacity <memory:1024, vCores:1> on host barbie:45258, which currently has 1 containers, <memory:2048, vCores:1> used and <memory:6144, vCores:7> available, release resources=true
2015-01-14 20:13:58,988 INFO org.apache.hadoop.yarn.server.resourcemanager.scheduler.capacity.LeafQueue: default used=<memory:2048, vCores:1> numContainers=1 user=doopy user-resources=<memory:2048, vCores:1>
2015-01-14 20:13:58,989 INFO org.apache.hadoop.yarn.server.resourcemanager.scheduler.capacity.LeafQueue: completedContainer container=Container: [ContainerId: container_1421286406893_0002_01_000003, NodeId: barbie:45258, NodeHttpAddress: barbie:8042, Resource: <memory:1024, vCores:1>, Priority: 10, Token: Token { kind: ContainerToken, service: 127.0.1.1:45258 }, ] queue=default: capacity=1.0, absoluteCapacity=1.0, usedResources=<memory:2048, vCores:1>, usedCapacity=0.25, absoluteUsedCapacity=0.25, numApps=3, numContainers=1 cluster=<memory:8192, vCores:8>
2015-01-14 20:13:58,990 INFO org.apache.hadoop.yarn.server.resourcemanager.scheduler.capacity.ParentQueue: completedContainer queue=root usedCapacity=0.25 absoluteUsedCapacity=0.25 used=<memory:2048, vCores:1> cluster=<memory:8192, vCores:8>
2015-01-14 20:13:58,990 INFO org.apache.hadoop.yarn.server.resourcemanager.scheduler.capacity.ParentQueue: Re-sorting completed queue: root.default stats: default: capacity=1.0, absoluteCapacity=1.0, usedResources=<memory:2048, vCores:1>, usedCapacity=0.25, absoluteUsedCapacity=0.25, numApps=3, numContainers=1
2015-01-14 20:13:58,990 INFO org.apache.hadoop.yarn.server.resourcemanager.scheduler.capacity.CapacityScheduler: Application attempt appattempt_1421286406893_0002_000001 released container container_1421286406893_0002_01_000003 on node: host: barbie:45258 #containers=1 available=6144 used=2048 with event: FINISHED
2015-01-14 20:13:59,679 INFO org.apache.hadoop.yarn.server.resourcemanager.ApplicationMasterService: application_1421286406893_0002 unregistered successfully. 
2015-01-14 20:13:59,991 INFO org.apache.hadoop.yarn.server.resourcemanager.scheduler.capacity.CapacityScheduler: Null container completed...
2015-01-14 20:14:00,994 INFO org.apache.hadoop.yarn.server.resourcemanager.scheduler.capacity.CapacityScheduler: Null container completed...
2015-01-14 20:14:01,997 INFO org.apache.hadoop.yarn.server.resourcemanager.scheduler.capacity.CapacityScheduler: Null container completed...
2015-01-14 20:14:03,000 INFO org.apache.hadoop.yarn.server.resourcemanager.scheduler.capacity.CapacityScheduler: Null container completed...
2015-01-14 20:14:04,002 INFO org.apache.hadoop.yarn.server.resourcemanager.scheduler.capacity.CapacityScheduler: Null container completed...
2015-01-14 20:14:05,005 INFO org.apache.hadoop.yarn.server.resourcemanager.rmcontainer.RMContainerImpl: container_1421286406893_0002_01_000001 Container Transitioned from RUNNING to COMPLETED
2015-01-14 20:14:05,005 INFO org.apache.hadoop.yarn.server.resourcemanager.scheduler.common.fica.FiCaSchedulerApp: Completed container: container_1421286406893_0002_01_000001 in state: COMPLETED event:FINISHED
2015-01-14 20:14:05,005 INFO org.apache.hadoop.yarn.server.resourcemanager.RMAuditLogger: USER=doopy	OPERATION=AM Released Container	TARGET=SchedulerApp	RESULT=SUCCESS	APPID=application_1421286406893_0002	CONTAINERID=container_1421286406893_0002_01_000001
2015-01-14 20:14:05,005 INFO org.apache.hadoop.yarn.server.resourcemanager.scheduler.SchedulerNode: Released container container_1421286406893_0002_01_000001 of capacity <memory:2048, vCores:1> on host barbie:45258, which currently has 0 containers, <memory:0, vCores:0> used and <memory:8192, vCores:8> available, release resources=true
2015-01-14 20:14:05,005 INFO org.apache.hadoop.yarn.server.resourcemanager.scheduler.capacity.LeafQueue: default used=<memory:0, vCores:0> numContainers=0 user=doopy user-resources=<memory:0, vCores:0>
2015-01-14 20:14:05,005 INFO org.apache.hadoop.yarn.server.resourcemanager.scheduler.capacity.LeafQueue: completedContainer container=Container: [ContainerId: container_1421286406893_0002_01_000001, NodeId: barbie:45258, NodeHttpAddress: barbie:8042, Resource: <memory:2048, vCores:1>, Priority: 0, Token: Token { kind: ContainerToken, service: 127.0.1.1:45258 }, ] queue=default: capacity=1.0, absoluteCapacity=1.0, usedResources=<memory:0, vCores:0>, usedCapacity=0.0, absoluteUsedCapacity=0.0, numApps=3, numContainers=0 cluster=<memory:8192, vCores:8>
2015-01-14 20:14:05,005 INFO org.apache.hadoop.yarn.server.resourcemanager.scheduler.capacity.ParentQueue: completedContainer queue=root usedCapacity=0.0 absoluteUsedCapacity=0.0 used=<memory:0, vCores:0> cluster=<memory:8192, vCores:8>
2015-01-14 20:14:05,005 INFO org.apache.hadoop.yarn.server.resourcemanager.scheduler.capacity.ParentQueue: Re-sorting completed queue: root.default stats: default: capacity=1.0, absoluteCapacity=1.0, usedResources=<memory:0, vCores:0>, usedCapacity=0.0, absoluteUsedCapacity=0.0, numApps=3, numContainers=0
2015-01-14 20:14:05,005 INFO org.apache.hadoop.yarn.server.resourcemanager.scheduler.capacity.CapacityScheduler: Application attempt appattempt_1421286406893_0002_000001 released container container_1421286406893_0002_01_000001 on node: host: barbie:45258 #containers=0 available=8192 used=0 with event: FINISHED
2015-01-14 20:14:05,006 INFO org.apache.hadoop.yarn.server.resourcemanager.scheduler.capacity.CapacityScheduler: Null container completed...
2015-01-14 20:14:05,006 INFO org.apache.hadoop.yarn.server.resourcemanager.ApplicationMasterService: Unregistering app attempt : appattempt_1421286406893_0002_000001
2015-01-14 20:14:05,006 INFO org.apache.hadoop.yarn.server.resourcemanager.security.AMRMTokenSecretManager: Application finished, removing password for appattempt_1421286406893_0002_000001
2015-01-14 20:14:05,007 INFO org.apache.hadoop.yarn.server.resourcemanager.rmapp.attempt.RMAppAttemptImpl: appattempt_1421286406893_0002_000001 State change from FINISHING to FINISHED
2015-01-14 20:14:05,007 INFO org.apache.hadoop.yarn.server.resourcemanager.rmapp.RMAppImpl: application_1421286406893_0002 State change from FINISHING to FINISHED
2015-01-14 20:14:05,007 INFO org.apache.hadoop.yarn.server.resourcemanager.RMAuditLogger: USER=doopy	OPERATION=Application Finished - Succeeded	TARGET=RMAppManager	RESULT=SUCCESS	APPID=application_1421286406893_0002
2015-01-14 20:14:05,007 INFO org.apache.hadoop.yarn.server.resourcemanager.RMAppManager$ApplicationSummary: appId=application_1421286406893_0002,name=grep-sort,user=doopy,queue=default,state=FINISHED,trackingUrl=http://barbie:8088/proxy/application_1421286406893_0002/jobhistory/job/job_1421286406893_0002,appMasterHost=barbie,startTime=1421287386734,finishTime=1421288038672,finalStatus=SUCCEEDED
2015-01-14 20:14:05,007 INFO org.apache.hadoop.yarn.server.resourcemanager.scheduler.capacity.CapacityScheduler: Application Attempt appattempt_1421286406893_0002_000001 is done. finalState=FINISHED
2015-01-14 20:14:05,008 INFO org.apache.hadoop.yarn.server.resourcemanager.scheduler.AppSchedulingInfo: Application application_1421286406893_0002 requests cleared
2015-01-14 20:14:05,008 INFO org.apache.hadoop.yarn.server.resourcemanager.scheduler.capacity.LeafQueue: Application application_1421286406893_0003 from user: doopy activated in queue: default
2015-01-14 20:14:05,008 INFO org.apache.hadoop.yarn.server.resourcemanager.scheduler.capacity.LeafQueue: Application removed - appId: application_1421286406893_0002 user: doopy queue: default #user-pending-applications: 1 #user-active-applications: 1 #queue-pending-applications: 1 #queue-active-applications: 1
2015-01-14 20:14:05,008 INFO org.apache.hadoop.yarn.server.resourcemanager.scheduler.capacity.ParentQueue: Application removed - appId: application_1421286406893_0002 user: doopy leaf-queue of parent: root #applications: 2
2015-01-14 20:14:05,011 INFO org.apache.hadoop.yarn.server.resourcemanager.amlauncher.AMLauncher: Cleaning master appattempt_1421286406893_0002_000001
2015-01-14 20:14:05,036 INFO org.apache.hadoop.yarn.server.resourcemanager.scheduler.capacity.CapacityScheduler: Null container completed...
2015-01-14 20:14:05,036 INFO org.apache.hadoop.yarn.server.resourcemanager.scheduler.capacity.CapacityScheduler: Null container completed...
2015-01-14 20:14:05,036 INFO org.apache.hadoop.yarn.server.resourcemanager.rmcontainer.RMContainerImpl: container_1421286406893_0003_01_000001 Container Transitioned from NEW to ALLOCATED
2015-01-14 20:14:05,036 INFO org.apache.hadoop.yarn.server.resourcemanager.RMAuditLogger: USER=doopy	OPERATION=AM Allocated Container	TARGET=SchedulerApp	RESULT=SUCCESS	APPID=application_1421286406893_0003	CONTAINERID=container_1421286406893_0003_01_000001
2015-01-14 20:14:05,036 INFO org.apache.hadoop.yarn.server.resourcemanager.scheduler.SchedulerNode: Assigned container container_1421286406893_0003_01_000001 of capacity <memory:2048, vCores:1> on host barbie:45258, which has 1 containers, <memory:2048, vCores:1> used and <memory:6144, vCores:7> available after allocation
2015-01-14 20:14:05,037 INFO org.apache.hadoop.yarn.server.resourcemanager.scheduler.capacity.LeafQueue: assignedContainer application attempt=appattempt_1421286406893_0003_000001 container=Container: [ContainerId: container_1421286406893_0003_01_000001, NodeId: barbie:45258, NodeHttpAddress: barbie:8042, Resource: <memory:2048, vCores:1>, Priority: 0, Token: null, ] queue=default: capacity=1.0, absoluteCapacity=1.0, usedResources=<memory:0, vCores:0>, usedCapacity=0.0, absoluteUsedCapacity=0.0, numApps=2, numContainers=0 clusterResource=<memory:8192, vCores:8>
2015-01-14 20:14:05,037 INFO org.apache.hadoop.yarn.server.resourcemanager.scheduler.capacity.ParentQueue: Re-sorting assigned queue: root.default stats: default: capacity=1.0, absoluteCapacity=1.0, usedResources=<memory:2048, vCores:1>, usedCapacity=0.25, absoluteUsedCapacity=0.25, numApps=2, numContainers=1
2015-01-14 20:14:05,037 INFO org.apache.hadoop.yarn.server.resourcemanager.scheduler.capacity.ParentQueue: assignedContainer queue=root usedCapacity=0.25 absoluteUsedCapacity=0.25 used=<memory:2048, vCores:1> cluster=<memory:8192, vCores:8>
2015-01-14 20:14:05,041 INFO org.apache.hadoop.yarn.server.resourcemanager.security.NMTokenSecretManagerInRM: Sending NMToken for nodeId : barbie:45258 for container : container_1421286406893_0003_01_000001
2015-01-14 20:14:05,049 INFO org.apache.hadoop.yarn.server.resourcemanager.rmcontainer.RMContainerImpl: container_1421286406893_0003_01_000001 Container Transitioned from ALLOCATED to ACQUIRED
2015-01-14 20:14:05,049 INFO org.apache.hadoop.yarn.server.resourcemanager.security.NMTokenSecretManagerInRM: Clear node set for appattempt_1421286406893_0003_000001
2015-01-14 20:14:05,050 INFO org.apache.hadoop.yarn.server.resourcemanager.rmapp.attempt.RMAppAttemptImpl: Storing attempt: AppId: application_1421286406893_0003 AttemptId: appattempt_1421286406893_0003_000001 MasterContainer: Container: [ContainerId: container_1421286406893_0003_01_000001, NodeId: barbie:45258, NodeHttpAddress: barbie:8042, Resource: <memory:2048, vCores:1>, Priority: 0, Token: Token { kind: ContainerToken, service: 127.0.1.1:45258 }, ]
2015-01-14 20:14:05,051 INFO org.apache.hadoop.yarn.server.resourcemanager.rmapp.attempt.RMAppAttemptImpl: appattempt_1421286406893_0003_000001 State change from SCHEDULED to ALLOCATED_SAVING
2015-01-14 20:14:05,051 INFO org.apache.hadoop.yarn.server.resourcemanager.rmapp.attempt.RMAppAttemptImpl: appattempt_1421286406893_0003_000001 State change from ALLOCATED_SAVING to ALLOCATED
2015-01-14 20:14:05,051 INFO org.apache.hadoop.yarn.server.resourcemanager.amlauncher.AMLauncher: Launching masterappattempt_1421286406893_0003_000001
2015-01-14 20:14:05,054 INFO org.apache.hadoop.yarn.server.resourcemanager.amlauncher.AMLauncher: Setting up container Container: [ContainerId: container_1421286406893_0003_01_000001, NodeId: barbie:45258, NodeHttpAddress: barbie:8042, Resource: <memory:2048, vCores:1>, Priority: 0, Token: Token { kind: ContainerToken, service: 127.0.1.1:45258 }, ] for AM appattempt_1421286406893_0003_000001
2015-01-14 20:14:05,054 INFO org.apache.hadoop.yarn.server.resourcemanager.amlauncher.AMLauncher: Command to launch container container_1421286406893_0003_01_000001 : $JAVA_HOME/bin/java -Dlog4j.configuration=container-log4j.properties -Dyarn.app.container.log.dir=<LOG_DIR> -Dyarn.app.container.log.filesize=0 -Dhadoop.root.logger=INFO,CLA  -Xmx1024m org.apache.hadoop.mapreduce.v2.app.MRAppMaster 1><LOG_DIR>/stdout 2><LOG_DIR>/stderr 
2015-01-14 20:14:05,054 INFO org.apache.hadoop.yarn.server.resourcemanager.security.AMRMTokenSecretManager: Create AMRMToken for ApplicationAttempt: appattempt_1421286406893_0003_000001
2015-01-14 20:14:05,054 INFO org.apache.hadoop.yarn.server.resourcemanager.security.AMRMTokenSecretManager: Creating password for appattempt_1421286406893_0003_000001
2015-01-14 20:14:05,078 INFO org.apache.hadoop.yarn.server.resourcemanager.amlauncher.AMLauncher: Done launching container Container: [ContainerId: container_1421286406893_0003_01_000001, NodeId: barbie:45258, NodeHttpAddress: barbie:8042, Resource: <memory:2048, vCores:1>, Priority: 0, Token: Token { kind: ContainerToken, service: 127.0.1.1:45258 }, ] for AM appattempt_1421286406893_0003_000001
2015-01-14 20:14:05,079 INFO org.apache.hadoop.yarn.server.resourcemanager.rmapp.attempt.RMAppAttemptImpl: appattempt_1421286406893_0003_000001 State change from ALLOCATED to LAUNCHED
2015-01-14 20:14:06,048 INFO org.apache.hadoop.yarn.server.resourcemanager.rmcontainer.RMContainerImpl: container_1421286406893_0003_01_000001 Container Transitioned from ACQUIRED to RUNNING
2015-01-14 20:14:06,048 INFO org.apache.hadoop.yarn.server.resourcemanager.scheduler.capacity.CapacityScheduler: Null container completed...
2015-01-14 20:14:12,973 INFO SecurityLogger.org.apache.hadoop.ipc.Server: Auth successful for appattempt_1421286406893_0003_000001 (auth:SIMPLE)
2015-01-14 20:14:12,978 INFO org.apache.hadoop.yarn.server.resourcemanager.ApplicationMasterService: AM registration appattempt_1421286406893_0003_000001
2015-01-14 20:14:12,978 INFO org.apache.hadoop.yarn.server.resourcemanager.RMAuditLogger: USER=doopy	IP=127.0.0.1	OPERATION=Register App Master	TARGET=ApplicationMasterService	RESULT=SUCCESS	APPID=application_1421286406893_0003	APPATTEMPTID=appattempt_1421286406893_0003_000001
2015-01-14 20:14:12,979 INFO org.apache.hadoop.yarn.server.resourcemanager.rmapp.attempt.RMAppAttemptImpl: appattempt_1421286406893_0003_000001 State change from LAUNCHED to RUNNING
2015-01-14 20:14:12,986 INFO org.apache.hadoop.yarn.server.resourcemanager.rmapp.RMAppImpl: application_1421286406893_0003 State change from ACCEPTED to RUNNING
2015-01-14 20:14:14,069 INFO org.apache.hadoop.yarn.server.resourcemanager.rmcontainer.RMContainerImpl: container_1421286406893_0003_01_000002 Container Transitioned from NEW to ALLOCATED
2015-01-14 20:14:14,070 INFO org.apache.hadoop.yarn.server.resourcemanager.RMAuditLogger: USER=doopy	OPERATION=AM Allocated Container	TARGET=SchedulerApp	RESULT=SUCCESS	APPID=application_1421286406893_0003	CONTAINERID=container_1421286406893_0003_01_000002
2015-01-14 20:14:14,070 INFO org.apache.hadoop.yarn.server.resourcemanager.scheduler.SchedulerNode: Assigned container container_1421286406893_0003_01_000002 of capacity <memory:1024, vCores:1> on host barbie:45258, which has 2 containers, <memory:3072, vCores:2> used and <memory:5120, vCores:6> available after allocation
2015-01-14 20:14:14,070 INFO org.apache.hadoop.yarn.server.resourcemanager.scheduler.capacity.LeafQueue: assignedContainer application attempt=appattempt_1421286406893_0003_000001 container=Container: [ContainerId: container_1421286406893_0003_01_000002, NodeId: barbie:45258, NodeHttpAddress: barbie:8042, Resource: <memory:1024, vCores:1>, Priority: 20, Token: null, ] queue=default: capacity=1.0, absoluteCapacity=1.0, usedResources=<memory:2048, vCores:1>, usedCapacity=0.25, absoluteUsedCapacity=0.25, numApps=2, numContainers=1 clusterResource=<memory:8192, vCores:8>
2015-01-14 20:14:14,070 INFO org.apache.hadoop.yarn.server.resourcemanager.scheduler.capacity.ParentQueue: Re-sorting assigned queue: root.default stats: default: capacity=1.0, absoluteCapacity=1.0, usedResources=<memory:3072, vCores:2>, usedCapacity=0.375, absoluteUsedCapacity=0.375, numApps=2, numContainers=2
2015-01-14 20:14:14,070 INFO org.apache.hadoop.yarn.server.resourcemanager.scheduler.capacity.ParentQueue: assignedContainer queue=root usedCapacity=0.375 absoluteUsedCapacity=0.375 used=<memory:3072, vCores:2> cluster=<memory:8192, vCores:8>
2015-01-14 20:14:14,071 INFO org.apache.hadoop.yarn.server.resourcemanager.rmcontainer.RMContainerImpl: container_1421286406893_0003_01_000003 Container Transitioned from NEW to ALLOCATED
2015-01-14 20:14:14,071 INFO org.apache.hadoop.yarn.server.resourcemanager.RMAuditLogger: USER=doopy	OPERATION=AM Allocated Container	TARGET=SchedulerApp	RESULT=SUCCESS	APPID=application_1421286406893_0003	CONTAINERID=container_1421286406893_0003_01_000003
2015-01-14 20:14:14,071 INFO org.apache.hadoop.yarn.server.resourcemanager.scheduler.SchedulerNode: Assigned container container_1421286406893_0003_01_000003 of capacity <memory:1024, vCores:1> on host barbie:45258, which has 3 containers, <memory:4096, vCores:3> used and <memory:4096, vCores:5> available after allocation
2015-01-14 20:14:14,071 INFO org.apache.hadoop.yarn.server.resourcemanager.scheduler.capacity.LeafQueue: assignedContainer application attempt=appattempt_1421286406893_0003_000001 container=Container: [ContainerId: container_1421286406893_0003_01_000003, NodeId: barbie:45258, NodeHttpAddress: barbie:8042, Resource: <memory:1024, vCores:1>, Priority: 20, Token: null, ] queue=default: capacity=1.0, absoluteCapacity=1.0, usedResources=<memory:3072, vCores:2>, usedCapacity=0.375, absoluteUsedCapacity=0.375, numApps=2, numContainers=2 clusterResource=<memory:8192, vCores:8>
2015-01-14 20:14:14,071 INFO org.apache.hadoop.yarn.server.resourcemanager.scheduler.capacity.ParentQueue: Re-sorting assigned queue: root.default stats: default: capacity=1.0, absoluteCapacity=1.0, usedResources=<memory:4096, vCores:3>, usedCapacity=0.5, absoluteUsedCapacity=0.5, numApps=2, numContainers=3
2015-01-14 20:14:14,071 INFO org.apache.hadoop.yarn.server.resourcemanager.scheduler.capacity.ParentQueue: assignedContainer queue=root usedCapacity=0.5 absoluteUsedCapacity=0.5 used=<memory:4096, vCores:3> cluster=<memory:8192, vCores:8>
2015-01-14 20:14:14,071 INFO org.apache.hadoop.yarn.server.resourcemanager.rmcontainer.RMContainerImpl: container_1421286406893_0003_01_000004 Container Transitioned from NEW to ALLOCATED
2015-01-14 20:14:14,071 INFO org.apache.hadoop.yarn.server.resourcemanager.RMAuditLogger: USER=doopy	OPERATION=AM Allocated Container	TARGET=SchedulerApp	RESULT=SUCCESS	APPID=application_1421286406893_0003	CONTAINERID=container_1421286406893_0003_01_000004
2015-01-14 20:14:14,072 INFO org.apache.hadoop.yarn.server.resourcemanager.scheduler.SchedulerNode: Assigned container container_1421286406893_0003_01_000004 of capacity <memory:1024, vCores:1> on host barbie:45258, which has 4 containers, <memory:5120, vCores:4> used and <memory:3072, vCores:4> available after allocation
2015-01-14 20:14:14,072 INFO org.apache.hadoop.yarn.server.resourcemanager.scheduler.capacity.LeafQueue: assignedContainer application attempt=appattempt_1421286406893_0003_000001 container=Container: [ContainerId: container_1421286406893_0003_01_000004, NodeId: barbie:45258, NodeHttpAddress: barbie:8042, Resource: <memory:1024, vCores:1>, Priority: 20, Token: null, ] queue=default: capacity=1.0, absoluteCapacity=1.0, usedResources=<memory:4096, vCores:3>, usedCapacity=0.5, absoluteUsedCapacity=0.5, numApps=2, numContainers=3 clusterResource=<memory:8192, vCores:8>
2015-01-14 20:14:14,076 INFO org.apache.hadoop.yarn.server.resourcemanager.scheduler.capacity.ParentQueue: Re-sorting assigned queue: root.default stats: default: capacity=1.0, absoluteCapacity=1.0, usedResources=<memory:5120, vCores:4>, usedCapacity=0.625, absoluteUsedCapacity=0.625, numApps=2, numContainers=4
2015-01-14 20:14:14,076 INFO org.apache.hadoop.yarn.server.resourcemanager.scheduler.capacity.ParentQueue: assignedContainer queue=root usedCapacity=0.625 absoluteUsedCapacity=0.625 used=<memory:5120, vCores:4> cluster=<memory:8192, vCores:8>
2015-01-14 20:14:14,077 INFO org.apache.hadoop.yarn.server.resourcemanager.rmcontainer.RMContainerImpl: container_1421286406893_0003_01_000005 Container Transitioned from NEW to ALLOCATED
2015-01-14 20:14:14,077 INFO org.apache.hadoop.yarn.server.resourcemanager.RMAuditLogger: USER=doopy	OPERATION=AM Allocated Container	TARGET=SchedulerApp	RESULT=SUCCESS	APPID=application_1421286406893_0003	CONTAINERID=container_1421286406893_0003_01_000005
2015-01-14 20:14:14,077 INFO org.apache.hadoop.yarn.server.resourcemanager.scheduler.SchedulerNode: Assigned container container_1421286406893_0003_01_000005 of capacity <memory:1024, vCores:1> on host barbie:45258, which has 5 containers, <memory:6144, vCores:5> used and <memory:2048, vCores:3> available after allocation
2015-01-14 20:14:14,077 INFO org.apache.hadoop.yarn.server.resourcemanager.scheduler.capacity.LeafQueue: assignedContainer application attempt=appattempt_1421286406893_0003_000001 container=Container: [ContainerId: container_1421286406893_0003_01_000005, NodeId: barbie:45258, NodeHttpAddress: barbie:8042, Resource: <memory:1024, vCores:1>, Priority: 20, Token: null, ] queue=default: capacity=1.0, absoluteCapacity=1.0, usedResources=<memory:5120, vCores:4>, usedCapacity=0.625, absoluteUsedCapacity=0.625, numApps=2, numContainers=4 clusterResource=<memory:8192, vCores:8>
2015-01-14 20:14:14,077 INFO org.apache.hadoop.yarn.server.resourcemanager.scheduler.capacity.ParentQueue: Re-sorting assigned queue: root.default stats: default: capacity=1.0, absoluteCapacity=1.0, usedResources=<memory:6144, vCores:5>, usedCapacity=0.75, absoluteUsedCapacity=0.75, numApps=2, numContainers=5
2015-01-14 20:14:14,078 INFO org.apache.hadoop.yarn.server.resourcemanager.scheduler.capacity.ParentQueue: assignedContainer queue=root usedCapacity=0.75 absoluteUsedCapacity=0.75 used=<memory:6144, vCores:5> cluster=<memory:8192, vCores:8>
2015-01-14 20:14:14,078 INFO org.apache.hadoop.yarn.server.resourcemanager.rmcontainer.RMContainerImpl: container_1421286406893_0003_01_000006 Container Transitioned from NEW to ALLOCATED
2015-01-14 20:14:14,078 INFO org.apache.hadoop.yarn.server.resourcemanager.RMAuditLogger: USER=doopy	OPERATION=AM Allocated Container	TARGET=SchedulerApp	RESULT=SUCCESS	APPID=application_1421286406893_0003	CONTAINERID=container_1421286406893_0003_01_000006
2015-01-14 20:14:14,078 INFO org.apache.hadoop.yarn.server.resourcemanager.scheduler.SchedulerNode: Assigned container container_1421286406893_0003_01_000006 of capacity <memory:1024, vCores:1> on host barbie:45258, which has 6 containers, <memory:7168, vCores:6> used and <memory:1024, vCores:2> available after allocation
2015-01-14 20:14:14,078 INFO org.apache.hadoop.yarn.server.resourcemanager.scheduler.capacity.LeafQueue: assignedContainer application attempt=appattempt_1421286406893_0003_000001 container=Container: [ContainerId: container_1421286406893_0003_01_000006, NodeId: barbie:45258, NodeHttpAddress: barbie:8042, Resource: <memory:1024, vCores:1>, Priority: 20, Token: null, ] queue=default: capacity=1.0, absoluteCapacity=1.0, usedResources=<memory:6144, vCores:5>, usedCapacity=0.75, absoluteUsedCapacity=0.75, numApps=2, numContainers=5 clusterResource=<memory:8192, vCores:8>
2015-01-14 20:14:14,078 INFO org.apache.hadoop.yarn.server.resourcemanager.scheduler.capacity.ParentQueue: Re-sorting assigned queue: root.default stats: default: capacity=1.0, absoluteCapacity=1.0, usedResources=<memory:7168, vCores:6>, usedCapacity=0.875, absoluteUsedCapacity=0.875, numApps=2, numContainers=6
2015-01-14 20:14:14,079 INFO org.apache.hadoop.yarn.server.resourcemanager.scheduler.capacity.ParentQueue: assignedContainer queue=root usedCapacity=0.875 absoluteUsedCapacity=0.875 used=<memory:7168, vCores:6> cluster=<memory:8192, vCores:8>
2015-01-14 20:14:14,079 INFO org.apache.hadoop.yarn.server.resourcemanager.rmcontainer.RMContainerImpl: container_1421286406893_0003_01_000007 Container Transitioned from NEW to ALLOCATED
2015-01-14 20:14:14,079 INFO org.apache.hadoop.yarn.server.resourcemanager.RMAuditLogger: USER=doopy	OPERATION=AM Allocated Container	TARGET=SchedulerApp	RESULT=SUCCESS	APPID=application_1421286406893_0003	CONTAINERID=container_1421286406893_0003_01_000007
2015-01-14 20:14:14,079 INFO org.apache.hadoop.yarn.server.resourcemanager.scheduler.SchedulerNode: Assigned container container_1421286406893_0003_01_000007 of capacity <memory:1024, vCores:1> on host barbie:45258, which has 7 containers, <memory:8192, vCores:7> used and <memory:0, vCores:1> available after allocation
2015-01-14 20:14:14,079 INFO org.apache.hadoop.yarn.server.resourcemanager.scheduler.capacity.LeafQueue: assignedContainer application attempt=appattempt_1421286406893_0003_000001 container=Container: [ContainerId: container_1421286406893_0003_01_000007, NodeId: barbie:45258, NodeHttpAddress: barbie:8042, Resource: <memory:1024, vCores:1>, Priority: 20, Token: null, ] queue=default: capacity=1.0, absoluteCapacity=1.0, usedResources=<memory:7168, vCores:6>, usedCapacity=0.875, absoluteUsedCapacity=0.875, numApps=2, numContainers=6 clusterResource=<memory:8192, vCores:8>
2015-01-14 20:14:14,079 INFO org.apache.hadoop.yarn.server.resourcemanager.scheduler.capacity.ParentQueue: Re-sorting assigned queue: root.default stats: default: capacity=1.0, absoluteCapacity=1.0, usedResources=<memory:8192, vCores:7>, usedCapacity=1.0, absoluteUsedCapacity=1.0, numApps=2, numContainers=7
2015-01-14 20:14:14,080 INFO org.apache.hadoop.yarn.server.resourcemanager.scheduler.capacity.ParentQueue: assignedContainer queue=root usedCapacity=1.0 absoluteUsedCapacity=1.0 used=<memory:8192, vCores:7> cluster=<memory:8192, vCores:8>
2015-01-14 20:14:15,122 INFO org.apache.hadoop.yarn.server.resourcemanager.security.NMTokenSecretManagerInRM: Sending NMToken for nodeId : barbie:45258 for container : container_1421286406893_0003_01_000002
2015-01-14 20:14:15,124 INFO org.apache.hadoop.yarn.server.resourcemanager.rmcontainer.RMContainerImpl: container_1421286406893_0003_01_000002 Container Transitioned from ALLOCATED to ACQUIRED
2015-01-14 20:14:15,126 INFO org.apache.hadoop.yarn.server.resourcemanager.rmcontainer.RMContainerImpl: container_1421286406893_0003_01_000003 Container Transitioned from ALLOCATED to ACQUIRED
2015-01-14 20:14:15,128 INFO org.apache.hadoop.yarn.server.resourcemanager.rmcontainer.RMContainerImpl: container_1421286406893_0003_01_000004 Container Transitioned from ALLOCATED to ACQUIRED
2015-01-14 20:14:15,130 INFO org.apache.hadoop.yarn.server.resourcemanager.rmcontainer.RMContainerImpl: container_1421286406893_0003_01_000005 Container Transitioned from ALLOCATED to ACQUIRED
2015-01-14 20:14:15,135 INFO org.apache.hadoop.yarn.server.resourcemanager.rmcontainer.RMContainerImpl: container_1421286406893_0003_01_000006 Container Transitioned from ALLOCATED to ACQUIRED
2015-01-14 20:14:15,137 INFO org.apache.hadoop.yarn.server.resourcemanager.rmcontainer.RMContainerImpl: container_1421286406893_0003_01_000007 Container Transitioned from ALLOCATED to ACQUIRED
2015-01-14 20:14:16,273 INFO org.apache.hadoop.yarn.server.resourcemanager.rmcontainer.RMContainerImpl: container_1421286406893_0003_01_000002 Container Transitioned from ACQUIRED to RUNNING
2015-01-14 20:14:16,273 INFO org.apache.hadoop.yarn.server.resourcemanager.rmcontainer.RMContainerImpl: container_1421286406893_0003_01_000003 Container Transitioned from ACQUIRED to RUNNING
2015-01-14 20:14:16,273 INFO org.apache.hadoop.yarn.server.resourcemanager.rmcontainer.RMContainerImpl: container_1421286406893_0003_01_000004 Container Transitioned from ACQUIRED to RUNNING
2015-01-14 20:14:16,273 INFO org.apache.hadoop.yarn.server.resourcemanager.rmcontainer.RMContainerImpl: container_1421286406893_0003_01_000005 Container Transitioned from ACQUIRED to RUNNING
2015-01-14 20:14:16,273 INFO org.apache.hadoop.yarn.server.resourcemanager.rmcontainer.RMContainerImpl: container_1421286406893_0003_01_000006 Container Transitioned from ACQUIRED to RUNNING
2015-01-14 20:14:16,273 INFO org.apache.hadoop.yarn.server.resourcemanager.rmcontainer.RMContainerImpl: container_1421286406893_0003_01_000007 Container Transitioned from ACQUIRED to RUNNING
2015-01-14 20:16:05,063 INFO SecurityLogger.org.apache.hadoop.ipc.Server: Auth successful for appattempt_1421286406893_0003_000001 (auth:SIMPLE)
